Workbook
Name dd: #REF!
Name dd: #REF!
Name te: #REF!
Name te: #REF!
Name vDateTime: #REF!
Name vDateTime: #REF!
Name vDateTime: #REF!
Name vDateTime: #REF!
Name vDateTime: #REF!
Name vDiastolic: #REF!
Name vDiastolic: #REF!
Name vDiastolic: #REF!
Name vHeartRate: #REF!
Name vHeartRate: #REF!
Name vHeartRate: #REF!
Name vSystolic: #REF!
Name vSystolic: #REF!
Name vSystolic: #REF!

Sheet Summary
A1: Summary
A2: Project: | B2: TFK
A3: Product: | B3: Plan Analytics
A4: Task/Area/Module/Feature | B4: Financial Analytics/Clinical Analytics-TFK
A5: Cycle Date | B5: January 01, 2012 to December 31, 2016
A6: Remarks | B6: Plan Analytics Ver: 6.0.0
A8: TEST CASE REVISION HISTORY
A10: Date | B10: Version | C10: Description | D10: Author/s | E10: Reviewer/s | F10: Remarks
A11: 41290 | B11: 1.5.5 | D11: Mgole
A14: TEST EXECUTION HISTORY
A16: Start Date | B16: End Date | C16: Test Environment | D16: Tester/s | E16: Overall Result | F16: Remarks
A17: 42766 | B17: 42766 | C17: https://app1.pa.uat.deerwalk.com | D17: AchyutB | E17: Pass | F17: Manually tested summary page data, counts and LOA values
C18: stage1_tfk_app_20170130

Sheet Summary_Page
A1: Testing Environment | B1: Section | C1: Sub-Section | D1: Test Summary | E1: Makalu Test Procedure | F1: Backend Test Procedure | G1: Test Data | H1: Test Result | I1: Related Defects | J1: Remarks
H2: DATE
A3: MSSQL 2008 R2 | B3: Book of Business | C3: Medical Claims Paid | D3: Verify Medical Claims Paid | E3: 1) Login to Makalu 2) Click "Dynamic Reports" 3) Select Default values(Basis and Period) 3) Click "Search" 4)The Makalu result for both "Reporting Period" and "Comparision Period" can be seen in "SP Data" tab. | F3: 1)Run the query from following svn path. http://www.deerwalk.com/repos/dwproject/makalu/docs/quality_control/test_cases/data_qc/Testing_Script/SummaryPage.sql 2)The Backend result for both "Reporting Period" and "Comparision Period" can be seen in "SP Data" tab. | G3: SP_Data!A1 | H3: Pass
C4: Pharmacy Claims Paid | D4: Verify Pharmacy Claims Paid | F4: http://www.deerwalk.com/repos/dwproject/makalu/docs/quality_control/test_cases/data_qc/1MASTER/Automated_Scripts/Care_Analytics/All_IN_ONE_INCURRED_1_8_0.sql | H4: Pass
C5: Total Healthplan Claims Paid | D5: Verify Total Healthplan Claims Paid | F5: 2)The Backend result for both "Reporting Period" and "Comparision Period" can be seen in "BB Data" tab. | H5: Pass
C6: Subscribers | D6: Verify Subscribers | H6: Pass
C7: Members | D7: Verify Members | H7: Pass
C8: Member Months | D8: Verify Member Months | H8: Pass
C9: Average Contract Size | D9: Verify Average Contract Size | H9: Pass
C10: Acute Care PMPM | D10: Verify Acute Care PMPM | H10: Pass
C11: Outpatient Facility PMPM | D11: Verify Outpatient Facility PMPM | H11: Pass
C12: Professional PMPM | D12: Verify Professional PMPM | H12: Pass
C13: Medical Claims PMPM | D13: Verify Medical Claims PMPM | H13: Pass
C14: Pharmacy Claims PMPM | D14: Verify Pharmacy Claims PMPM | H14: Pass
C15: Other PMPM | D15: Verify Other PMPM | H15: Pass
C16: Total Healthplan Claims PMPM | D16: Verify Total Healthplan Claims PMPM | H16: Pass

Sheet SP_Data
A1: Basis: Paid
A2: Makalu Result (Last Processing) | F2: Makalu Result (Current Processing) | K2: Backend Result
A3: Healthplan Snapshot | B3: Reporting Period | C3: Comparison Period | D3: % Change | F3: Healthplan Snapshot | G3: Reporting Period | H3: Comparison Period | I3: % Change | K3: Healthplan Snapshot | L3: Reporting Period | M3: Comparison Period | N3: % Change | O3: Repo amount check | P3: Comp amount check | Q3: Result
A4: Medical Claims Paid | B4: 61573744 | C4: 45259306 | D4: 0.3605 | F4: Medical Claims Paid | G4: 62592749 | H4: 56142858 | I4: 0.1149 | K4: Medical Claims Paid | L4: 62592749 | M4: 56142858 | N4: 11.49 | O4: =L4-G4 -> -0.13 | P4: =M4-H4 -> -0.46 | Q4: =IF(AND(ROUNDDOWN(O4,0)=0,ROUNDDOWN(P4,0)=0),"PASS","FAIL") -> PASS | R4: Manully tested
A5: Pharmacy Claims Paid | B5: 14810810 | C5: 14446001 | D5: 0.0253 | F5: Pharmacy Claims Paid | G5: 14880889 | H5: 14581890 | I5: 0.0205 | K5: Pharmacy Claims Paid | L5: 14880889 | M5: 14581890 | N5: 2.05 | O5: =L5-G5 -> 0.0099999998 | P5: =M5-H5 -> -0.46 | Q5: =IF(AND(ROUNDDOWN(O5,0)=0,ROUNDDOWN(P5,0)=0),"PASS","FAIL") -> PASS | R5: Manully tested
A6: Total Health Plan Claims Paid | B6: 76384554 | C6: 59705307 | D6: 0.2794 | F6: Total Health Plan Claims Paid | G6: 77473638 | H6: 70724747 | I6: 0.0954 | K6: Total Healthplan Claims Paid | L6: 77473638 | M6: 70724747 | N6: 9.54 | O6: =L6-G6 -> -0.12 | P6: =M6-H6 -> 0.079999998 | Q6: =IF(AND(ROUNDDOWN(O6,0)=0,ROUNDDOWN(P6,0)=0),"PASS","FAIL") -> PASS | R6: Manully tested
A7: Subscribers | B7: 8400 | C7: 8303 | D7: 0.0117 | F7: Subscribers | G7: 8483 | H7: 8298 | I7: 0.0223 | K7: Subscribers | L7: 8483 | M7: 8298 | N7: 2.23 | O7: =L7-G7 -> 0 | P7: =M7-H7 -> 0 | Q7: =IF(AND(ROUNDDOWN(O7,0)=0,ROUNDDOWN(P7,0)=0),"PASS","FAIL") -> PASS | R7: Manully tested
A8: Members | B8: 17524 | C8: 17494 | D8: 0.0017 | F8: Members | G8: 17705 | H8: 17492 | I8: 0.0122 | K8: Members | L8: 17705 | M8: 17492 | N8: 0 | O8: =L8-G8 -> 0 | P8: =M8-H8 -> 0 | Q8: =IF(AND(ROUNDDOWN(O8,0)=0,ROUNDDOWN(P8,0)=0),"PASS","FAIL") -> PASS | R8: Manully tested
A9: Member Months | B9: 212440 | C9: 177746 | D9: 0.1952 | F9: Member Months | G9: 213333 | H9: 212713 | I9: 0.0029 | K9: Member Months | L9: 226040 | M9: 212713 | N9: 6.27 | O9: =L9-G9 -> 12707 | P9: =M9-H9 -> 0 | Q9: =IF(AND(ROUNDDOWN(O9,0)=0,ROUNDDOWN(P9,0)=0),"PASS","FAIL") -> FAIL
A10: Average Family Size | B10: 2.09 | C10: 2.11 | D10: -0.0098 | F10: Average Family Size | G10: 2.09 | H10: 2.11 | I10: -0.0099 | K10: Average Contract Size | L10: 2.81 | M10: 0 | N10: 0 | O10: =L10-G10 -> 0.72 | P10: =M10-H10 -> -2.11 | Q10: =IF(AND(ROUNDDOWN(O10,0)=0,ROUNDDOWN(P10,0)=0),"PASS","FAIL") -> FAIL
A11: Inpatient PMPM | B11: 120.45 | C11: 111.33 | D11: 0.0819 | F11: Inpatient PMPM | G11: 116.61 | H11: 114.28 | I11: 0.0203 | K11: Inpatient PMPM | L11: 110.05 | M11: 114.28 | N11: -3.7 | O11: =L11-G11 -> -6.56 | P11: =M11-H11 -> 0 | Q11: =IF(AND(ROUNDDOWN(O11,0)=0,ROUNDDOWN(P11,0)=0),"PASS","FAIL") -> FAIL
A12: Outpatient PMPM | B12: 126.02 | C12: 104.35 | D12: 0.2076 | F12: Outpatient PMPM | G12: 132.91 | H12: 108.1 | I12: 0.2295 | K12: Outpatient PMPM | L12: 125.43 | M12: 108.09 | N12: 16.04 | O12: =L12-G12 -> -7.48 | P12: =M12-H12 -> -0.01 | Q12: =IF(AND(ROUNDDOWN(O12,0)=0,ROUNDDOWN(P12,0)=0),"PASS","FAIL") -> FAIL
A13: Office Visit PMPM | B13: 43.37 | C13: 38.95 | D13: 0.1136 | F13: Office Visit PMPM | G13: 43.89 | H13: 41.56 | I13: 0.0561 | K13: Office PMPM | L13: 41.42 | M13: 41.55 | N13: -0.31 | O13: =L13-G13 -> -2.47 | P13: =M13-H13 -> -0.01 | Q13: =IF(AND(ROUNDDOWN(O13,0)=0,ROUNDDOWN(P13,0)=0),"PASS","FAIL") -> FAIL
A14: Medical Claims PMPM | B14: 289.84 | C14: 254.63 | D14: 0.1383 | F14: Medical Claims PMPM | G14: 293.4 | H14: 263.94 | I14: 0.1116 | K14: Medical PMPM | L14: 276.91 | M14: 263.93 | N14: 4.92 | O14: =L14-G14 -> -16.49 | P14: =M14-H14 -> -0.01 | Q14: =IF(AND(ROUNDDOWN(O14,0)=0,ROUNDDOWN(P14,0)=0),"PASS","FAIL") -> FAIL
A15: Pharmacy Claims PMPM | B15: 69.72 | C15: 81.27 | D15: -0.1422 | F15: Pharmacy Claims PMPM | G15: 69.75 | H15: 68.55 | I15: 0.0175 | K15: Pharmacy Claims PMPM | L15: 65.83 | M15: 68.55 | N15: -3.97 | O15: =L15-G15 -> -3.92 | P15: =M15-H15 -> 0 | Q15: =IF(AND(ROUNDDOWN(O15,0)=0,ROUNDDOWN(P15,0)=0),"PASS","FAIL") -> FAIL
A16: Medical and Pharmacy Claims PMPM | B16: 359.56 | C16: 335.9 | D16: 0.0704 | F16: Medical and Pharmacy Claims PMPM | G16: 363.16 | H16: 332.49 | I16: 0.0922 | K16: Total Health Plan claims PMPM | L16: 342.74 | M16: 332.48 | N16: 3.09 | O16: =L16-G16 -> -20.42 | P16: =M16-H16 -> -0.01 | Q16: =IF(AND(ROUNDDOWN(O16,0)=0,ROUNDDOWN(P16,0)=0),"PASS","FAIL") -> FAIL
A18: Basis: Incurred
A19: Makalu Result (Last Processing) | F19: Makalu Result (Current Processing) | K19: Backend Result
A20: Healthplan Snapshot | B20: Reporting Period | C20: Comparison Period | D20: % Change | F20: Healthplan Snapshot | G20: Reporting Period | H20: Comparison Period | I20: % Change | K20: Healthplan Snapshot | L20: Reporting Period | M20: Comparison Period | N20: % Change | O20: Repo Amount Diff | P20: Comp Amount Diff | Q20: Result
A21: Medical Claims Paid | B21: 51953972 | C21: 43948438 | D21: 0.1822 | F21: Medical Claims Paid | G21: 53225145 | H21: 48776404 | I21: 0.0912 | K21: Medical Claims Paid | L21: 53225145 | M21: 48776404 | N21: 9.12 | O21: =G21-L21 -> -0.1 | P21: =H21-M21 -> 0.079999998 | Q21: =IF(AND(ROUNDDOWN(O21,0)=0,ROUNDDOWN(P21,0)=0),"PASS","FAIL") -> PASS | R21: Manully tested
A22: Pharmacy Claims Paid | B22: 14297442 | C22: 14221984 | D22: 0.0053 | F22: Pharmacy Claims Paid | G22: 14494637 | H22: 14273024 | I22: 0.0155 | K22: Pharmacy Claims Paid | L22: 14494637 | M22: 14273024 | N22: 1.55 | O22: =G22-L22 -> 0.31 | P22: =H22-M22 -> -0.3 | Q22: =IF(AND(ROUNDDOWN(O22,0)=0,ROUNDDOWN(P22,0)=0),"PASS","FAIL") -> PASS | R22: Manully tested
A23: Total Health Plan Claims Paid | B23: 66251413 | C23: 58170422 | D23: 0.1389 | F23: Total Health Plan Claims Paid | G23: 67719782 | H23: 63049428 | I23: 0.0741 | K23: Total Healthplan Claims Paid | L23: 67719782 | M23: 63049428 | N23: 7.41 | O23: =G23-L23 -> 0.20999999 | P23: =H23-M23 -> -0.22 | Q23: =IF(AND(ROUNDDOWN(O23,0)=0,ROUNDDOWN(P23,0)=0),"PASS","FAIL") -> PASS | R23: Manully tested
A24: Subscribers | B24: 8400 | C24: 8303 | D24: 0.0117 | F24: Subscribers | G24: 8483 | H24: 8298 | I24: 0.0223 | K24: Subscribers | L24: 8483 | M24: 8298 | N24: 2.23 | O24: =G24-L24 -> 0 | P24: =H24-M24 -> 0 | Q24: =IF(AND(ROUNDDOWN(O24,0)=0,ROUNDDOWN(P24,0)=0),"PASS","FAIL") -> PASS | R24: Manully tested
A25: Members | B25: 17524 | C25: 17494 | D25: 0.0017 | F25: Members | G25: 17705 | H25: 17492 | I25: 0.0122 | K25: Members | L25: 17705 | M25: 17492 | N25: 0.0122 | O25: =G25-L25 -> 0 | P25: =H25-M25 -> 0 | Q25: =IF(AND(ROUNDDOWN(O25,0)=0,ROUNDDOWN(P25,0)=0),"PASS","FAIL") -> PASS | R25: Manully tested
A26: Member Months | B26: 212440 | C26: 177746 | D26: 0.1952 | F26: Member Months | G26: 213333 | H26: 212713 | I26: 0.0029 | K26: Member Months | L26: 226040 | M26: 212713 | N26: 6.27 | O26: =G26-L26 -> -12707 | P26: =H26-M26 -> 0 | Q26: =IF(AND(ROUNDDOWN(O26,0)=0,ROUNDDOWN(P26,0)=0),"PASS","FAIL") -> FAIL
A27: Average Family Size | B27: 2.09 | C27: 2.11 | D27: -0.0098 | F27: Average Family Size | G27: 2.09 | H27: 2.11 | I27: -0.0099 | K27: Average Contract Size | L27: 2.81 | M27: 0 | N27: 0 | O27: =G27-L27 -> -0.72 | P27: =H27-M27 -> 2.11 | Q27: =IF(AND(ROUNDDOWN(O27,0)=0,ROUNDDOWN(P27,0)=0),"PASS","FAIL") -> FAIL
A28: Inpatient PMPM | B28: 92.12 | C28: 107.98 | D28: -0.1469 | F28: Inpatient PMPM | G28: 94 | H28: 95.92 | I28: -0.0201 | K28: Inpatient PMPM | L28: 88.71 | M28: 95.91 | N28: -7.51 | O28: =G28-L28 -> 5.29 | P28: =H28-M28 -> 0.01 | Q28: =IF(AND(ROUNDDOWN(O28,0)=0,ROUNDDOWN(P28,0)=0),"PASS","FAIL") -> FAIL
A29: Outpatient PMPM | B29: 113.07 | C29: 101.3 | D29: 0.1162 | F29: Outpatient PMPM | G29: 116.13 | H29: 96.33 | I29: 0.2055 | K29: Outpatient PMPM | L29: 109.6 | M29: 96.33 | N29: 13.78 | O29: =G29-L29 -> 6.53 | P29: =H29-M29 -> 0 | Q29: =IF(AND(ROUNDDOWN(O29,0)=0,ROUNDDOWN(P29,0)=0),"PASS","FAIL") -> FAIL
A30: Office Visit PMPM | B30: 39.37 | C30: 37.97 | D30: 0.0369 | F30: Office Visit PMPM | G30: 39.37 | H30: 37.06 | I30: 0.0624 | K30: Office PMPM | L30: 37.15 | M30: 37.05 | N30: 0.27 | O30: =G30-L30 -> 2.22 | P30: =H30-M30 -> 0.01 | Q30: =IF(AND(ROUNDDOWN(O30,0)=0,ROUNDDOWN(P30,0)=0),"PASS","FAIL") -> FAIL
A31: Medical Claims PMPM | B31: 244.56 | C31: 247.25 | D31: -0.0109 | F31: Medical Claims PMPM | G31: 249.49 | H31: 229.31 | I31: 0.088 | K31: Medical PMPM | L31: 235.46 | M31: 229.3 | N31: 2.69 | O31: =G31-L31 -> 14.03 | P31: =H31-M31 -> 0.01 | Q31: =IF(AND(ROUNDDOWN(O31,0)=0,ROUNDDOWN(P31,0)=0),"PASS","FAIL") -> FAIL
A32: Pharmacy Claims PMPM | B32: 67.3 | C32: 80.01 | D32: -0.1589 | F32: Pharmacy Claims PMPM | G32: 67.94 | H32: 67.1 | I32: 0.0126 | K32: Pharmacy Claims PMPM | L32: 64.12 | M32: 67.09 | N32: -4.43 | O32: =G32-L32 -> 3.82 | P32: =H32-M32 -> 0.01 | Q32: =IF(AND(ROUNDDOWN(O32,0)=0,ROUNDDOWN(P32,0)=0),"PASS","FAIL") -> FAIL
A33: Medical and Pharmacy Claims PMPM | B33: 311.86 | C33: 327.27 | D33: -0.0471 | F33: Medical and Pharmacy Claims PMPM | G33: 317.44 | H33: 296.41 | I33: 0.071 | K33: Total Health Plan claims PMPM | L33: 299.59 | M33: 296.4 | N33: 1.08 | O33: =G33-L33 -> 17.85 | P33: =H33-M33 -> 0.01 | Q33: =IF(AND(ROUNDDOWN(O33,0)=0,ROUNDDOWN(P33,0)=0),"PASS","FAIL") -> FAIL
A35: Basis: Paid | F35: Basis: Incurrred
A36: Trending Analysis ( Diff of 10 % is considered for Monthly Clients ) | F36: Trending Analysis ( Diff of 10 % is considered for Monthly Clients )
A37: Healthplan Snapshot | B37: Reporting Period | C37: Comparison Period | D37: Result | F37: Healthplan Snapshot | G37: Reporting Period | H37: Comparison Period | I37: Result | L37: Front End Total Member | M37: Backend Total Members | N37: Result
A38: Medical Claims Paid | B38: =IF(G4=0, 0%,(G4-B4)/G4) -> 0.016279921 | C38: =IF(H4=0, 0%,(H4-C4)/H4) -> 0.19385461 | D38: =IF(AND(B38<=10%,C38<=10%,B38>=-10%,C38>=-10%),"PASS","FAIL") -> FAIL | F38: Medical Claims Paid | G38: =IF(G21=0, 0%,(G21-B21)/G21) -> 0.023882941 | H38: =IF(H21=0, 0%,(H21-C21)/H21) -> 0.09898159 | I38: =IF(AND(G38<=10%,H38<=10%,G38>=-10%,H38>=-10%),"PASS","FAIL") -> PASS | K38: Medical | L38: 984425 | M38: 984425 | N38: =IF(EXACT(L38,M38),"PASS","FAIL") -> PASS
A39: Pharmacy Claims Paid | B39: =IF(G5=0, 0%,(G5-B5)/G5) -> 0.0047093289 | C39: =IF(H5=0, 0%,(H5-C5)/H5) -> 0.0093190252 | D39: =IF(AND(B39<=10%,C39<=10%,B39>=-10%,C39>=-10%),"PASS","FAIL") -> PASS | F39: Pharmacy Claims Paid | G39: =IF(G22=0, 0%,(G22-B22)/G22) -> 0.013604687 | H39: =IF(H22=0, 0%,(H22-C22)/H22) -> 0.0035759766 | I39: =IF(AND(G39<=10%,H39<=10%,G39>=-10%,H39>=-10%),"PASS","FAIL") -> PASS | K39: Pharmacy | L39: 288378 | M39: 288378 | N39: =IF(EXACT(L39,M39),"PASS","FAIL") -> PASS
A40: Total Healthplan Claims Paid | B40: =IF(G6=0, 0%,(G6-B6)/G6) -> 0.014057478 | C40: =IF(H6=0, 0%,(H6-C6)/H6) -> 0.15580741 | D40: =IF(AND(B40<=10%,C40<=10%,B40>=-10%,C40>=-10%),"PASS","FAIL") -> FAIL | F40: Total Healthplan Claims Paid | G40: =IF(G23=0, 0%,(G23-B23)/G23) -> 0.021683014 | H40: =IF(H23=0, 0%,(H23-C23)/H23) -> 0.077383827 | I40: =IF(AND(G40<=10%,H40<=10%,G40>=-10%,H40>=-10%),"PASS","FAIL") -> PASS | K40: Eligibility | L40: 164648 | M40: 164648 | N40: =IF(EXACT(L40,M40),"PASS","FAIL") -> PASS
A41: Subscribers | B41: =IF(G7=0, 0%,(G7-B7)/G7) -> 0.0097842744 | C41: =IF(H7=0, 0%,(H7-C7)/H7) -> -0.00060255483 | D41: =IF(AND(B41<=10%,C41<=10%,B41>=-10%,C41>=-10%),"PASS","FAIL") -> PASS | F41: Subscribers | G41: =IF(G24=0, 0%,(G24-B24)/G24) -> 0.0097842744 | H41: =IF(H24=0, 0%,(H24-C24)/H24) -> -0.00060255483 | I41: =IF(AND(G41<=10%,H41<=10%,G41>=-10%,H41>=-10%),"PASS","FAIL") -> PASS | K41: Active | L41: 17705 | M41: 17705 | N41: =IF(EXACT(L41,M41),"PASS","FAIL") -> PASS
A42: Members | B42: =IF(G8=0, 0%,(G8-B8)/G8) -> 0.010223101 | C42: =IF(H8=0, 0%,(H8-C8)/H8) -> -0.00011433798 | D42: =IF(AND(B42<=10%,C42<=10%,B42>=-10%,C42>=-10%),"PASS","FAIL") -> PASS | F42: Members | G42: =IF(G25=0, 0%,(G25-B25)/G25) -> 0.010223101 | H42: =IF(H25=0, 0%,(H25-C25)/H25) -> -0.00011433798 | I42: =IF(AND(G42<=10%,H42<=10%,G42>=-10%,H42>=-10%),"PASS","FAIL") -> PASS
...

Sheet Group Summary
A1: Testing Environment | B1: Section | C1: Sub-Section | D1: Test Summary | E1: Makalu Test Procedure | F1: Backend Test Procedure | G1: Test Data | H1: Test Result | I1: Related Defects | J1: Remarks
H2: DATE
A3: MSSQL 2008 R2 | B3: Dashboard | C3: Group | D3: Verify Group Name | E3: 1) Login to Makalu 2) Check groupwise data from dashboard. | F3: 1) Run the query from following svn path | G3: Dash_board_data | H3: Pass
C4: # of Subscribers | D4: Verify Subscribers count. | F4: http://www.deerwalk.com/repos/dwproject/makalu/docs/quality_control/test_cases/data_qc/1MASTER/Automated_Scripts/Care_Analytics/All_IN_ONE_INCURRED_1_8_0.sql | H4: Pass
C5: # of Members | D5: Verify Member count. | F5: 2) Tally Makalu data with executed SQL result. | H5: Pass
C6: Med Paid | D6: Verify Med Paid amount | H6: Pass
C7: Rx Paid | D7: Verify Rx Paid amount | H7: Pass
C8: Total Paid | H8: Pass
C9: Med PEPM | D9: Verify Med PEPM | H9: Pass
C10: Rx PEPM | D10: Verify Rx PEPM | H10: Pass
C11: Total PEPM | D11: Verify Total PEPM | H11: Pass
C12: Group Risk Score | D12: Verify Group Risk Score | H12: Pass

Sheet Group Summary Data
A1: Basis: Incurred
A2: Makalu Result (Current Processing) | L2: Scrub Result
A3: Group | B3: # of Subscribers | C3: # of Members | D3: Med Paid | E3: Rx Paid | F3: Total Paid | G3: Med PEPM | H3: Rx PEPM | I3: Total PEPM | J3: Group Risk Score | L3: SN | M3: Group | N3: # of Subscribers | O3: # of Members | P3: Med Paid | Q3: Rx Paid | R3: Total Paid | S3: Med PEPM | T3: Rx PEPM | U3: Total PEPM
A4: School District of Manatee County | B4: 5221 | C4: 10238 | D4: 26186950 | E4: 13260811 | F4: 39447762 | G4: 458.11 | H4: 231.98 | I4: 690.09 | J4: 1.02 | L4: 1 | M4: School District of Manatee County | N4: 5221 | O4: 10238 | P4: 26186950 | Q4: 13260811 | R4: =SUM(N4:Q4) -> 39463221 | S4: 458.11 | T4: 231.98 | U4: 690.09
A5: Alachua County BOCC | B5: 2410 | C5: 4744 | D5: 16018971 | E5: 4101898.7 | F5: 20120870 | G5: 582.21 | H5: 149.08 | I5: 731.3 | J5: 0.95 | L5: 2 | M5: Alachua County BOCC | N5: 2410 | O5: 4744 | P5: 16018971 | Q5: 4101898.7 | R5: 20120870 | S5: 582.21 | T5: 149.08 | U5: 731.3
A6: Page Total | B6: 7631 | C6: 14982 | D6: 42205922 | E6: 17362710 | F6: 59568632 | G6: 498.43 | H6: 205.05 | I6: 703.48 | N6: =SUM(N4:N5) -> 7631 | O6: =SUM(O4:O5) -> 14982 | P6: =SUM(P4:P5) -> 42205922 | Q6: =SUM(Q4:Q5) -> 17362710 | R6: =SUM(R4:R5) -> 59584091 | S6: =SUM(S4:S5) -> 1040.32 | T6: =SUM(T4:T5) -> 381.06
A7: Total | B7: 7631 | C7: 14982 | D7: 42205922 | E7: 17362710 | F7: 59568632 | G7: 498.43 | H7: 205.05 | I7: 703.48 | N7: =SUM(N4:N6) -> 15262 | O7: =SUM(O4:O6) -> 29964 | P7: =SUM(N7:O7) -> 45226 | Q7: =SUM(Q4:Q6) -> 34725420 | R7: =SUM(R6) -> 59584091 | S7: =SUM(S6) -> 1040.32 | T7: =SUM(T5:T6) -> 530.14
A9: Result
A10: SN | B10: Group | C10: # of Subscribers | D10: # of Members | E10: Med Paid | F10: Rx Paid | G10: Total Paid | H10: Med PEPM | I10: Rx PEPM | J10: Total PEPM | K10: Result
A11: 1 | B11: =IF(EXACT(A4,M4),""&A4,"Different Name: "&A4) -> School District of Manatee County | C11: =B4-N4 -> 0 | D11: =C4-O4 -> 0 | E11: =D4-P4 -> 0 | F11: =E4-Q4 -> 0 | G11: =F4-R4 -> -15459 | H11: =G4-S4 -> 0 | I11: =H4-T4 -> 0 | J11: =I4-U4 -> 0 | K11: =IF(AND(EXACT(C11,0),EXACT(D11,0),ROUNDDOWN(E11,0)=0,ROUNDDOWN(F11,0)=0,ROUNDDOWN(G11,0)=0,ROUNDDOWN(H11,0)=0,ROUNDDOWN(I11,0)=0,ROUNDDOWN(J11,0)=0),"TRUE","FALSE") -> FALSE
A12: 2 | B12: =IF(EXACT(A6,M6),""&A6,"Different Name: "&A6) -> Different Name: Page Total | C12: =B6-N6 -> 0 | D12: =C6-O6 -> 0 | E12: =D6-P6 -> 0.0099999979 | F12: =E6-Q6 -> 0 | G12: =F6-R6 -> -15458.99 | H12: =G6-S6 -> -541.89 | I12: =H6-T6 -> -176.01 | J12: =I6-U6 -> 703.48 | K12: =IF(AND(EXACT(C12,0),EXACT(D12,0),ROUNDDOWN(E12,0)=0,ROUNDDOWN(F12,0)=0,ROUNDDOWN(G12,0)=0,ROUNDDOWN(H12,0)=0,ROUNDDOWN(I12,0)=0,ROUNDDOWN(J12,0)=0),"TRUE","FALSE") -> FALSE

Sheet HealthCareTrend
A1: Testing Environment | B1: Section | C1: Sub-Section | E1: Test Summary | F1: Makalu Test Procedure | G1: Backend Test Procedure | H1: Test Data | I1: Test Result | J1: Related Defects | K1: Remarks
I2: 41215
A3: MSSQL 2008 R2 | B3: Trending report | C3: Perodic | D3: 1) Count 2) Amount | E3: 1) Verify # Employees Verify # Members Verify # Avg Age Verify Avg Family Size Verify Gender Mix (% of Verify Female) Verify # Claimants Verify # Claim Lines Verify Total Dollars (in thousand) Verify Avg. claims/member Verify Avg Lines/Members Verify % of claimants to members Verify Avg. turnaround incurred to paid Verify Claims/1000 cov. lives Verify E & M visits/1000 covered lives Verify Procedure/1000 covered lives Verify Avg Claim Cost Verify Avg Cost/claimants Verify Avg Lines/Claimants Verify % Paid In-Network (Facility) Verify % In Paid In-Network (Professional) Verify % In Paid In-Network (Total) | F3: 1) Login to Makalu 2) Click "Care Analytics" 3) Select Default values(Basis and Period) 3) Click "Select" 4) Click "Trending Analysis" 5) The Makalu trending result for monthly and perodic can be seen in report. | G3: 1) Run the query from svn path | H3: Periodic Analysis'!A1 | I3: Pass
I4: Pass
G5: 2) The Backend result for both periodic and monthwise and can be seen in "trending data " tab. | I5: Pass
C6: Monthwise | I6: Pass

Sheet Periodic Analysis
A1: Medical_Periodic_Analysis
A3: Makalu Result (Last Processing) | E3: Makalu Result (Current Processing) | I3: Scrub Result
B4: Reporting Period | C4: Comparison Period | F4: Reporting Period | G4: Comparison Period | J4: Reporting Period | K4: Comparison Period | L4: Reporting Check | M4: Comparison Check | N4: Result
A5: # Employees | B5: 7468 | C5: 6766 | E5: # Employees | I5: # Employees | J5: 7631 | K5: 6773 | L5: =SUM(J5-F5) -> 7631 | M5: =SUM(K5-G5) -> 6773 | N5: =IF(AND(ROUNDDOWN(L5,0)=0,ROUNDDOWN(M5,0)=0),"PASS","FAIL") -> FAIL
A6: # Members | B6: 14638 | C6: 13256 | E6: # Members | I6: # Members | J6: 14982 | K6: 13257 | L6: =SUM(J6-F6) -> 14982 | M6: =SUM(K6-G6) -> 13257 | N6: =IF(AND(ROUNDDOWN(L6,0)=0,ROUNDDOWN(M6,0)=0),"PASS","FAIL") -> FAIL
A7: Avg Age | B7: 38.25 | C7: 39.12 | E7: Avg Age | I7: # Avg Age | J7: 38.3017 | K7: 37.3017 | L7: =SUM(J7-F7) -> 38.3017 | M7: =SUM(K7-G7) -> 37.3017 | N7: =IF(AND(ROUNDDOWN(L7,0)=0,ROUNDDOWN(M7,0)=0),"PASS","FAIL") -> FAIL
A8: Avg Family Size | B8: 1.96 | C8: 1.96 | E8: Avg Family Size | I8: Avg Family Size | J8: 2 | K8: 1.96 | L8: =SUM(J8-F8) -> 2 | M8: =SUM(K8-G8) -> 1.96 | N8: =IF(AND(ROUNDDOWN(L8,0)=0,ROUNDDOWN(M8,0)=0),"PASS","FAIL") -> FAIL
A9: Gender Mix (% of Female) | B9: 0.56 | C9: 0.5591 | E9: Gender Mix (% of Female) | I9: Gender Mix (% of Female) | J9: 55.9471 | K9: 55.9101 | L9: =SUM(J9-F9) -> 55.9471 | M9: =SUM(K9-G9) -> 55.9101 | N9: =IF(AND(ROUNDDOWN(L9,0)=0,ROUNDDOWN(M9,0)=0),"PASS","FAIL") -> FAIL
A10: # Claimants | B10: 12736 | C10: 12998 | E10: # Claimants | I10: # Claimants | J10: 13056 | K10: 13010 | L10: =SUM(J10-F10) -> 13056 | M10: =SUM(K10-G10) -> 13010 | N10: =IF(AND(ROUNDDOWN(L10,0)=0,ROUNDDOWN(M10,0)=0),"PASS","FAIL") -> FAIL
A11: # Claims | B11: 169139 | C11: 184769 | E11: # Claims | I11: # Claims | J11: 183848 | K11: 186135 | L11: =SUM(J11-F11) -> 183848 | M11: =SUM(K11-G11) -> 186135 | N11: =IF(AND(ROUNDDOWN(L11,0)=0,ROUNDDOWN(M11,0)=0),"PASS","FAIL") -> FAIL
A12: Total Dollars (in thousands) | B12: 41059.94 | C12: 40283.53 | E12: Total Dollars (in thousands) | I12: Total Dollars (in thousand) | J12: 44785.452 | K12: 40270.474 | L12: =SUM(J12-F12) -> 44785.452 | M12: =SUM(K12-G12) -> 40270.474 | N12: =IF(AND(ROUNDDOWN(L12,0)=0,ROUNDDOWN(M12,0)=0),"PASS","FAIL") -> FAIL
A13: Avg. claims/member | B13: 11.55 | C13: 13.94 | E13: Avg. claims/member | I13: Avg. claims/member | J13: 12.2713 | K13: 14.0405 | L13: =SUM(J13-F13) -> 12.2713 | M13: =SUM(K13-G13) -> 14.0405 | N13: =IF(AND(ROUNDDOWN(L13,0)=0,ROUNDDOWN(M13,0)=0),"PASS","FAIL") -> FAIL
A14: Avg. lines/member | B14: 29.24 | C14: 34.08 | E14: Avg. lines/member | I14: Avg Lines/Members | J14: 10.2287 | K14: 9.6977 | L14: =SUM(J14-F14) -> 10.2287 | M14: =SUM(K14-G14) -> 9.6977 | N14: =IF(AND(ROUNDDOWN(L14,0)=0,ROUNDDOWN(M14,0)=0),"PASS","FAIL") -> FAIL
A15: % of claimants to members | B15: 0.8701 | C15: 0.9805 | E15: % of claimants to members | I15: % of claimants to members | J15: 0.871446 | K15: 0.981368 | L15: =SUM(J15-F15) -> 0.871446 | M15: =SUM(K15-G15) -> 0.981368 | N15: =IF(AND(ROUNDDOWN(L15,0)=0,ROUNDDOWN(M15,0)=0),"PASS","FAIL") -> PASS
A16: Avg. turnaround incurred to paid | B16: 35.09 | C16: 35.83 | E16: Avg. turnaround incurred to paid | I16: Avg. turnaround incurred to paid | J16: 31.5 | K16: 32.21 | L16: =SUM(J16-F16) -> 31.5 | M16: =SUM(K16-G16) -> 32.21 | N16: =IF(AND(ROUNDDOWN(L16,0)=0,ROUNDDOWN(M16,0)=0),"PASS","FAIL") -> FAIL
A17: Claims/1000 covered lives | B17: 12257.71 | C17: 13774.85 | E17: Claims/1000 covered lives | I17: Claims/1000 cov. lives | J17: 12271.3 | K17: 14040.5 | L17: =SUM(J17-F17) -> 12271.3 | M17: =SUM(K17-G17) -> 14040.5 | N17: =IF(AND(ROUNDDOWN(L17,0)=0,ROUNDDOWN(M17,0)=0),"PASS","FAIL") -> FAIL
A18: Procedure/1000 covered lives | B18: 27522.83 | C18: 29742.57 | E18: Procedure/1000 covered lives | I18: Procedure/1000 covered lives | J18: NULL | K18: NULL | L18: =SUM(J18-F18) -> #VALUE! | M18: =SUM(K18-G18) -> #VALUE! | N18: =IF(AND(ROUNDDOWN(L18,0)=0,ROUNDDOWN(M18,0)=0),"PASS","FAIL") -> #VALUE!
A19: Inpatient Days/1,000 | B19: 404.17 | C19: 397.06 | E19: Inpatient Days/1,000 | I19: Avg Claim Cost | J19: 243.6 | K19: 216.351
A20: ER visits/1000 covered lives | B20: 184.87 | C20: 186.23 | E20: ER visits/1000 covered lives | I20: Avg Cost/claimants | J20: 3430.26 | K20: 3095.35 | L20: =SUM(J20-F20) -> 3430.26 | M20: =SUM(K20-G20) -> 3095.35 | N20: =IF(AND(ROUNDDOWN(L20,0)=0,ROUNDDOWN(M20,0)=0),"PASS","FAIL") -> FAIL
A21: Avg Claim Cost | B21: 242.76 | C21: 218.02 | E21: Avg Claim Cost | I21: Avg Lines/Claimants | J21: NULL | K21: NULL | L21: =SUM(J21-F21) -> #VALUE! | M21: =SUM(K21-G21) -> #VALUE! | N21: =IF(AND(ROUNDDOWN(L21,0)=0,ROUNDDOWN(M21,0)=0),"PASS","FAIL") -> #VALUE!
A22: Avg Cost/claimants | B22: 3223.93 | C22: 3099.21 | E22: Avg Cost/claimants | I22: % Paid In-Network (Facility) | J22: 99.7239 | K22: 100.528 | L22: =SUM(J22-F22) -> 99.7239 | M22: =SUM(K22-G22) -> 100.528 | N22: =IF(AND(ROUNDDOWN(L22,0)=0,ROUNDDOWN(M22,0)=0),"PASS","FAIL") -> FAIL
A23: Avg Lines/claimants | B23: 33.6 | C23: 34.76 | E23: Avg Lines/claimants | I23: % In Paid In-Network (Professional) | J23: 93.4445 | K23: 95.0595 | L23: =SUM(J23-F23) -> 93.4445 | M23: =SUM(K23-G23) -> 95.0595 | N23: =IF(AND(ROUNDDOWN(L23,0)=0,ROUNDDOWN(M23,0)=0),"PASS","FAIL") -> FAIL
A24: % In Paid In-Network (Facility) | B24: 0.9973 | C24: 1.0053 | E24: % In Paid In-Network (Facility) | I24: % In Paid In-Network (Total) | J24: 96.8629 | K24: 97.9248 | L24: =SUM(J24-F24) -> 96.8629 | M24: =SUM(K24-G24)*100 -> 9792.48 | N24: =IF(AND(ROUNDDOWN(L24,0)=0,ROUNDDOWN(M24,0)=0),"PASS","FAIL") -> FAIL
A25: % In Paid In-Network (Professional) | B25: 0.9356 | C25: 0.9506 | E25: % In Paid In-Network (Professional) | L25: =SUM(J25-F25) -> 0 | M25: =SUM(K25-G25)*100 -> 0 | N25: =IF(AND(ROUNDDOWN(L25,0)=0,ROUNDDOWN(M25,0)=0),"PASS","FAIL") -> PASS
A26: % In Paid In-Network (Total) | B26: 0.9692 | C26: 0.9792 | E26: % In Paid In-Network (Total) | L26: =SUM(J26-F26) -> 0 | M26: =SUM(K26-G26)*100 -> 0 | N26: =IF(AND(ROUNDDOWN(L26,0)=0,ROUNDDOWN(M26,0)=0),"PASS","FAIL") -> PASS
A28: Pharmacy_Periodic_Analysis
A30: Makalu Result (Last Processing) | E30: Makalu Result (Current Processing) | I30: Scrub Result
B31: Reporting Period | C31: Comparison Period | F31: Reporting Period | G31: Comparison Period | J31: Reporting Period | K31: Comparison Period | L31: Reporting Check | M31: Comparison Check | N31: Result
A32: # Employees | B32: 7468 | C32: 6766 | I32: # Employees | J32: 7631 | K32: 6773 | L32: =SUM(J32-F32) -> 7631 | M32: =SUM(K32-G32) -> 6773 | N32: =IF(AND(ROUNDDOWN(L32,0)=0,ROUNDDOWN(M32,0)=0),"PASS","FAIL") -> FAIL
A33: # Members | B33: 14638 | C33: 13256 | I33: # Members | J33: 14982 | K33: 13257 | L33: =SUM(J33-F33) -> 14982 | M33: =SUM(K33-G33) -> 13257 | N33: =IF(AND(ROUNDDOWN(L33,0)=0,ROUNDDOWN(M33,0)=0),"PASS","FAIL") -> FAIL
A34: # Avg Age | B34: 38.25 | C34: 39.12 | I34: # Avg Age | J34: 38.3017 | K34: 37.3017 | L34: =SUM(J34-F34) -> 38.3017 | M34: =SUM(K34-G34) -> 37.3017 | N34: =IF(AND(ROUNDDOWN(L34,0)=0,ROUNDDOWN(M34,0)=0),"PASS","FAIL") -> FAIL
A35: Avg Family Size | B35: 1.96 | C35: 1.96 | I35: Avg Family Size | J35: 2 | K35: 1.96 | L35: =SUM(J35-F35) -> 2 | M35: =SUM(K35-G35) -> 1.96 | N35: =IF(AND(ROUNDDOWN(L35,0)=0,ROUNDDOWN(M35,0)=0),"PASS","FAIL") -> FAIL
A36: Gender Mix (% of Female) | B36: 0.56 | C36: 0.5591 | I36: Gender Mix (% of Female) | J36: 0.559471 | K36: 0.559101 | L36: =SUM(J36-F36) -> 0.559471 | M36: =SUM(K36-G36) -> 0.559101 | N36: =IF(AND(ROUNDDOWN(L36,0)=0,ROUNDDOWN(M36,0)=0),"PASS","FAIL") -> PASS
A37: # Claimants | B37: 10988 | C37: 10951 | I37: # Claimants | J37: 11263 | K37: 10950 | L37: =SUM(J37-F37) -> 11263 | M37: =SUM(K37-G37) -> 10950 | N37: =IF(AND(ROUNDDOWN(L37,0)=0,ROUNDDOWN(M37,0)=0),"PASS","FAIL") -> FAIL
A38: # Scripts | B38: 146550 | C38: 153156 | I38: # Scripts | J38: 159443 | K38: 153120 | L38: =SUM(J38-F38) -> 159443 | M38: =SUM(K38-G38) -> 153120 | N38: =IF(AND(ROUNDDOWN(L38,0)=0,ROUNDDOWN(M38,0)=0),"PASS","FAIL") -> FAIL
A39: Total Dollars (in thousand) | B39: 16017.78 | C39: 15130.98 | I39: Total Dollars (in thousand) | J39: 17417.32 | K39: 15125.67 | L39: =SUM(J39-F39) -> 17417.32 | M39: =SUM(K39-G39) -> 15125.67 | N39: =IF(AND(ROUNDDOWN(L39,0)=0,ROUNDDOWN(M39,0)=0),"PASS","FAIL") -> FAIL
A40: % of claimants to members | B40: 0.7506 | C40: 0.8261 | I40: % of claimants to members | J40: 0.751769 | K40: 0.825979 | L40: =SUM(J40-F40) -> 0.751769 | M40: =SUM(K40-G40) -> 0.825979 | N40: =IF(AND(ROUNDDOWN(L40,0)=0,ROUNDDOWN(M40,0)=0),"PASS","FAIL") -> PASS
A41: Avg. script cost | B41: 109.3 | C41: 98.79 | I41: Avg. script cost | J41: 109.239 | K41: 98.7831 | L41: =SUM(J41-F41) -> 109.239 | M41: =SUM(K41-G41) -> 98.7831 | N41: =IF(AND(ROUNDDOWN(L41,0)=0,ROUNDDOWN(M41,0)=0),"PASS","FAIL") -> FAIL
A42: Avg. scripts/claimant | B42: 13.34 | C42: 13.99 | I42: Avg. scripts/claimant | J42: 14.1564 | K42: 13.9836 | L42: =SUM(J42-F42) -> 14.1564 | M42: =SUM(K42-G42) -> 13.9836 | N42: =IF(AND(ROUNDDOWN(L42,0)=0,ROUNDDOWN(M42,0)=0),"PASS","FAIL") -> FAIL
A43: Avg. scripts/member | B43: 10.01 | C43: 11.55 | I43: Avg. scripts/member | J43: 10.6423 | K43: 11.5501 | L43: =SUM(J43-F43) -> 10.6423 | M43: =SUM(K43-G43) -> 11.5501 | N43: =IF(AND(ROUNDDOWN(L43,0)=0,ROUNDDOWN(M43,0)=0),"PASS","FAIL") -> FAIL
...

Sheet Monthly Analysis
A1: Basis: Incurred
A2: Medical Monthly Analysis | S2: Pharmacy Monthly Analysis
A4: Makalu Result (Last Processing) | S4: Makalu Result (Last Processing)
B5: Avg | C5: Jun | D5: Jul | E5: Aug | F5: Sep | G5: Oct | H5: Nov | I5: Dec | J5: Jan | K5: Feb | L5: Mar | M5: Apr | N5: May | T5: Avg | U5: Jun | V5: Jul | W5: Aug | X5: Sep | Y5: Oct | Z5: Nov | AA5: Dec | AB5: Jan | AC5: Feb | AD5: Mar | AE5: Apr | AF5: May
A6: # Employees | B6: 7035 | C6: 6763 | D6: 6783 | E6: 6785 | F6: 6799 | G6: 6850 | H6: 6887 | I6: 6930 | J6: 6976 | K6: 7297 | L6: 7408 | M6: 7484 | N6: 7468 | S6: # Employees | T6: 7035.83 | U6: 6763 | V6: 6783 | W6: 6785 | X6: 6799 | Y6: 6850 | Z6: 6887 | AA6: 6930 | AB6: 6976 | AC6: 7297 | AD6: 7408 | AE6: 7484 | AF6: 7468
A7: # Members | B7: 13798 | C7: 13263 | D7: 13297 | E7: 13301 | F7: 13342 | G7: 13434 | H7: 13502 | I7: 13599 | J7: 13696 | K7: 14325 | L7: 14522 | M7: 14664 | N7: 14638 | S7: # Members | T7: 13798.58 | U7: 13263 | V7: 13297 | W7: 13301 | X7: 13342 | Y7: 13434 | Z7: 13502 | AA7: 13599 | AB7: 13696 | AC7: 14325 | AD7: 14522 | AE7: 14664 | AF7: 14638
A8: Avg Age | B8: 38.68 | C8: 39.06 | D8: 39.04 | E8: 38.98 | F8: 38.93 | G8: 38.85 | H8: 38.8 | I8: 38.74 | J8: 38.7 | K8: 38.33 | L8: 38.27 | M8: 38.24 | N8: 38.25 | S8: Avg Age | T8: 38.68 | U8: 39.06 | V8: 39.04 | W8: 38.98 | X8: 38.93 | Y8: 38.85 | Z8: 38.8 | AA8: 38.74 | AB8: 38.7 | AC8: 38.33 | AD8: 38.27 | AE8: 38.24 | AF8: 38.25
A9: Avg Family Size | B9: 1.96 | C9: 1.96 | D9: 1.96 | E9: 1.96 | F9: 1.96 | G9: 1.96 | H9: 1.96 | I9: 1.96 | J9: 1.96 | K9: 1.96 | L9: 1.96 | M9: 1.96 | N9: 1.96 | S9: Avg Family Size | T9: 1.96 | U9: 1.96 | V9: 1.96 | W9: 1.96 | X9: 1.96 | Y9: 1.96 | Z9: 1.96 | AA9: 1.96 | AB9: 1.96 | AC9: 1.96 | AD9: 1.96 | AE9: 1.96 | AF9: 1.96
A10: Gender Mix (% of Female) | B10: 0.5586 | C10: 0.5591 | D10: 0.5589 | E10: 0.5589 | F10: 0.559 | G10: 0.5575 | H10: 0.5573 | I10: 0.557 | J10: 0.5573 | K10: 0.5586 | L10: 0.5594 | M10: 0.5601 | N10: 0.56 | S10: Gender Mix (% of Female) | T10: 0.5586 | U10: 0.5591 | V10: 0.5589 | W10: 0.5589 | X10: 0.559 | Y10: 0.5575 | Z10: 0.5573 | AA10: 0.557 | AB10: 0.5573 | AC10: 0.5586 | AD10: 0.5594 | AE10: 0.5601 | AF10: 0.56
A11: # Claimants | B11: 4899 | C11: 5479 | D11: 5189 | E11: 5293 | F11: 5104 | G11: 5309 | H11: 5367 | I11: 5261 | J11: 5105 | K11: 5677 | L11: 4931 | M11: 5664 | N11: 420 | S11: # Claimants | T11: 4769.08 | U11: 4972 | V11: 5247 | W11: 5315 | X11: 5084 | Y11: 5068 | Z11: 5072 | AA11: 4909 | AB11: 5065 | AC11: 5837 | AD11: 5184 | AE11: 5476 | AF11: 0
A12: # Claims | B12: 14094 | C12: 16105 | D12: 14409 | E12: 15621 | F12: 14183 | G12: 15261 | H12: 15878 | I12: 15047 | J12: 14978 | K12: 17374 | L12: 12861 | M12: 16833 | N12: 589 | S12: # Scripts | T12: 12212.5 | U12: 12173 | V12: 13247 | W12: 14251 | X12: 12896 | Y12: 12598 | Z12: 13655 | AA12: 12289 | AB12: 12776 | AC12: 15132 | AD12: 12812 | AE12: 14721 | AF12: 0
A13: Total Dollars (in thousands) | B13: 3421.66 | C13: 3301.67 | D13: 3380.89 | E13: 3612.8 | F13: 3148.9 | G13: 3984.61 | H13: 3835.42 | I13: 3971.48 | J13: 3601.66 | K13: 3531.9 | L13: 4221.11 | M13: 4372.39 | N13: 97.12 | S13: Employer Cost (in thousands) | T13: 1334.82 | U13: 1122.37 | V13: 1441.75 | W13: 1573.66 | X13: 1499.01 | Y13: 1596.11 | Z13: 1549.79 | AA13: 1382.97 | AB13: 1410.66 | AC13: 1457.55 | AD13: 1392.05 | AE13: 1591.85 | AF13: 0
A14: Actual PEPM | B14: 488.44 | C14: 488.2 | D14: 498.44 | E14: 532.47 | F14: 463.14 | G14: 581.69 | H14: 556.91 | I14: 573.09 | J14: 516.29 | K14: 484.02 | L14: 569.8 | M14: 584.23 | N14: 13.01 | S14: Actual PEPM | T14: 190.92 | U14: 165.96 | V14: 212.55 | W14: 231.93 | X14: 220.47 | Y14: 233.01 | Z14: 225.03 | AA14: 199.56 | AB14: 202.22 | AC14: 199.75 | AD14: 187.91 | AE14: 212.7 | AF14: 0
A15: Actual PMPM | B15: 249.05 | C15: 248.94 | D15: 254.26 | E15: 271.62 | F15: 236.01 | G15: 296.61 | H15: 284.06 | I15: 292.04 | J15: 262.97 | K15: 246.56 | L15: 290.67 | M15: 298.17 | N15: 6.64 | S15: Actual PMPM | T15: 97.35 | U15: 84.62 | V15: 108.43 | W15: 118.31 | X15: 112.35 | Y15: 118.81 | Z15: 114.78 | AA15: 101.7 | AB15: 103 | AC15: 101.75 | AD15: 95.86 | AE15: 108.55 | AF15: 0
A16: Avg. claims/member | B16: 1.03 | C16: 1.21 | D16: 1.08 | E16: 1.17 | F16: 1.06 | G16: 1.14 | H16: 1.18 | I16: 1.11 | J16: 1.09 | K16: 1.21 | L16: 0.89 | M16: 1.15 | N16: 0.04 | S16: # of Rx Claims PMPM | T16: 0.89 | U16: 0.92 | V16: 1 | W16: 1.07 | X16: 0.97 | Y16: 0.94 | Z16: 1.01 | AA16: 0.9 | AB16: 0.93 | AC16: 1.06 | AD16: 0.88 | AE16: 1 | AF16: 0
A17: Avg. lines/member | B17: 2.6 | C17: 2.92 | D17: 2.6 | E17: 2.96 | F17: 2.58 | G17: 2.92 | H17: 2.98 | I17: 3.01 | J17: 2.84 | K17: 3.14 | L17: 2.28 | M17: 2.88 | N17: 0.08 | S17: % of claimants to members | T17: 0.3476 | U17: 0.3749 | V17: 0.3946 | W17: 0.3996 | X17: 0.3811 | Y17: 0.3773 | Z17: 0.3756 | AA17: 0.361 | AB17: 0.3698 | AC17: 0.4075 | AD17: 0.357 | AE17: 0.3734 | AF17: 0
... A20: Claims/1000 covered lives | B20: 1027.84 | C20: 1214.28 | D20: 1083.63 | E20: 1174.42 | F20: 1063.03 | G20: 1136 | H20: 1175.97 | I20: 1106.48 | J20: 1093.6 | K20: 1212.84 | L20: 885.62 | M20: 1147.91 | N20: 40.24 | S20: Avg. scripts/member | T20: 0.89 | U20: 0.92 | V20: 1 | W20: 1.07 | X20: 0.97 | Y20: 0.94 | Z20: 1.01 | AA20: 0.9 | AB20: 0.93 | AC20: 1.06 | AD20: 0.88 | AE20: 1 | AF20: 0
A21: Procedure/1000 covered lives | B21: 2306.64 | C21: 2635.98 | D21: 2339.25 | E21: 2629.65 | F21: 2284.81 | G21: 2510.12 | H21: 2671.97 | I21: 2632.77 | J21: 2461.45 | K21: 2820.03 | L21: 2019.56 | M21: 2599.77 | N21: 74.33 | S21: Employer vs. Copay | T21: Employer vs. Copay
A22: Inpatient Days/1,000 | B22: 69.96 | C22: 63.86 | D22: 76.93 | E22: 71.05 | F22: 87.92 | G22: 69.38 | H22: 86.36 | I22: 98.1 | J22: 86.59 | K22: 68.76 | L22: 66.93 | M22: 61.1 | N22: 2.53 | S22: Employer Cost (in thousands) | T22: 1334.82 | U22: 1122.37 | V22: 1441.75 | W22: 1573.66 | X22: 1499.01 | Y22: 1596.11 | Z22: 1549.79 | AA22: 1382.97 | AB22: 1410.66 | AC22: 1457.55 | AD22: 1392.05 | AE22: 1591.85 | AF22: 0
A23: ER visits/1000 covered lives | B23: 21.95 | C23: 19.91 | D23: 21.36 | E23: 26.46 | F23: 22.56 | G23: 25.68 | H23: 25.48 | I23: 22.58 | J23: 24.75 | K23: 24.43 | L23: 24.45 | M23: 24.89 | N23: 0.89 | S23: Total Copay (in thousands) | T23: 81.42 | U23: 79.38 | V23: 91.94 | W23: 90.57 | X23: 87.86 | Y23: 89.31 | Z23: 87.27 | AA23: 89.31 | AB23: 93.48 | AC23: 86.73 | AD23: 83.96 | AE23: 97.26 | AF23: 0
A24: Avg Claim Cost | B24: 238.01 | C24: 205.01 | D24: 234.64 | E24: 231.28 | F24: 222.02 | G24: 261.1 | H24: 241.56 | I24: 263.94 | J24: 240.46 | K24: 203.29 | L24: 328.21 | M24: 259.75 | N24: 164.89 | S24: Total Coinsurance | T24: 0 | U24: 0 | V24: 0 | W24: 0 | X24: 0 | Y24: 0 | Z24: 0 | AA24: 0 | AB24: 0 | AC24: 0 | AD24: 0 | AE24: 0 | AF24: 0
A25: Avg Cost/claimants | B25: 663.38 | C25: 602.6 | D25: 651.55 | E25: 682.56 | F25: 616.95 | G25: 750.54 | H25: 714.63 | I25: 754.89 | J25: 705.52 | K25: 622.14 | L25: 856.04 | M25: 771.96 | N25: 231.24 | S25: Total Deductible | T25: 0 | U25: 0 | V25: 0 | W25: 0 | X25: 0 | Y25: 0 | Z25: 0 | AA25: 0 | AB25: 0 | AC25: 0 | AD25: 0 | AE25: 0 | AF25: 0
A26: Avg Lines/claimants | B26: 6.92 | C26: 7.06 | D26: 6.66 | E26: 7.44 | F26: 6.73 | G26: 7.39 | H26: 7.51 | I26: 7.79 | J26: 7.62 | K26: 7.93 | L26: 6.71 | M26: 7.46 | N26: 2.78 | S26: Total Cost (in thousands) | T26: 1416.24 | U26: 1201.76 | V26: 1533.69 | W26: 1664.23 | X26: 1586.87 | Y26: 1685.42 | Z26: 1637.06 | AA26: 1472.28 | AB26: 1504.14 | AC26: 1544.28 | AD26: 1476.01 | AE26: 1689.11 | AF26: 0
A27: % In Paid In-Network (Facility) | B27: 0.9938 | C27: 0.9433 | D27: 1.0042 | E27: 1.0411 | F27: 1.011 | G27: 0.993 | H27: 0.9963 | I27: 0.9957 | J27: 0.9965 | K27: 0.9946 | L27: 0.9954 | M27: 0.9945 | N27: 0.9604 | S27: Employee % | T27: 0.053 | U27: 0.0661 | V27: 0.0599 | W27: 0.0544 | X27: 0.0554 | Y27: 0.053 | Z27: 0.0533 | AA27: 0.0607 | AB27: 0.0621 | AC27: 0.0562 | AD27: 0.0569 | AE27: 0.0576 | AF27: 0
A28: % In Paid In-Network (Professional) | B28: 0.9349 | C28: 0.9535 | D28: 0.9638 | E28: 0.9524 | F28: 0.9494 | G28: 0.9301 | H28: 0.9337 | I28: 0.9144 | J28: 0.9194 | K28: 0.9102 | L28: 0.9462 | M28: 0.9283 | N28: 0.9173 | S28: Employer % | T28: 0.8637 | U28: 0.9339 | V28: 0.9401 | W28: 0.9456 | X28: 0.9446 | Y28: 0.947 | Z28: 0.9467 | AA28: 0.9393 | AB28: 0.9379 | AC28: 0.9438 | AD28: 0.9431 | AE28: 0.9424 | AF28: 0
A29: % In Paid In-Network (Total) | B29: 0.9668 | C29: 0.9485 | D29: 0.9848 | E29: 1.0023 | F29: 0.9816 | G29: 0.9642 | H29: 0.9672 | I29: 0.959 | J29: 0.9591 | K29: 0.9533 | L29: 0.9781 | M29: 0.9656 | N29: 0.9376 | S29: Copay Breakdown of Scripts | T29: Copay Breakdown of Scripts
S30: $0.00 - $5.00 | T30: 0.6955 | U30: 0.7835 | V30: 0.7515 | W30: 0.7688 | X30: 0.7462 | Y30: 0.7371 | Z30: 0.7649 | AA30: 0.7394 | AB30: 0.7383 | AC30: 0.7917 | AD30: 0.7652 | AE30: 0.7595 | AF30: 0
S31: $5.01 - $10.00 | T31: 0.1183 | U31: 0.112 | V31: 0.1306 | W31: 0.1224 | X31: 0.1377 | Y31: 0.143 | Z31: 0.127 | AA31: 0.1396 | AB31: 0.1419 | AC31: 0.112 | AD31: 0.1263 | AE31: 0.1266 | AF31: 0
S32: $10.01 - $15.00 | T32: 0.0063 | U32: 0.0039 | V32: 0.0075 | W32: 0.0062 | X32: 0.0071 | Y32: 0.0085 | Z32: 0.0074 | AA32: 0.008 | AB32: 0.0077 | AC32: 0.0061 | AD32: 0.0059 | AE32: 0.0077 | AF32: 0
S33: $15.01 - $20.00 | T33: 0.0037 | U33: 0.0022 | V33: 0.0041 | W33: 0.0042 | X33: 0.0046 | Y33: 0.0037 | Z33: 0.004 | AA33: 0.0046 | AB33: 0.0048 | AC33: 0.0038 | AD33: 0.0037 | AE33: 0.0044 | AF33: 0
S34: $20.01 - $25.00 | T34: 0.0418 | U34: 0.0443 | V34: 0.0484 | W34: 0.0452 | X34: 0.0464 | Y34: 0.0471 | Z34: 0.0438 | AA34: 0.0474 | AB34: 0.046 | AC34: 0.0391 | AD34: 0.0446 | AE34: 0.049 | AF34: 0
S35: $25.01 - $30.00 | T35: 0.0033 | U35: 0.0018 | V35: 0.0038 | W35: 0.0034 | X35: 0.0039 | Y35: 0.0036 | Z35: 0.0037 | AA35: 0.0038 | AB35: 0.0041 | AC35: 0.0036 | AD35: 0.0037 | AE35: 0.0045 | AF35: 0
S36: $30.01+ | T36: 0.0478 | U36: 0.0522 | V36: 0.0541 | W36: 0.0498 | X36: 0.0541 | Y36: 0.0571 | Z36: 0.0492 | AA36: 0.0573 | AB36: 0.0572 | AC36: 0.0437 | AD36: 0.0506 | AE36: 0.0483 | AF36: 0
S37: Generic % of dollars | T37: 0.199 | U37: 0.2823 | V37: 0.2029 | W37: 0.2005 | X37: 0.1941 | Y37: 0.2005 | Z37: 0.2015 | AA37: 0.218 | AB37: 0.2176 | AC37: 0.2211 | AD37: 0.2217 | AE37: 0.2277 | AF37: 0
S38: Brand % of dollars | T38: 0.7177 | U38: 0.7177 | V38: 0.7971 | W38: 0.7995 | X38: 0.8059 | Y38: 0.7995 | Z38: 0.7985 | AA38: 0.782 | AB38: 0.7824 | AC38: 0.7789 | AD38: 0.7783 | AE38: 0.7723 | AF38: 0
S39: Generic % of Scripts | T39: 0.6545 | U39: 0.7184 | V39: 0.7264 | W39: 0.718 | X39: 0.7282 | Y39: 0.7304 | Z39: 0.7175 | AA39: 0.7171 | AB39: 0.7109 | AC39: 0.655 | AD39: 0.7095 | AE39: 0.7228 | AF39: 0
S40: Brand % of Scripts | T40: 0.2622 | U40: 0.2816 | V40: 0.2736 | W40: 0.282 | X40: 0.2718 | Y40: 0.2696 | Z40: 0.2825 | AA40: 0.2829 | AB40: 0.2891 | AC40: 0.345 | AD40: 0.2905 | AE40: 0.2772 | AF40: 0
S41: Total Cost Breakdown | T41: Total Cost Breakdown
S42: % Ingredient Cost | T42: 0.9112 | U42: 0.9942 | V42: 0.9938 | W42: 0.994 | X42: 0.9945 | Y42: 0.9953 | Z42: 0.9947 | AA42: 0.9945 | AB42: 0.9914 | AC42: 0.9934 | AD42: 0.9944 | AE42: 0.9941 | AF42: 0
S43: % Administrative Cost | T43: 0.0055 | U43: 0.0058 | V43: 0.0062 | W43: 0.006 | X43: 0.0055 | Y43: 0.0047 | Z43: 0.0053 | AA43: 0.0055 | AB43: 0.0086 | AC43: 0.0066 | AD43: 0.0056 | AE43: 0.0059 | AF43: 0
...

Sheet Benefit_Categories
A1: Basis: Incurred
A2: Makalu Result (Last Processing)
A3: Category | B3: Reporting Period | F3: Comparison Period
B4: Paid Amount | C4: Paid PMPM | D4: Allowed Amount | E4: Allowed PMPM | F4: Paid Amount | G4: Paid PMPM | H4: Allowed Amount | I4: Allowed PMPM
A15: Makalu Result (Current Processing)
A16: Category | B16: Reporting Period | F16: Comparison Period
B17: Paid Amount | C17: Paid PMPM | D17: Allowed Amount | E17: Allowed PMPM | F17: Paid Amount | G17: Paid PMPM | H17: Allowed Amount | I17: Allowed PMPM
A28: Trending Analysis ( Diff of 10 % is considered for Monthly Clients )
A29: Category | B29: Reporting Period | E29: Comparison Period
B30: Paid Amount | C30: Allowed Amount | D30: Result | E30: Paid Amount | F30: Allowed Amount | G30: Result
A31: Professional Services | B31: =IF(B18=0,0%,(B18-B5)/B18) -> 0 | C31: =IF(C18=0,0%,(C18-C5)/C18) -> 0 | D31: =IF(D18=0,0%,(D18-D5)/D18) -> 0 | E31: =IF(E18=0,0%,(E18-E5)/E18) -> 0 | F31: =IF(F18=0,0%,(F18-F5)/F18) -> 0 | G31: =IF(G18=0,0%,(G18-G5)/G18) -> 0
A32: Hospital Inpatient | B32: =IF(B19=0,0%,(B19-B6)/B19) -> 0 | C32: =IF(C19=0,0%,(C19-C6)/C19) -> 0 | D32: =IF(D19=0,0%,(D19-D6)/D19) -> 0 | E32: =IF(E19=0,0%,(E19-E6)/E19) -> 0 | F32: =IF(F19=0,0%,(F19-F6)/F19) -> 0 | G32: =IF(G19=0,0%,(G19-G6)/G19) -> 0
A33: Hospital Outpatient | B33: =IF(B20=0,0%,(B20-B7)/B20) -> 0 | C33: =IF(C20=0,0%,(C20-C7)/C20) -> 0 | D33: =IF(D20=0,0%,(D20-D7)/D20) -> 0 | E33: =IF(E20=0,0%,(E20-E7)/E20) -> 0 | F33: =IF(F20=0,0%,(F20-F7)/F20) -> 0 | G33: =IF(G20=0,0%,(G20-G7)/G20) -> 0
A34: Pharmacy | B34: =IF(B21=0,0%,(B21-B8)/B21) -> 0 | C34: =IF(C21=0,0%,(C21-C8)/C21) -> 0 | D34: =IF(D21=0,0%,(D21-D8)/D21) -> 0 | E34: =IF(E21=0,0%,(E21-E8)/E21) -> 0 | F34: =IF(F21=0,0%,(F21-F8)/F21) -> 0 | G34: =IF(G21=0,0%,(G21-G8)/G21) -> 0
A35: Emergency Room | B35: =IF(B22=0,0%,(B22-B9)/B22) -> 0 | C35: =IF(C22=0,0%,(C22-C9)/C22) -> 0 | D35: =IF(D22=0,0%,(D22-D9)/D22) -> 0 | E35: =IF(E22=0,0%,(E22-E9)/E22) -> 0 | F35: =IF(F22=0,0%,(F22-F9)/F22) -> 0 | G35: =IF(G22=0,0%,(G22-G9)/G22) -> 0
A36: Lab/X-Ray | B36: =IF(B23=0,0%,(B23-B10)/B23) -> 0 | C36: =IF(C23=0,0%,(C23-C10)/C23) -> 0 | D36: =IF(D23=0,0%,(D23-D10)/D23) -> 0 | E36: =IF(E23=0,0%,(E23-E10)/E23) -> 0 | F36: =IF(F23=0,0%,(F23-F10)/F23) -> 0 | G36: =IF(G23=0,0%,(G23-G10)/G23) -> 0
A37: DME | B37: =IF(B24=0,0%,(B24-B11)/B24) -> 0 | C37: =IF(C24=0,0%,(C24-C11)/C24) -> 0 | D37: =IF(D24=0,0%,(D24-D11)/D24) -> 0 | E37: =IF(E24=0,0%,(E24-E11)/E24) -> 0 | F37: =IF(F24=0,0%,(F24-F11)/F24) -> 0 | G37: =IF(G24=0,0%,(G24-G11)/G24) -> 0
A38: Mental Health/Substance Abuse | B38: =IF(B25=0,0%,(B25-B12)/B25) -> 0 | C38: =IF(C25=0,0%,(C25-C12)/C25) -> 0 | D38: =IF(D25=0,0%,(D25-D12)/D25) -> 0 | E38: =IF(E25=0,0%,(E25-E12)/E25) -> 0 | F38: =IF(F25=0,0%,(F25-F12)/F25) -> 0 | G38: =IF(G25=0,0%,(G25-G12)/G25) -> 0
A39: Others | B39: =IF(B26=0,0%,(B26-B13)/B26) -> 0 | C39: =IF(C26=0,0%,(C26-C13)/C26) -> 0 | D39: =IF(D26=0,0%,(D26-D13)/D26) -> 0 | E39: =IF(E26=0,0%,(E26-E13)/E26) -> 0 | F39: =IF(F26=0,0%,(F26-F13)/F26) -> 0 | G39: =IF(G26=0,0%,(G26-G13)/G26) -> 0

Sheet Top_20_Reports
A1: Testing Environment | B1: Section | C1: Sub-Section | D1: Test Summary | E1: Makalu Test Procedure | G1: Backend Test Procedure | H1: Test Data | I1: Test Result | J1: Related Defects | K1: Remarks
I2: DATE
A3: MSSQL 2008 R2 | B3: Top 20 Reports | C3: Diagnoses | D3: Verify Top 20 Diagnoses | E3: 1) Login to Makalu 2) Click "Dynamic Reports" 3) Select Default values(Basis and Period) 3) Click "Search" 4) Click "Top 20 Reports" | F3: 1) Click "Diagnoses" 2) The Makalu result for both "Reporting Period" and "Comparision Period" can be seen in "T20 Reports Data" tab. | G3: 1) Run the query from following svn path | H3: Top 20 Data'!A1 | I3: Pass
C4: Procedure Group | D4: Verify Top 20 Procedure Group | F4: 1) Click "Procedure Group" 2) The Makalu result for both "Reporting Period" and "Comparision Period" can be seen in "T20 Reports Data" tab. | G4: http://www.deerwalk.com/repos/dwproject/makalu/docs/quality_control/test_cases/data_qc/1MASTER/Automated_Scripts/Care_Analytics/All_IN_ONE_INCURRED_1_8_0.sql | H4: Top 20 Data'!A1 | I4: Pass
C5: Therapeutic Classes | D5: Verify Top 20 Therapeutic Classes | F5: 1) Click Therapeutic Classes" 2) The Makalu resultfor both "Reporting Period" and "Comparision Period" can be seen in "T20 Reports Data" tab. | G5: 2) The backend result for both "Reporting Period" and "Comparision Period" can be seen in "T20 Reports Data" tab. | H5: Top 20 Data'!A1 | I5: Pass
C6: Drugs | D6: Verify Top 20 Drugs | F6: 1) Click "Drugs" 2) The Makalu result for both "Reporting Period" and "Comparision Period" can be seen in "T20 Reports Data" tab. | H6: Top 20 Data'!A1 | I6: Pass
C7: Injectable Drugs | D7: Verify Top 20 Injectable Drugs | F7: 1) Click "Injectable Drugs" 2) The Makalu result for both "Reporting Period" and "Comparision Period" can be seen in "T20 Reports Data" tab. | H7: Top 20 Data'!A1 | I7: Pass
C8: Provider List | D8: Verify Top 20 Provider List | F8: 1) Click "Provider List" 2) The Makalu resultfor both "Reporting Period" and "Comparision Period" can be seen in "T20 Reports Data" tab. | H8: Top 20 Data'!A1 | I8: Pass
C9: Benefit codes | D9: Verify Top 20 Benefit codes | F9: 1) Click "Benefit codes" 2) The Makalu result for both "Reporting Period" and "Comparision Period" can be seen in "T20 Reports Data" tab. | H9: Top 20 Data'!A1 | I9: Pass
C10: Place of service | D10: Verify Top 20 Place of service | F10: 1) Click "Place of service" 2) The Makalu result for both "Reporting Period" and "Comparision Period" can be seen in "T20 Reports Data" tab. | H10: Top 20 Data'!A1 | I10: Pass

Sheet Utilization Metrics
A1: Testing Environment | B1: Section | C1: Sub-Section | D1: Test Summary | E1: Makalu Test Procedure | F1: Backend Test Procedure | G1: Test Data | H1: Test Result | I1: Related Defects | J1: Remarks
H2: 40941
A3: MSSQL 2008 R2 | B3: Utilization Metrics | C3: ER Visits | D3: Verify ER Visits | E3: 1) Login to Makalu 2) Click "Dynamic Reports" 3) Select Default values(Basis and Period) 3) Click "Search" 4) Click "Utilization Metrics" 5) The Makalu resultfor both "Reporting Period" and "Comparision Period" can be seen in "UM Data" tab. | F3: 1)Run the query from following svn path | G3: UM Data'!A1 | H3: Not Tested
C4: Total Office Visits 1) Routine Office Visits 2) Preventive Office Visits 3) Mental Health Office Visits | D4: Verify Total Office Visits | F4: http://www.deerwalk.com/repos/dwproject/makalu/docs/ quality_control/test_cases/data_qc/Testing_Script/UtilizationMetrics.sql | H4: Not Tested
C5: Chiropractic Visits | D5: Verify Chiropractic Visits | F5: 2)The Backend result for both "Reporting Period" and "Comparision Period" can be seen in "UM Data" tab. | H5: Not Tested
C6: Physical Therapy | D6: Verify Physical Therapy | H6: Not Tested
C7: MRI Scan | D7: Verify MRI Scan | H7: Not Tested
C8: CT Scan | D8: Verify CT Scan | H8: Not Tested
C9: Newborn Deliveries 1) Vaginal Delveries 2) C-Section Deliveries | D9: Verify Newborn Deliveries | H9: Not Tested
C10: SNF Days | D10: Verify SNF Days | H10: Not Tested
C11: Inpatient Days | D11: Verify Inpatient Days | H11: Not Tested
C12: Total Admissions 1) Medical Admissions 2) Surgical Admissions 3) Maternity Admissions 4) Mental Health Admissions 5) Substance Abuse Admissions | D12: Verify Total Admissions | H12: Not Tested
C13: Admissions from ER | D13: Verify Admissions from ER | H13: Not Tested
C14: Average Length of Stay | D14: Verify Average Length of Stay | H14: Not Tested
C15: Pharmacy Scripts | D15: Verify Pharmacy Scripts | H15: Not Tested
C16: Pharmacy Scripts Mail Order | D16: Verify Pharmacy Scripts Mail Order | H16: Not Tested
C17: Pharmacy Scripts Brand Drugs | D17: Verify Pharmacy Scripts Brand Drugs | H17: Not Tested

Sheet Top 20 Trending
A1: Basis: Incurred
A2: Makalu Result (Last Processing) | K2: Trending Result
A4: TOP 20 DIAGNOSES DATA
A6: SN | B6: Top 20 Diagnoses | C6: Reporting Period | D6: Reporting PMPM | E6: Comparison Period | F6: Comparison PMPM | G6: % Change | H6: Prior Period Ranking | K6: SN | L6: Top 20 Diagnoses | M6: Reporting Period | N6: Comparison Period | O6: Trending Result
K7: 1 | L7: =IF(EXACT(B7,#REF!),#REF!,"Different Name: "&#REF!) -> #REF! | M7: =IF(D7=0, 0%,(#REF!-D7)/D7) -> 0 | N7: =IF(E7=0, 0%,(#REF!-E7)/E7) -> 0 | O7: =IF(AND(M7<10%,N7<10%,M7>-10%,N7>-10%),"Pass","Fail") -> Pass
K8: 2 | L8: =IF(EXACT(B8,#REF!),#REF!,"Different Name: "&#REF!) -> #REF! | M8: =IF(D8=0, 0%,(#REF!-D8)/D8) -> 0 | N8: =IF(E8=0, 0%,(#REF!-E8)/E8) -> 0 | O8: =IF(AND(M8<10%,N8<10%,M8>-10%,N8>-10%),"Pass","Fail") -> Pass
K9: 3 | L9: =IF(EXACT(B9,#REF!),#REF!,"Different Name: "&#REF!) -> #REF! | M9: =IF(D9=0, 0%,(#REF!-D9)/D9) -> 0 | N9: =IF(E9=0, 0%,(#REF!-E9)/E9) -> 0 | O9: =IF(AND(M9<10%,N9<10%,M9>-10%,N9>-10%),"Pass","Fail") -> Pass
K10: 4 | L10: =IF(EXACT(B10,#REF!),#REF!,"Different Name: "&#REF!) -> #REF! | M10: =IF(D10=0, 0%,(#REF!-D10)/D10) -> 0 | N10: =IF(E10=0, 0%,(#REF!-E10)/E10) -> 0 | O10: =IF(AND(M10<10%,N10<10%,M10>-10%,N10>-10%),"Pass","Fail") -> Pass
K11: 5 | L11: =IF(EXACT(B11,#REF!),#REF!,"Different Name: "&#REF!) -> #REF! | M11: =IF(D11=0, 0%,(#REF!-D11)/D11) -> 0 | N11: =IF(E11=0, 0%,(#REF!-E11)/E11) -> 0 | O11: =IF(AND(M11<10%,N11<10%,M11>-10%,N11>-10%),"Pass","Fail") -> Pass
K12: 6 | L12: =IF(EXACT(B12,#REF!),#REF!,"Different Name: "&#REF!) -> #REF! | M12: =IF(D12=0, 0%,(#REF!-D12)/D12) -> 0 | N12: =IF(E12=0, 0%,(#REF!-E12)/E12) -> 0 | O12: =IF(AND(M12<10%,N12<10%,M12>-10%,N12>-10%),"Pass","Fail") -> Pass
K13: 7 | L13: =IF(EXACT(B13,#REF!),#REF!,"Different Name: "&#REF!) -> #REF! | M13: =IF(D13=0, 0%,(#REF!-D13)/D13) -> 0 | N13: =IF(E13=0, 0%,(#REF!-E13)/E13) -> 0 | O13: =IF(AND(M13<10%,N13<10%,M13>-10%,N13>-10%),"Pass","Fail") -> Pass
K14: 8 | L14: =IF(EXACT(B14,#REF!),#REF!,"Different Name: "&#REF!) -> #REF! | M14: =IF(D14=0, 0%,(#REF!-D14)/D14) -> 0 | N14: =IF(E14=0, 0%,(#REF!-E14)/E14) -> 0 | O14: =IF(AND(M14<10%,N14<10%,M14>-10%,N14>-10%),"Pass","Fail") -> Pass
K15: 9 | L15: =IF(EXACT(B15,#REF!),#REF!,"Different Name: "&#REF!) -> #REF! | M15: =IF(D15=0, 0%,(#REF!-D15)/D15) -> 0 | N15: =IF(E15=0, 0%,(#REF!-E15)/E15) -> 0 | O15: =IF(AND(M15<10%,N15<10%,M15>-10%,N15>-10%),"Pass","Fail") -> Pass
K16: 10 | L16: =IF(EXACT(B16,#REF!),#REF!,"Different Name: "&#REF!) -> #REF! | M16: =IF(D16=0, 0%,(#REF!-D16)/D16) -> 0 | N16: =IF(E16=0, 0%,(#REF!-E16)/E16) -> 0 | O16: =IF(AND(M16<10%,N16<10%,M16>-10%,N16>-10%),"Pass","Fail") -> Pass
K17: 11 | L17: =IF(EXACT(B17,#REF!),#REF!,"Different Name: "&#REF!) -> #REF! | M17: =IF(D17=0, 0%,(#REF!-D17)/D17) -> 0 | N17: =IF(E17=0, 0%,(#REF!-E17)/E17) -> 0 | O17: =IF(AND(M17<10%,N17<10%,M17>-10%,N17>-10%),"Pass","Fail") -> Pass
K18: 12 | L18: =IF(EXACT(B18,#REF!),#REF!,"Different Name: "&#REF!) -> #REF! | M18: =IF(D18=0, 0%,(#REF!-D18)/D18) -> 0 | N18: =IF(E18=0, 0%,(#REF!-E18)/E18) -> 0 | O18: =IF(AND(M18<10%,N18<10%,M18>-10%,N18>-10%),"Pass","Fail") -> Pass
... K26: 20 | L26: =IF(EXACT(B26,#REF!),#REF!,"Different Name: "&#REF!) -> #REF! | M26: =IF(D26=0, 0%,(#REF!-D26)/D26) -> 0 | N26: =IF(E26=0, 0%,(#REF!-E26)/E26) -> 0 | O26: =IF(AND(M26<10%,N26<10%,M26>-10%,N26>-10%),"Pass","Fail") -> Pass
A31: TOP 20 PROCEDURE GROUP DATA
A33: SN | B33: Top 20 Procedure Group | C33: Reporting Period | D33: Reporting PMPM | E33: Comparison Period | F33: Comparison PMPM | G33: % Change | H33: Prior Period Ranking | K33: SN | L33: Top 20 Procedure Group | M33: Reporting Period | N33: Comparison Period | O33: Trending Result
K34: 1 | L34: =IF(EXACT(B34,#REF!),#REF!,"Different Name: "&#REF!) -> #REF! | M34: =IF('Top 20 Trending'!D34=0, 0%,(#REF!-'Top 20 Trending'!D34)/'Top 20 Trending'!D34) -> 0 | N34: =IF('Top 20 Trending'!E34=0, 0%,(#REF!-'Top 20 Trending'!E34)/'Top 20 Trending'!E34) -> 0 | O34: =IF(AND(M34<10%,N34<10%,M34>-10%,N34>-10%),"Pass","Fail") -> Pass
K35: 2 | L35: =IF(EXACT(B35,#REF!),#REF!,"Different Name: "&#REF!) -> #REF! | M35: =IF('Top 20 Trending'!D35=0, 0%,(#REF!-'Top 20 Trending'!D35)/'Top 20 Trending'!D35) -> 0 | N35: =IF('Top 20 Trending'!E35=0, 0%,(#REF!-'Top 20 Trending'!E35)/'Top 20 Trending'!E35) -> 0 | O35: =IF(AND(M35<10%,N35<10%,M35>-10%,N35>-10%),"Pass","Fail") -> Pass
K36: 3 | L36: =IF(EXACT(B36,#REF!),#REF!,"Different Name: "&#REF!) -> #REF! | M36: =IF('Top 20 Trending'!D36=0, 0%,(#REF!-'Top 20 Trending'!D36)/'Top 20 Trending'!D36) -> 0 | N36: =IF('Top 20 Trending'!E36=0, 0%,(#REF!-'Top 20 Trending'!E36)/'Top 20 Trending'!E36) -> 0 | O36: =IF(AND(M36<10%,N36<10%,M36>-10%,N36>-10%),"Pass","Fail") -> Pass
K37: 4 | L37: =IF(EXACT(B37,#REF!),#REF!,"Different Name: "&#REF!) -> #REF! | M37: =IF('Top 20 Trending'!D37=0, 0%,(#REF!-'Top 20 Trending'!D37)/'Top 20 Trending'!D37) -> 0 | N37: =IF('Top 20 Trending'!E37=0, 0%,(#REF!-'Top 20 Trending'!E37)/'Top 20 Trending'!E37) -> 0 | O37: =IF(AND(M37<10%,N37<10%,M37>-10%,N37>-10%),"Pass","Fail") -> Pass
K38: 5 | L38: =IF(EXACT(B38,#REF!),#REF!,"Different Name: "&#REF!) -> #REF! | M38: =IF('Top 20 Trending'!D38=0, 0%,(#REF!-'Top 20 Trending'!D38)/'Top 20 Trending'!D38) -> 0 | N38: =IF('Top 20 Trending'!E38=0, 0%,(#REF!-'Top 20 Trending'!E38)/'Top 20 Trending'!E38) -> 0 | O38: =IF(AND(M38<10%,N38<10%,M38>-10%,N38>-10%),"Pass","Fail") -> Pass
K39: 6 | L39: =IF(EXACT(B39,#REF!),#REF!,"Different Name: "&#REF!) -> #REF! | M39: =IF('Top 20 Trending'!D39=0, 0%,(#REF!-'Top 20 Trending'!D39)/'Top 20 Trending'!D39) -> 0 | N39: =IF('Top 20 Trending'!E39=0, 0%,(#REF!-'Top 20 Trending'!E39)/'Top 20 Trending'!E39) -> 0 | O39: =IF(AND(M39<10%,N39<10%,M39>-10%,N39>-10%),"Pass","Fail") -> Pass
K40: 7 | L40: =IF(EXACT(B40,#REF!),#REF!,"Different Name: "&#REF!) -> #REF! | M40: =IF('Top 20 Trending'!D40=0, 0%,(#REF!-'Top 20 Trending'!D40)/'Top 20 Trending'!D40) -> 0 | N40: =IF('Top 20 Trending'!E40=0, 0%,(#REF!-'Top 20 Trending'!E40)/'Top 20 Trending'!E40) -> 0 | O40: =IF(AND(M40<10%,N40<10%,M40>-10%,N40>-10%),"Pass","Fail") -> Pass
K41: 8 | L41: =IF(EXACT(B41,#REF!),#REF!,"Different Name: "&#REF!) -> #REF! | M41: =IF('Top 20 Trending'!D41=0, 0%,(#REF!-'Top 20 Trending'!D41)/'Top 20 Trending'!D41) -> 0 | N41: =IF('Top 20 Trending'!E41=0, 0%,(#REF!-'Top 20 Trending'!E41)/'Top 20 Trending'!E41) -> 0 | O41: =IF(AND(M41<10%,N41<10%,M41>-10%,N41>-10%),"Pass","Fail") -> Pass
K42: 9 | L42: =IF(EXACT(B42,#REF!),#REF!,"Different Name: "&#REF!) -> #REF! | M42: =IF('Top 20 Trending'!D42=0, 0%,(#REF!-'Top 20 Trending'!D42)/'Top 20 Trending'!D42) -> 0 | N42: =IF('Top 20 Trending'!E42=0, 0%,(#REF!-'Top 20 Trending'!E42)/'Top 20 Trending'!E42) -> 0 | O42: =IF(AND(M42<10%,N42<10%,M42>-10%,N42>-10%),"Pass","Fail") -> Pass
K43: 10 | L43: =IF(EXACT(B43,#REF!),#REF!,"Different Name: "&#REF!) -> #REF! | M43: =IF('Top 20 Trending'!D43=0, 0%,(#REF!-'Top 20 Trending'!D43)/'Top 20 Trending'!D43) -> 0 | N43: =IF('Top 20 Trending'!E43=0, 0%,(#REF!-'Top 20 Trending'!E43)/'Top 20 Trending'!E43) -> 0 | O43: =IF(AND(M43<10%,N43<10%,M43>-10%,N43>-10%),"Pass","Fail") -> Pass
K44: 11 | L44: =IF(EXACT(B44,#REF!),#REF!,"Different Name: "&#REF!) -> #REF! | M44: =IF('Top 20 Trending'!D44=0, 0%,(#REF!-'Top 20 Trending'!D44)/'Top 20 Trending'!D44) -> 0 | N44: =IF('Top 20 Trending'!E44=0, 0%,(#REF!-'Top 20 Trending'!E44)/'Top 20 Trending'!E44) -> 0 | O44: =IF(AND(M44<10%,N44<10%,M44>-10%,N44>-10%),"Pass","Fail") -> Pass
K45: 12 | L45: =IF(EXACT(B45,#REF!),#REF!,"Different Name: "&#REF!) -> #REF! | M45: =IF('Top 20 Trending'!D45=0, 0%,(#REF!-'Top 20 Trending'!D45)/'Top 20 Trending'!D45) -> 0 | N45: =IF('Top 20 Trending'!E45=0, 0%,(#REF!-'Top 20 Trending'!E45)/'Top 20 Trending'!E45) -> 0 | O45: =IF(AND(M45<10%,N45<10%,M45>-10%,N45>-10%),"Pass","Fail") -> Pass
... K53: 20 | L53: =IF(EXACT(B53,#REF!),#REF!,"Different Name: "&#REF!) -> #REF! | M53: =IF('Top 20 Trending'!D53=0, 0%,(#REF!-'Top 20 Trending'!D53)/'Top 20 Trending'!D53) -> 0 | N53: =IF('Top 20 Trending'!E53=0, 0%,(#REF!-'Top 20 Trending'!E53)/'Top 20 Trending'!E53) -> 0 | O53: =IF(AND(M53<10%,N53<10%,M53>-10%,N53>-10%),"Pass","Fail") -> Pass
A58: TOP 20 BENEFIT CODES
A60: SN | B60: Top 20 Benefit Codes | C60: Reporting Period | D60: Comparison Period | E60: % Change | F60: Prior Period Ranking | K60: SN | L60: Top 20 Benefit Codes | M60: Reporting Period | N60: Comparison Period | O60: Trending Result
K61: 1 | L61: =IF(EXACT(B61,#REF!),#REF!,"Different Name: "&#REF!) -> #REF! | M61: =IF('Top 20 Trending'!C61=0, 0%,(#REF!-'Top 20 Trending'!C61)/'Top 20 Trending'!C61) -> 0 | N61: =IF('Top 20 Trending'!D61=0, 0%,(#REF!-'Top 20 Trending'!D61)/'Top 20 Trending'!D61) -> 0 | O61: =IF(AND(M61<10%,N61<10%,M61>-10%,N61>-10%),"Pass","Fail") -> Pass
K62: 2 | L62: =IF(EXACT(B62,#REF!),#REF!,"Different Name: "&#REF!) -> #REF! | M62: =IF('Top 20 Trending'!C62=0, 0%,(#REF!-'Top 20 Trending'!C62)/'Top 20 Trending'!C62) -> 0 | N62: =IF('Top 20 Trending'!D62=0, 0%,(#REF!-'Top 20 Trending'!D62)/'Top 20 Trending'!D62) -> 0 | O62: =IF(AND(M62<10%,N62<10%,M62>-10%,N62>-10%),"Pass","Fail") -> Pass
K63: 3 | L63: =IF(EXACT(B63,#REF!),#REF!,"Different Name: "&#REF!) -> #REF! | M63: =IF('Top 20 Trending'!C63=0, 0%,(#REF!-'Top 20 Trending'!C63)/'Top 20 Trending'!C63) -> 0 | N63: =IF('Top 20 Trending'!D63=0, 0%,(#REF!-'Top 20 Trending'!D63)/'Top 20 Trending'!D63) -> 0 | O63: =IF(AND(M63<10%,N63<10%,M63>-10%,N63>-10%),"Pass","Fail") -> Pass
K64: 4 | L64: =IF(EXACT(B64,#REF!),#REF!,"Different Name: "&#REF!) -> #REF! | M64: =IF('Top 20 Trending'!C64=0, 0%,(#REF!-'Top 20 Trending'!C64)/'Top 20 Trending'!C64) -> 0 | N64: =IF('Top 20 Trending'!D64=0, 0%,(#REF!-'Top 20 Trending'!D64)/'Top 20 Trending'!D64) -> 0 | O64: =IF(AND(M64<10%,N64<10%,M64>-10%,N64>-10%),"Pass","Fail") -> Pass
K65: 5 | L65: =IF(EXACT(B65,#REF!),#REF!,"Different Name: "&#REF!) -> #REF! | M65: =IF('Top 20 Trending'!C65=0, 0%,(#REF!-'Top 20 Trending'!C65)/'Top 20 Trending'!C65) -> 0 | N65: =IF('Top 20 Trending'!D65=0, 0%,(#REF!-'Top 20 Trending'!D65)/'Top 20 Trending'!D65) -> 0 | O65: =IF(AND(M65<10%,N65<10%,M65>-10%,N65>-10%),"Pass","Fail") -> Pass
K66: 6 | L66: =IF(EXACT(B66,#REF!),#REF!,"Different Name: "&#REF!) -> #REF! | M66: =IF('Top 20 Trending'!C66=0, 0%,(#REF!-'Top 20 Trending'!C66)/'Top 20 Trending'!C66) -> 0 | N66: =IF('Top 20 Trending'!D66=0, 0%,(#REF!-'Top 20 Trending'!D66)/'Top 20 Trending'!D66) -> 0 | O66: =IF(AND(M66<10%,N66<10%,M66>-10%,N66>-10%),"Pass","Fail") -> Pass
...

Sheet Uitilization_Metrics
A1: Basis: Incurred
A2: Makalu Result (Last Processing) | G2: Makalu Result (Current Processing)
