Workbook

Sheet Test_Summary
B1: Test Case Revision History
B2: Date | C2: Version | D2: Description | E2: Author | F2: Reviewer/s | G2: Remarks
B3: 42418 | C3: 1.0 | E3: RaghuP
B4: 42425 | C4: 1.1 | D4: Overall Result Auto Display function added. | E4: RaghuP
B5: 42578 | C5: 1.2 | D5: Previous Extract and Current Count section added in each tab | E5: RaghuP
B6: 42587 | C6: 1.3 | D6: Count Verification between extract and application added in each tab | E6: RaghuP
B8: Test Case Execution History
B9: Start Date | C9: End Date | D9: Test Environment | E9: Tester | F9: Overall Result | G9: Remarks
B10: 42849 | C10: 42849 | D10: UAT | E10: RaghuP | F10: Partially Pass
B12: Test Case Summary Results
B13: Test Case ID | C13: Summary | G13: Test Result
B14: EX01 | C14: Verify file size | G14: =File_Size_Comparision!L2 -> Fail
B15: EX02 | C15: Verify Care Alert layout | G15: =Care_Alerts!M5 -> Pass
B16: EX03 | C16: Verify Care Alert field length | G16: =Care_Alerts!M6 -> Pass
B17: EX04 | C17: Verify Demographics layout | G17: =Demographics!M5 -> Pass
B18: EX05 | C18: Verify Demographics field length | G18: =Demographics!M6 -> Pass
B19: EX06 | C19: Verify Eligibility layout | G19: =Eligibility!M6 -> Pass
B20: EX07 | C20: Verify Eligibility field length | G20: =Eligibility!M7 -> Pass
B21: EX08 | C21: Verify Eligibility count between application and extract | G21: =Eligibility!M8 -> Pass
B22: EX09 | C22: Verify Generic Quality Metrics layout | G22: =Generic_Quality_Metrics!M6 -> Pass
B23: EX10 | C23: Verify Generic Quality Metrics field length | G23: =Generic_Quality_Metrics!M7 -> Pass
B24: EX11 | C24: Verify High_Cost layout | G24: =High_Cost!M5 -> Pass
B25: EX12 | C25: Verify High_Cost field length | G25: =High_Cost!M6 -> Pass
B26: EX13 | C26: Verify Historical Scores layout | G26: =Historical_Scores!M6 -> Pass
B27: EX14 | C27: Verify Historical Scores field length | G27: =Historical_Scores!M7 -> Pass
B28: EX15 | C28: Verify Lab layout | G28: =Lab!M6 -> Pass
B29: EX16 | C29: Verify Lab field length | G29: =Lab!M7 -> Pass
B30: EX17 | C30: Verify Lab count between application and extract | G30: =Lab!M8 -> Pass
B31: EX18 | C31: Verify Medcial Claims layout | G31: =Medical_Claims!M6 -> Pass
B32: EX19 | C32: Verify Medcial Claims field length | G32: =Medical_Claims!M7 -> Pass
B33: EX20 | C33: Verify Medcial Claims count between application and extract | G33: =Medical_Claims!M8 -> Pass
B34: EX21 | C34: Verify Member layout | G34: =Member!M6 -> Pass
B35: EX22 | C35: Verify Member field length | G35: =Member!M7 -> Pass
B36: EX23 | C36: Verify Member count between application and extract | G36: =Member!M8 -> Pass
B37: EX24 | C37: Verify Member Months layout | G37: =Member_Months!M6 -> Pass
B38: EX25 | C38: Verify Member Months field length | G38: =Member_Months!M7 -> Pass
B39: EX26 | C39: Verify Member Months count between application and extract | G39: =Member_Months!M8 -> Pass
B40: EX27 | C40: Verify Member PCP layout | G40: =Member_PCP!M6 -> Pass
B41: EX28 | C41: Verify Member PCP field length | G41: =Member_PCP!M7 -> Pass
B42: EX29 | C42: Verify Pharmacy layout | G42: =Pharmacy!M6 -> Pass
...

Sheet File_Size_Comparision
B1: Previous Extract | D1: Current Extract | F1: % Change | G1: Test Result | M1: Fail
B2: File Name | C2: Size | D2: File Name | E2: Size | K2: Overall File Size Result | L2: =IF(ISERROR(VLOOKUP($M$1,$G$2:$G$12,1,)),"Pass","Fail") -> Fail
B3: CareAlerts.csv | C3: 7.70 MB | D3: CareAlerts.csv | E3: 8.94 MB | F3: =IF(I3=0,0%,(I3-H3)/I3) -> 0.13870246 | G3: =IF(AND(F3<=10%,F3>=-10%),"Pass","Fail") -> Fail | H3: =LEFT(C3, SEARCH(" ", C3, 1)) -> 7.70 | I3: =LEFT(E3, SEARCH(" ", E3, 1)) -> 8.94
B4: Demographics.csv | C4: 3.24 MB | D4: Demographics.csv | E4: 3.36 MB | F4: =IF(I4=0,0%,(I4-H4)/I4) -> 0.035714286 | G4: =IF(AND(F4<=10%,F4>=-10%),"Pass","Fail") -> Pass | H4: =LEFT(C4, SEARCH(" ", C4, 1)) -> 3.24 | I4: =LEFT(E4, SEARCH(" ", E4, 1)) -> 3.36
B5: Eligibility.csv | C5: 115.13 MB | D5: Eligibility.csv | E5: 119.44 MB | F5: =IF(I5=0,0%,(I5-H5)/I5) -> 0.036085064 | G5: =IF(AND(F5<=10%,F5>=-10%),"Pass","Fail") -> Pass | H5: =LEFT(C5, SEARCH(" ", C5, 1)) -> 115.13 | I5: =LEFT(E5, SEARCH(" ", E5, 1)) -> 119.44
B6: Generic Quality Metrics.csv | D6: GenericQualityMetrics.csv | E6: 56.52 MB | F6: =IF(I6=0,0%,(I6-H6)/I6) -> #VALUE! | G6: =IF(AND(F6<=10%,F6>=-10%),"Pass","Fail") -> #VALUE! | H6: =LEFT(C6, SEARCH(" ", C6, 1)) -> #VALUE! | I6: =LEFT(E6, SEARCH(" ", E6, 1)) -> 56.52
B7: HighCost.csv | C7: 1.53 MB | D7: HighCost.csv | E7: 1.56 MB | F7: =IF(I7=0,0%,(I7-H7)/I7) -> 0.019230769 | G7: =IF(AND(F7<=10%,F7>=-10%),"Pass","Fail") -> Pass | H7: =LEFT(C7, SEARCH(" ", C7, 1)) -> 1.53 | I7: =LEFT(E7, SEARCH(" ", E7, 1)) -> 1.56
B8: HistoricalScores.csv | C8: 22.70 MB | D8: HistoricalScores.csv | E8: 23.32 MB | F8: =IF(I8=0,0%,(I8-H8)/I8) -> 0.026586621 | G8: =IF(AND(F8<=10%,F8>=-10%),"Pass","Fail") -> Pass | H8: =LEFT(C8, SEARCH(" ", C8, 1)) -> 22.70 | I8: =LEFT(E8, SEARCH(" ", E8, 1)) -> 23.32
B9: Lab.csv | D9: Lab.csv | E9: 30.16 MB | F9: =IF(I9=0,0%,(I9-H9)/I9) -> #VALUE! | G9: =IF(AND(F9<=10%,F9>=-10%),"Pass","Fail") -> #VALUE! | H9: =LEFT(C9, SEARCH(" ", C9, 1)) -> #VALUE! | I9: =LEFT(E9, SEARCH(" ", E9, 1)) -> 30.16
B10: Medical.csv | C10: 1.15 GB | D10: Medical.csv | E10: 1.17 GB | F10: =IF(I10=0,0%,(I10-H10)/I10) -> 0.017094017 | G10: =IF(AND(F10<=10%,F10>=-10%),"Pass","Fail") -> Pass | H10: =LEFT(C10, SEARCH(" ", C10, 1)) -> 1.15 | I10: =LEFT(E10, SEARCH(" ", E10, 1)) -> 1.17
B11: Member.csv | D11: Member.csv | E11: 9.34 MB | F11: =IF(I11=0,0%,(I11-H11)/I11) -> #VALUE! | G11: =IF(AND(F11<=10%,F11>=-10%),"Pass","Fail") -> #VALUE! | H11: =LEFT(C11, SEARCH(" ", C11, 1)) -> #VALUE! | I11: =LEFT(E11, SEARCH(" ", E11, 1)) -> 9.34
B12: MemberMonths.csv | D12: MemberMonths.csv | E12: 158.06 MB | F12: =IF(I12=0,0%,(I12-H12)/I12) -> #VALUE! | G12: =IF(AND(F12<=10%,F12>=-10%),"Pass","Fail") -> #VALUE! | H12: =LEFT(C12, SEARCH(" ", C12, 1)) -> #VALUE! | I12: =LEFT(E12, SEARCH(" ", E12, 1)) -> 158.06
B13: Pcp.csv | C13: 944.89 KB | D13: Pcp.csv | E13: 957 KB | F13: =IF(I13=0,0%,(I13-H13)/I13) -> 0.012654127 | G13: =IF(AND(F13<=10%,F13>=-10%),"Pass","Fail") -> Pass | H13: =LEFT(C13, SEARCH(" ", C13, 1)) -> 944.89 | I13: =LEFT(E13, SEARCH(" ", E13, 1)) -> 957
B14: Pharmacy.csv | C14: 122.73 MB | D14: Pharmacy.csv | E14: 131.66 MB | F14: =IF(I14=0,0%,(I14-H14)/I14) -> 0.067826219 | G14: =IF(AND(F14<=10%,F14>=-10%),"Pass","Fail") -> Pass | H14: =LEFT(C14, SEARCH(" ", C14, 1)) -> 122.73 | I14: =LEFT(E14, SEARCH(" ", E14, 1)) -> 131.66
B15: QualityMetrics.csv | C15: 38.85 MB | D15: QualityMetrics.csv | E15: 39.31 MB | F15: =IF(I15=0,0%,(I15-H15)/I15) -> 0.011701857 | G15: =IF(AND(F15<=10%,F15>=-10%),"Pass","Fail") -> Pass | H15: =LEFT(C15, SEARCH(" ", C15, 1)) -> 38.85 | I15: =LEFT(E15, SEARCH(" ", E15, 1)) -> 39.31
B16: Scores.csv | C16: 1.41 MB | D16: Scores.csv | E16: 1.41 MB | F16: =IF(I16=0,0%,(I16-H16)/I16) -> 0 | G16: =IF(AND(F16<=10%,F16>=-10%),"Pass","Fail") -> Pass | H16: =LEFT(C16, SEARCH(" ", C16, 1)) -> 1.41 | I16: =LEFT(E16, SEARCH(" ", E16, 1)) -> 1.41
B17: ScoresWithHistorical.csv | D17: ScoresWithHistorical.csv | E17: 39.14 MB | F17: =IF(I17=0,0%,(I17-H17)/I17) -> #VALUE! | G17: =IF(AND(F17<=10%,F17>=-10%),"Pass","Fail") -> #VALUE! | H17: =LEFT(C17, SEARCH(" ", C17, 1)) -> #VALUE! | I17: =LEFT(E17, SEARCH(" ", E17, 1)) -> 39.14
B18: Utilization.csv | D18: Utilization.csv | E18: 78.36 MB | F18: =IF(I18=0,0%,(I18-H18)/I18) -> #VALUE! | G18: =IF(AND(F18<=10%,F18>=-10%),"Pass","Fail") -> #VALUE! | H18: =LEFT(C18, SEARCH(" ", C18, 1)) -> #VALUE! | I18: =LEFT(E18, SEARCH(" ", E18, 1)) -> 78.36
B19: Visits.csv | C19: 13.64 MB | D19: Visits.csv | E19: 13.89 MB | F19: =IF(I19=0,0%,(I19-H19)/I19) -> 0.01799856 | G19: =IF(AND(F19<=10%,F19>=-10%),"Pass","Fail") -> Pass | H19: =LEFT(C19, SEARCH(" ", C19, 1)) -> 13.64 | I19: =LEFT(E19, SEARCH(" ", E19, 1)) -> 13.89

Sheet Care_Alerts
B1: Client layout | C1: Data Type | D1: Client Length | E1: Extract Layout | F1: Extract Length | G1: Layout Result | H1: Length Result | L1: Current Extract Count | M1: Previous Extract Count | N1: Difference
B2: dw_record_id | C2: int | E2: dw_record_id | G2: =IF(I2=J2,"Pass","Fail") -> Pass | H2: =IF(AND(ISBLANK(D2),F2>=0),"Pass",IF(F2<=D2,"Pass","Fail")) -> Pass | I2: =SUBSTITUTE(B2,"_","") -> dwrecordid | J2: =SUBSTITUTE(E2,"_","") -> dwrecordid | L2: 42532 | M2: 36646 | N2: =L2-M2 -> 5886
B3: dw_member_id | C3: varchar | D3: 50 | E3: dw_member_id | F3: 32 | G3: =IF(I3=J3,"Pass","Fail") -> Pass | H3: =IF(AND(ISBLANK(D3),F3>=0),"Pass",IF(F3<=D3,"Pass","Fail")) -> Pass | I3: =SUBSTITUTE(B3,"_","") -> dwmemberid | J3: =SUBSTITUTE(E3,"_","") -> dwmemberid
B4: mbr_id | C4: varchar | D4: 50 | E4: mbr_id | F4: 32 | G4: =IF(I4=J4,"Pass","Fail") -> Pass | H4: =IF(AND(ISBLANK(D4),F4>=0),"Pass",IF(F4<=D4,"Pass","Fail")) -> Pass | I4: =SUBSTITUTE(B4,"_","") -> mbrid | J4: =SUBSTITUTE(E4,"_","") -> mbrid | L4: Overall | M4: Result
B5: first_name | C5: varchar | D5: 50 | E5: first_name | F5: 15 | G5: =IF(I5=J5,"Pass","Fail") -> Pass | H5: =IF(AND(ISBLANK(D5),F5>=0),"Pass",IF(F5<=D5,"Pass","Fail")) -> Pass | I5: =SUBSTITUTE(B5,"_","") -> firstname | J5: =SUBSTITUTE(E5,"_","") -> firstname | L5: Layout Result | M5: =IF(ISERROR(VLOOKUP($O$1,$G$2:$G$19,1,)),"Pass","Fail") -> Pass
B6: last_name | C6: varchar | D6: 20 | E6: last_name | F6: 17 | G6: =IF(I6=J6,"Pass","Fail") -> Pass | H6: =IF(AND(ISBLANK(D6),F6>=0),"Pass",IF(F6<=D6,"Pass","Fail")) -> Pass | I6: =SUBSTITUTE(B6,"_","") -> lastname | J6: =SUBSTITUTE(E6,"_","") -> lastname | L6: Field Length Result | M6: =IF(ISERROR(VLOOKUP($O$1,$H$2:$H$19,1,)),"Pass","Fail") -> Pass
B7: middle_name | C7: varchar | D7: 10 | E7: middle_name | F7: 1 | G7: =IF(I7=J7,"Pass","Fail") -> Pass | H7: =IF(AND(ISBLANK(D7),F7>=0),"Pass",IF(F7<=D7,"Pass","Fail")) -> Pass | I7: =SUBSTITUTE(B7,"_","") -> middlename | J7: =SUBSTITUTE(E7,"_","") -> middlename | L7: % change in count with respect to previous count | M7: =IF(M2=0,0%,N2/M2) -> 0.1606178
B8: mbr_dob | C8: date | E8: mbr_dob | F8: 10 | G8: =IF(I8=J8,"Pass","Fail") -> Pass | H8: =IF(AND(ISBLANK(D8),F8>=0),"Pass",IF(F8<=D8,"Pass","Fail")) -> Pass | I8: =SUBSTITUTE(B8,"_","") -> mbrdob | J8: =SUBSTITUTE(E8,"_","") -> mbrdob | L8: % change in file size with respect to previous file | M8: =File_Size_Comparision!F3 -> 0.13870246
B9: mbr_gender | C9: varchar | D9: 10 | E9: mbr_gender | F9: 7 | G9: =IF(I9=J9,"Pass","Fail") -> Pass | H9: =IF(AND(ISBLANK(D9),F9>=0),"Pass",IF(F9<=D9,"Pass","Fail")) -> Pass | I9: =SUBSTITUTE(B9,"_","") -> mbrgender | J9: =SUBSTITUTE(E9,"_","") -> mbrgender
B10: mbr_status | C10: varchar | D10: 10 | E10: mbr_status | F10: 6 | G10: =IF(I10=J10,"Pass","Fail") -> Pass | H10: =IF(AND(ISBLANK(D10),F10>=0),"Pass",IF(F10<=D10,"Pass","Fail")) -> Pass | I10: =SUBSTITUTE(B10,"_","") -> mbrstatus | J10: =SUBSTITUTE(E10,"_","") -> mbrstatus
B11: mbr_relationship | C11: varchar | D11: 50 | E11: mbr_relationship | F11: 42 | G11: =IF(I11=J11,"Pass","Fail") -> Pass | H11: =IF(AND(ISBLANK(D11),F11>=0),"Pass",IF(F11<=D11,"Pass","Fail")) -> Pass | I11: =SUBSTITUTE(B11,"_","") -> mbrrelationship | J11: =SUBSTITUTE(E11,"_","") -> mbrrelationship
B12: pcp_full_name | C12: varchar | D12: 65 | E12: pcp_full_name | F12: 65 | G12: =IF(I12=J12,"Pass","Fail") -> Pass | H12: =IF(AND(ISBLANK(D12),F12>=0),"Pass",IF(F12<=D12,"Pass","Fail")) -> Pass | I12: =SUBSTITUTE(B12,"_","") -> pcpfullname | J12: =SUBSTITUTE(E12,"_","") -> pcpfullname
B13: mbr_age | C13: varchar | D13: 3 | E13: mbr_age | F13: 3 | G13: =IF(I13=J13,"Pass","Fail") -> Pass | H13: =IF(AND(ISBLANK(D13),F13>=0),"Pass",IF(F13<=D13,"Pass","Fail")) -> Pass | I13: =SUBSTITUTE(B13,"_","") -> mbrage | J13: =SUBSTITUTE(E13,"_","") -> mbrage
B14: mbr_months | C14: varchar | D14: 3 | E14: mbr_months | F14: 2 | G14: =IF(I14=J14,"Pass","Fail") -> Pass | H14: =IF(AND(ISBLANK(D14),F14>=0),"Pass",IF(F14<=D14,"Pass","Fail")) -> Pass | I14: =SUBSTITUTE(B14,"_","") -> mbrmonths | J14: =SUBSTITUTE(E14,"_","") -> mbrmonths
B15: care_alert_startDate | C15: date | E15: care_alert_startDate | F15: 10 | G15: =IF(I15=J15,"Pass","Fail") -> Pass | H15: =IF(AND(ISBLANK(D15),F15>=0),"Pass",IF(F15<=D15,"Pass","Fail")) -> Pass | I15: =SUBSTITUTE(B15,"_","") -> carealertstartDate | J15: =SUBSTITUTE(E15,"_","") -> carealertstartDate
B16: care_alert_id | C16: varchar | D16: 50 | E16: care_alert_id | F16: 21 | G16: =IF(I16=J16,"Pass","Fail") -> Pass | H16: =IF(AND(ISBLANK(D16),F16>=0),"Pass",IF(F16<=D16,"Pass","Fail")) -> Pass | I16: =SUBSTITUTE(B16,"_","") -> carealertid | J16: =SUBSTITUTE(E16,"_","") -> carealertid
B17: care_alert_desc | C17: varchar | D17: 94 | E17: care_alert_desc | F17: 94 | G17: =IF(I17=J17,"Pass","Fail") -> Pass | H17: =IF(AND(ISBLANK(D17),F17>=0),"Pass",IF(F17<=D17,"Pass","Fail")) -> Pass | I17: =SUBSTITUTE(B17,"_","") -> carealertdesc | J17: =SUBSTITUTE(E17,"_","") -> carealertdesc
B18: metric_Type | C18: varchar | D18: 50 | E18: metric_Type | F18: 15 | G18: =IF(I18=J18,"Pass","Fail") -> Pass | H18: =IF(AND(ISBLANK(D18),F18>=0),"Pass",IF(F18<=D18,"Pass","Fail")) -> Pass | I18: =SUBSTITUTE(B18,"_","") -> metricType | J18: =SUBSTITUTE(E18,"_","") -> metricType
B19: metric_name | C19: varchar | D19: 50 | E19: metric_name | F19: 15 | G19: =IF(I19=J19,"Pass","Fail") -> Pass | H19: =IF(AND(ISBLANK(D19),F19>=0),"Pass",IF(F19<=D19,"Pass","Fail")) -> Pass | I19: =SUBSTITUTE(B19,"_","") -> metricname | J19: =SUBSTITUTE(E19,"_","") -> metricname

Sheet Demographics
B1: Client layout | C1: Data Type | D1: Client Length | E1: Extract Layout | F1: Extract Length | G1: Layout Result | H1: Length Result | L1: Current Extract Count | M1: Previous Extract Count | N1: Difference | O1: Fail
B2: dw_record_id | C2: varchar | E2: dw_record_id | F2: 5 | G2: =IF(I2=J2,"Pass","Fail") -> Pass | H2: =IF(AND(ISBLANK(D2),F2>=0),"Pass",IF(F2<=D2,"Pass","Fail")) -> Pass | I2: =SUBSTITUTE(B2,"_","") -> dwrecordid | J2: =SUBSTITUTE(E2,"_","") -> dwrecordid | L2: 13235 | M2: 12801 | N2: =L2-M2 -> 434
B3: dw_account_id | C3: varchar | D3: 10 | E3: dw_account_id | F3: 0 | G3: =IF(I3=J3,"Pass","Fail") -> Pass | H3: =IF(AND(ISBLANK(D3),F3>=0),"Pass",IF(F3<=D3,"Pass","Fail")) -> Pass | I3: =SUBSTITUTE(B3,"_","") -> dwaccountid | J3: =SUBSTITUTE(E3,"_","") -> dwaccountid
B4: dw_client_id | C4: varchar | D4: 10 | E4: dw_client_id | F4: 8 | G4: =IF(I4=J4,"Pass","Fail") -> Pass | H4: =IF(AND(ISBLANK(D4),F4>=0),"Pass",IF(F4<=D4,"Pass","Fail")) -> Pass | I4: =SUBSTITUTE(B4,"_","") -> dwclientid | J4: =SUBSTITUTE(E4,"_","") -> dwclientid | L4: Overall | M4: Result
B5: dw_member_id | C5: varchar | D5: 50 | E5: dw_member_id | F5: 32 | G5: =IF(I5=J5,"Pass","Fail") -> Pass | H5: =IF(AND(ISBLANK(D5),F5>=0),"Pass",IF(F5<=D5,"Pass","Fail")) -> Pass | I5: =SUBSTITUTE(B5,"_","") -> dwmemberid | J5: =SUBSTITUTE(E5,"_","") -> dwmemberid | L5: Layout Result | M5: =IF(ISERROR(VLOOKUP($O$1,$G$2:$G$27,1,)),"Pass","Fail") -> Pass
B6: mbr_id | C6: varchar | D6: 32 | E6: mbr_id | F6: 32 | G6: =IF(I6=J6,"Pass","Fail") -> Pass | H6: =IF(AND(ISBLANK(D6),F6>=0),"Pass",IF(F6<=D6,"Pass","Fail")) -> Pass | I6: =SUBSTITUTE(B6,"_","") -> mbrid | J6: =SUBSTITUTE(E6,"_","") -> mbrid | L6: Field Length Result | M6: =IF(ISERROR(VLOOKUP($O$1,$H$2:$H$27,1,)),"Pass","Fail") -> Pass
B7: mbr_ssn | C7: varchar | D7: 22 | E7: mbr_ssn | F7: 22 | G7: =IF(I7=J7,"Pass","Fail") -> Pass | H7: =IF(AND(ISBLANK(D7),F7>=0),"Pass",IF(F7<=D7,"Pass","Fail")) -> Pass | I7: =SUBSTITUTE(B7,"_","") -> mbrssn | J7: =SUBSTITUTE(E7,"_","") -> mbrssn | L7: % change in count with respect to previous count | M7: =IF(M2=0,0%,N2/M2) -> 0.033903601
B8: mbr_first_name | C8: varchar | D8: 100 | E8: mbr_first_name | F8: 15 | G8: =IF(I8=J8,"Pass","Fail") -> Pass | H8: =IF(AND(ISBLANK(D8),F8>=0),"Pass",IF(F8<=D8,"Pass","Fail")) -> Pass | I8: =SUBSTITUTE(B8,"_","") -> mbrfirstname | J8: =SUBSTITUTE(E8,"_","") -> mbrfirstname | L8: % change in file size with respect to previous file | M8: =File_Size_Comparision!F4 -> 0.035714286
B9: mbr_middle_name | C9: varchar | D9: 100 | E9: mbr_middle_name | F9: 1 | G9: =IF(I9=J9,"Pass","Fail") -> Pass | H9: =IF(AND(ISBLANK(D9),F9>=0),"Pass",IF(F9<=D9,"Pass","Fail")) -> Pass | I9: =SUBSTITUTE(B9,"_","") -> mbrmiddlename | J9: =SUBSTITUTE(E9,"_","") -> mbrmiddlename
B10: mbr_last_name | C10: date | D10: 100 | E10: mbr_last_name | F10: 26 | G10: =IF(I10=J10,"Pass","Fail") -> Pass | H10: =IF(AND(ISBLANK(D10),F10>=0),"Pass",IF(F10<=D10,"Pass","Fail")) -> Pass | I10: =SUBSTITUTE(B10,"_","") -> mbrlastname | J10: =SUBSTITUTE(E10,"_","") -> mbrlastname
B11: mbr_current_status | C11: varchar | D11: 10 | E11: mbr_current_status | F11: 6 | G11: =IF(I11=J11,"Pass","Fail") -> Pass | H11: =IF(AND(ISBLANK(D11),F11>=0),"Pass",IF(F11<=D11,"Pass","Fail")) -> Pass | I11: =SUBSTITUTE(B11,"_","") -> mbrcurrentstatus | J11: =SUBSTITUTE(E11,"_","") -> mbrcurrentstatus
B12: mbr_gender | C12: varchar | D12: 10 | E12: mbr_gender | F12: 1 | G12: =IF(I12=J12,"Pass","Fail") -> Pass | H12: =IF(AND(ISBLANK(D12),F12>=0),"Pass",IF(F12<=D12,"Pass","Fail")) -> Pass | I12: =SUBSTITUTE(B12,"_","") -> mbrgender | J12: =SUBSTITUTE(E12,"_","") -> mbrgender
B13: mbr_dob | C13: varchar | E13: mbr_dob | F13: 10 | G13: =IF(I13=J13,"Pass","Fail") -> Pass | H13: =IF(AND(ISBLANK(D13),F13>=0),"Pass",IF(F13<=D13,"Pass","Fail")) -> Pass | I13: =SUBSTITUTE(B13,"_","") -> mbrdob | J13: =SUBSTITUTE(E13,"_","") -> mbrdob
B14: mbr_street_1 | C14: varchar | D14: 100 | E14: mbr_street_1 | F14: 30 | G14: =IF(I14=J14,"Pass","Fail") -> Pass | H14: =IF(AND(ISBLANK(D14),F14>=0),"Pass",IF(F14<=D14,"Pass","Fail")) -> Pass | I14: =SUBSTITUTE(B14,"_","") -> mbrstreet1 | J14: =SUBSTITUTE(E14,"_","") -> mbrstreet1
B15: mbr_street_2 | C15: varchar | D15: 100 | E15: mbr_street_2 | F15: 22 | G15: =IF(I15=J15,"Pass","Fail") -> Pass | H15: =IF(AND(ISBLANK(D15),F15>=0),"Pass",IF(F15<=D15,"Pass","Fail")) -> Pass | I15: =SUBSTITUTE(B15,"_","") -> mbrstreet2 | J15: =SUBSTITUTE(E15,"_","") -> mbrstreet2
B16: mbr_city | C16: varchar | D16: 100 | E16: mbr_city | F16: 19 | G16: =IF(I16=J16,"Pass","Fail") -> Pass | H16: =IF(AND(ISBLANK(D16),F16>=0),"Pass",IF(F16<=D16,"Pass","Fail")) -> Pass | I16: =SUBSTITUTE(B16,"_","") -> mbrcity | J16: =SUBSTITUTE(E16,"_","") -> mbrcity
B17: mbr_county | C17: varchar | D17: 100 | E17: mbr_county | F17: 5 | G17: =IF(I17=J17,"Pass","Fail") -> Pass | H17: =IF(AND(ISBLANK(D17),F17>=0),"Pass",IF(F17<=D17,"Pass","Fail")) -> Pass | I17: =SUBSTITUTE(B17,"_","") -> mbrcounty | J17: =SUBSTITUTE(E17,"_","") -> mbrcounty
B18: mbr_state | C18: varchar | D18: 100 | E18: mbr_state | F18: 2 | G18: =IF(I18=J18,"Pass","Fail") -> Pass | H18: =IF(AND(ISBLANK(D18),F18>=0),"Pass",IF(F18<=D18,"Pass","Fail")) -> Pass | I18: =SUBSTITUTE(B18,"_","") -> mbrstate | J18: =SUBSTITUTE(E18,"_","") -> mbrstate
B19: mbr_zip | C19: varchar | D19: 100 | E19: mbr_zip | F19: 9 | G19: =IF(I19=J19,"Pass","Fail") -> Pass | H19: =IF(AND(ISBLANK(D19),F19>=0),"Pass",IF(F19<=D19,"Pass","Fail")) -> Pass | I19: =SUBSTITUTE(B19,"_","") -> mbrzip | J19: =SUBSTITUTE(E19,"_","") -> mbrzip
B20: mbr_phone | C20: varchar | D20: 100 | E20: mbr_phone | F20: 12 | G20: =IF(I20=J20,"Pass","Fail") -> Pass | H20: =IF(AND(ISBLANK(D20),F20>=0),"Pass",IF(F20<=D20,"Pass","Fail")) -> Pass | I20: =SUBSTITUTE(B20,"_","") -> mbrphone | J20: =SUBSTITUTE(E20,"_","") -> mbrphone
B21: mbr_region_code | C21: varchar | D21: 100 | E21: mbr_region_code | F21: 0 | G21: =IF(I21=J21,"Pass","Fail") -> Pass | H21: =IF(AND(ISBLANK(D21),F21>=0),"Pass",IF(F21<=D21,"Pass","Fail")) -> Pass | I21: =SUBSTITUTE(B21,"_","") -> mbrregioncode | J21: =SUBSTITUTE(E21,"_","") -> mbrregioncode
B22: mbr_region_name | C22: varchar | D22: 100 | E22: mbr_region_name | F22: 0 | G22: =IF(I22=J22,"Pass","Fail") -> Pass | H22: =IF(AND(ISBLANK(D22),F22>=0),"Pass",IF(F22<=D22,"Pass","Fail")) -> Pass | I22: =SUBSTITUTE(B22,"_","") -> mbrregionname | J22: =SUBSTITUTE(E22,"_","") -> mbrregionname
B23: mbr_relationship_code | C23: varchar | D23: 10 | E23: mbr_relationship_code | F23: 3 | G23: =IF(I23=J23,"Pass","Fail") -> Pass | H23: =IF(AND(ISBLANK(D23),F23>=0),"Pass",IF(F23<=D23,"Pass","Fail")) -> Pass | I23: =SUBSTITUTE(B23,"_","") -> mbrrelationshipcode | J23: =SUBSTITUTE(E23,"_","") -> mbrrelationshipcode
B24: mbr_relationship_desc | C24: varchar | D24: 50 | E24: mbr_relationship_desc | F24: 42 | G24: =IF(I24=J24,"Pass","Fail") -> Pass | H24: =IF(AND(ISBLANK(D24),F24>=0),"Pass",IF(F24<=D24,"Pass","Fail")) -> Pass | I24: =SUBSTITUTE(B24,"_","") -> mbrrelationshipdesc | J24: =SUBSTITUTE(E24,"_","") -> mbrrelationshipdesc
B25: dw_rawfilename | C25: varchar | D25: 100 | E25: dw_rawfilename | F25: 85 | G25: =IF(I25=J25,"Pass","Fail") -> Pass | H25: =IF(AND(ISBLANK(D25),F25>=0),"Pass",IF(F25<=D25,"Pass","Fail")) -> Pass | I25: =SUBSTITUTE(B25,"_","") -> dwrawfilename | J25: =SUBSTITUTE(E25,"_","") -> dwrawfilename
... B27: dw_vendor_name | C27: varchar | D27: 100 | E27: dw_vendor_name | F27: 10 | G27: =IF(I27=J27,"Pass","Fail") -> Pass | H27: =IF(AND(ISBLANK(D27),F27>=0),"Pass",IF(F27<=D27,"Pass","Fail")) -> Pass | I27: =SUBSTITUTE(B27,"_","") -> dwvendorname | J27: =SUBSTITUTE(E27,"_","") -> dwvendorname

Sheet Eligibility
B1: Client layout | C1: Data Type | D1: Client Length | E1: Extract Layout | F1: Extract Length | G1: Layout Result | H1: Length Result | L1: Extract Total Count | M1: Application Total Count | N1: Difference | O1: Fail
B2: mbr_id | C2: varchar | D2: 32 | E2: mbr_id | F2: 32 | G2: =IF(I2=J2,"Pass","Fail") -> Pass | H2: =IF(AND(ISBLANK(D2),F2>=0),"Pass",IF(F2<=D2,"Pass","Fail")) -> Pass | I2: =SUBSTITUTE(B2,"_","") -> mbrid | J2: =SUBSTITUTE(E2,"_","") -> mbrid | L2: 216132 | M2: 216132 | N2: =L2-M2 -> 0
B3: ins_policy_id | C3: varchar | D3: 20 | E3: ins_policy_id | F3: 0 | G3: =IF(I3=J3,"Pass","Fail") -> Pass | H3: =IF(AND(ISBLANK(D3),F3>=0),"Pass",IF(F3<=D3,"Pass","Fail")) -> Pass | I3: =SUBSTITUTE(B3,"_","") -> inspolicyid | J3: =SUBSTITUTE(E3,"_","") -> inspolicyid | L3: Prior Count | M3: 207601 | N3: =L2-M3 -> 8531
B4: mbr_ssn | C4: varchar | D4: 22 | E4: mbr_ssn | F4: 22 | G4: =IF(I4=J4,"Pass","Fail") -> Pass | H4: =IF(AND(ISBLANK(D4),F4>=0),"Pass",IF(F4<=D4,"Pass","Fail")) -> Pass | I4: =SUBSTITUTE(B4,"_","") -> mbrssn | J4: =SUBSTITUTE(E4,"_","") -> mbrssn
B5: mbr_first_name | C5: varchar | D5: 30 | E5: mbr_first_name | F5: 15 | G5: =IF(I5=J5,"Pass","Fail") -> Pass | H5: =IF(AND(ISBLANK(D5),F5>=0),"Pass",IF(F5<=D5,"Pass","Fail")) -> Pass | I5: =SUBSTITUTE(B5,"_","") -> mbrfirstname | J5: =SUBSTITUTE(E5,"_","") -> mbrfirstname | L5: Overall | M5: Result
B6: mbr_middle_name | C6: varchar | D6: 30 | E6: mbr_middle_name | F6: 1 | G6: =IF(I6=J6,"Pass","Fail") -> Pass | H6: =IF(AND(ISBLANK(D6),F6>=0),"Pass",IF(F6<=D6,"Pass","Fail")) -> Pass | I6: =SUBSTITUTE(B6,"_","") -> mbrmiddlename | J6: =SUBSTITUTE(E6,"_","") -> mbrmiddlename | L6: Layout Result | M6: =IF(ISERROR(VLOOKUP($O$1,$G$2:$G$94,1,)),"Pass","Fail") -> Pass
B7: mbr_last_name | C7: varchar | D7: 30 | E7: mbr_last_name | F7: 26 | G7: =IF(I7=J7,"Pass","Fail") -> Pass | H7: =IF(AND(ISBLANK(D7),F7>=0),"Pass",IF(F7<=D7,"Pass","Fail")) -> Pass | I7: =SUBSTITUTE(B7,"_","") -> mbrlastname | J7: =SUBSTITUTE(E7,"_","") -> mbrlastname | L7: Field Length Result | M7: =IF(ISERROR(VLOOKUP($O$1,$H$2:$H$94,1,)),"Pass","Fail") -> Pass
B8: mbr_current_status | C8: varchar | D8: 20 | E8: mbr_current_status | F8: 6 | G8: =IF(I8=J8,"Pass","Fail") -> Pass | H8: =IF(AND(ISBLANK(D8),F8>=0),"Pass",IF(F8<=D8,"Pass","Fail")) -> Pass | I8: =SUBSTITUTE(B8,"_","") -> mbrcurrentstatus | J8: =SUBSTITUTE(E8,"_","") -> mbrcurrentstatus | L8: Count Result | M8: =IF(N2=0,"Pass","Fail") -> Pass
B9: mbr_gender | C9: varchar | D9: 2 | E9: mbr_gender | F9: 1 | G9: =IF(I9=J9,"Pass","Fail") -> Pass | H9: =IF(AND(ISBLANK(D9),F9>=0),"Pass",IF(F9<=D9,"Pass","Fail")) -> Pass | I9: =SUBSTITUTE(B9,"_","") -> mbrgender | J9: =SUBSTITUTE(E9,"_","") -> mbrgender | L9: % change in count with respect to previous count | M9: =IF(M3=0,0%,N3/M3) -> 0.041093251
B10: mbr_dob | C10: date | E10: mbr_dob | F10: 10 | G10: =IF(I10=J10,"Pass","Fail") -> Pass | H10: =IF(AND(ISBLANK(D10),F10>=0),"Pass",IF(F10<=D10,"Pass","Fail")) -> Pass | I10: =SUBSTITUTE(B10,"_","") -> mbrdob | J10: =SUBSTITUTE(E10,"_","") -> mbrdob | L10: % change in file size with respect to previous file | M10: =File_Size_Comparision!F5 -> 0.036085064
B11: mbr_street_1 | C11: varchar | D11: 50 | E11: mbr_street_1 | F11: 30 | G11: =IF(I11=J11,"Pass","Fail") -> Pass | H11: =IF(AND(ISBLANK(D11),F11>=0),"Pass",IF(F11<=D11,"Pass","Fail")) -> Pass | I11: =SUBSTITUTE(B11,"_","") -> mbrstreet1 | J11: =SUBSTITUTE(E11,"_","") -> mbrstreet1
B12: mbr_street_2 | C12: varchar | D12: 50 | E12: mbr_street_2 | F12: 22 | G12: =IF(I12=J12,"Pass","Fail") -> Pass | H12: =IF(AND(ISBLANK(D12),F12>=0),"Pass",IF(F12<=D12,"Pass","Fail")) -> Pass | I12: =SUBSTITUTE(B12,"_","") -> mbrstreet2 | J12: =SUBSTITUTE(E12,"_","") -> mbrstreet2
B13: mbr_city | C13: varchar | D13: 100 | E13: mbr_city | F13: 20 | G13: =IF(I13=J13,"Pass","Fail") -> Pass | H13: =IF(AND(ISBLANK(D13),F13>=0),"Pass",IF(F13<=D13,"Pass","Fail")) -> Pass | I13: =SUBSTITUTE(B13,"_","") -> mbrcity | J13: =SUBSTITUTE(E13,"_","") -> mbrcity
B14: mbr_county | C14: varchar | D14: 20 | E14: mbr_county | F14: 5 | G14: =IF(I14=J14,"Pass","Fail") -> Pass | H14: =IF(AND(ISBLANK(D14),F14>=0),"Pass",IF(F14<=D14,"Pass","Fail")) -> Pass | I14: =SUBSTITUTE(B14,"_","") -> mbrcounty | J14: =SUBSTITUTE(E14,"_","") -> mbrcounty
B15: mbr_state | C15: varchar | D15: 2 | E15: mbr_state | F15: 2 | G15: =IF(I15=J15,"Pass","Fail") -> Pass | H15: =IF(AND(ISBLANK(D15),F15>=0),"Pass",IF(F15<=D15,"Pass","Fail")) -> Pass | I15: =SUBSTITUTE(B15,"_","") -> mbrstate | J15: =SUBSTITUTE(E15,"_","") -> mbrstate
B16: mbr_zip | C16: varchar | D16: 12 | E16: mbr_zip | F16: 9 | G16: =IF(I16=J16,"Pass","Fail") -> Pass | H16: =IF(AND(ISBLANK(D16),F16>=0),"Pass",IF(F16<=D16,"Pass","Fail")) -> Pass | I16: =SUBSTITUTE(B16,"_","") -> mbrzip | J16: =SUBSTITUTE(E16,"_","") -> mbrzip
B17: mbr_phone | C17: varchar | D17: 15 | E17: mbr_phone | F17: 12 | G17: =IF(I17=J17,"Pass","Fail") -> Pass | H17: =IF(AND(ISBLANK(D17),F17>=0),"Pass",IF(F17<=D17,"Pass","Fail")) -> Pass | I17: =SUBSTITUTE(B17,"_","") -> mbrphone | J17: =SUBSTITUTE(E17,"_","") -> mbrphone
B18: mbr_region_code | C18: varchar | D18: 32 | E18: mbr_region_code | F18: 0 | G18: =IF(I18=J18,"Pass","Fail") -> Pass | H18: =IF(AND(ISBLANK(D18),F18>=0),"Pass",IF(F18<=D18,"Pass","Fail")) -> Pass | I18: =SUBSTITUTE(B18,"_","") -> mbrregioncode | J18: =SUBSTITUTE(E18,"_","") -> mbrregioncode
B19: mbr_region_name | C19: varchar | D19: 50 | E19: mbr_region_name | F19: 0 | G19: =IF(I19=J19,"Pass","Fail") -> Pass | H19: =IF(AND(ISBLANK(D19),F19>=0),"Pass",IF(F19<=D19,"Pass","Fail")) -> Pass | I19: =SUBSTITUTE(B19,"_","") -> mbrregionname | J19: =SUBSTITUTE(E19,"_","") -> mbrregionname
B20: mbr_relationship_code | C20: varchar | D20: 5 | E20: mbr_relationship_code | F20: 3 | G20: =IF(I20=J20,"Pass","Fail") -> Pass | H20: =IF(AND(ISBLANK(D20),F20>=0),"Pass",IF(F20<=D20,"Pass","Fail")) -> Pass | I20: =SUBSTITUTE(B20,"_","") -> mbrrelationshipcode | J20: =SUBSTITUTE(E20,"_","") -> mbrrelationshipcode
B21: mbr_relationship_desc | C21: varchar | D21: 42 | E21: mbr_relationship_desc | F21: 42 | G21: =IF(I21=J21,"Pass","Fail") -> Pass | H21: =IF(AND(ISBLANK(D21),F21>=0),"Pass",IF(F21<=D21,"Pass","Fail")) -> Pass | I21: =SUBSTITUTE(B21,"_","") -> mbrrelationshipdesc | J21: =SUBSTITUTE(E21,"_","") -> mbrrelationshipdesc
B22: ins_plan_type_code | C22: varchar | D22: 20 | E22: ins_plan_type_code | F22: 20 | G22: =IF(I22=J22,"Pass","Fail") -> Pass | H22: =IF(AND(ISBLANK(D22),F22>=0),"Pass",IF(F22<=D22,"Pass","Fail")) -> Pass | I22: =SUBSTITUTE(B22,"_","") -> insplantypecode | J22: =SUBSTITUTE(E22,"_","") -> insplantypecode
... B35: ins_cobra_desc | C35: varchar | D35: 30 | E35: ins_cobra_desc | F35: 0 | G35: =IF(I35=J35,"Pass","Fail") -> Pass | H35: =IF(AND(ISBLANK(D35),F35>=0),"Pass",IF(F35<=D35,"Pass","Fail")) -> Pass | I35: =SUBSTITUTE(B35,"_","") -> inscobradesc | J35: =SUBSTITUTE(E35,"_","") -> inscobradesc
B36: ins_med_eff_date | C36: date | E36: ins_med_eff_date | F36: 10 | G36: =IF(I36=J36,"Pass","Fail") -> Pass | H36: =IF(AND(ISBLANK(D36),F36>=0),"Pass",IF(F36<=D36,"Pass","Fail")) -> Pass | I36: =SUBSTITUTE(B36,"_","") -> insmedeffdate | J36: =SUBSTITUTE(E36,"_","") -> insmedeffdate
B37: ins_med_term_date | C37: date | E37: ins_med_term_date | F37: 10 | G37: =IF(I37=J37,"Pass","Fail") -> Pass | H37: =IF(AND(ISBLANK(D37),F37>=0),"Pass",IF(F37<=D37,"Pass","Fail")) -> Pass | I37: =SUBSTITUTE(B37,"_","") -> insmedtermdate | J37: =SUBSTITUTE(E37,"_","") -> insmedtermdate
B38: ins_rx_eff_date | C38: date | E38: ins_rx_eff_date | F38: 0 | G38: =IF(I38=J38,"Pass","Fail") -> Pass | H38: =IF(AND(ISBLANK(D38),F38>=0),"Pass",IF(F38<=D38,"Pass","Fail")) -> Pass | I38: =SUBSTITUTE(B38,"_","") -> insrxeffdate | J38: =SUBSTITUTE(E38,"_","") -> insrxeffdate
B39: ins_rx_term_date | C39: date | E39: ins_rx_term_date | F39: 0 | G39: =IF(I39=J39,"Pass","Fail") -> Pass | H39: =IF(AND(ISBLANK(D39),F39>=0),"Pass",IF(F39<=D39,"Pass","Fail")) -> Pass | I39: =SUBSTITUTE(B39,"_","") -> insrxtermdate | J39: =SUBSTITUTE(E39,"_","") -> insrxtermdate
B40: ins_den_eff_date | C40: date | E40: ins_den_eff_date | F40: 0 | G40: =IF(I40=J40,"Pass","Fail") -> Pass | H40: =IF(AND(ISBLANK(D40),F40>=0),"Pass",IF(F40<=D40,"Pass","Fail")) -> Pass | I40: =SUBSTITUTE(B40,"_","") -> insdeneffdate | J40: =SUBSTITUTE(E40,"_","") -> insdeneffdate
B41: ins_den_term_date | C41: date | E41: ins_den_term_date | F41: 0 | G41: =IF(I41=J41,"Pass","Fail") -> Pass | H41: =IF(AND(ISBLANK(D41),F41>=0),"Pass",IF(F41<=D41,"Pass","Fail")) -> Pass | I41: =SUBSTITUTE(B41,"_","") -> insdentermdate | J41: =SUBSTITUTE(E41,"_","") -> insdentermdate
B42: ins_vis_eff_date | C42: date | E42: ins_vis_eff_date | F42: 0 | G42: =IF(I42=J42,"Pass","Fail") -> Pass | H42: =IF(AND(ISBLANK(D42),F42>=0),"Pass",IF(F42<=D42,"Pass","Fail")) -> Pass | I42: =SUBSTITUTE(B42,"_","") -> insviseffdate | J42: =SUBSTITUTE(E42,"_","") -> insviseffdate
B43: ins_vis_term_date | C43: date | E43: ins_vis_term_date | F43: 0 | G43: =IF(I43=J43,"Pass","Fail") -> Pass | H43: =IF(AND(ISBLANK(D43),F43>=0),"Pass",IF(F43<=D43,"Pass","Fail")) -> Pass | I43: =SUBSTITUTE(B43,"_","") -> insvistermdate | J43: =SUBSTITUTE(E43,"_","") -> insvistermdate
B44: ins_ltd_eff_date | C44: date | E44: ins_ltd_eff_date | F44: 0 | G44: =IF(I44=J44,"Pass","Fail") -> Pass | H44: =IF(AND(ISBLANK(D44),F44>=0),"Pass",IF(F44<=D44,"Pass","Fail")) -> Pass | I44: =SUBSTITUTE(B44,"_","") -> insltdeffdate | J44: =SUBSTITUTE(E44,"_","") -> insltdeffdate
B45: ins_ltd_term_date | C45: date | E45: ins_ltd_term_date | F45: 0 | G45: =IF(I45=J45,"Pass","Fail") -> Pass | H45: =IF(AND(ISBLANK(D45),F45>=0),"Pass",IF(F45<=D45,"Pass","Fail")) -> Pass | I45: =SUBSTITUTE(B45,"_","") -> insltdtermdate | J45: =SUBSTITUTE(E45,"_","") -> insltdtermdate
B46: ins_std_eff_date | C46: date | E46: ins_std_eff_date | F46: 0 | G46: =IF(I46=J46,"Pass","Fail") -> Pass | H46: =IF(AND(ISBLANK(D46),F46>=0),"Pass",IF(F46<=D46,"Pass","Fail")) -> Pass | I46: =SUBSTITUTE(B46,"_","") -> insstdeffdate | J46: =SUBSTITUTE(E46,"_","") -> insstdeffdate
B47: ins_std_term_date | C47: date | E47: ins_std_term_date | F47: 0 | G47: =IF(I47=J47,"Pass","Fail") -> Pass | H47: =IF(AND(ISBLANK(D47),F47>=0),"Pass",IF(F47<=D47,"Pass","Fail")) -> Pass | I47: =SUBSTITUTE(B47,"_","") -> insstdtermdate | J47: =SUBSTITUTE(E47,"_","") -> insstdtermdate
B48: prv_pcp_id | C48: varchar | D48: 50 | E48: prv_pcp_id | F48: 10 | G48: =IF(I48=J48,"Pass","Fail") -> Pass | H48: =IF(AND(ISBLANK(D48),F48>=0),"Pass",IF(F48<=D48,"Pass","Fail")) -> Pass | I48: =SUBSTITUTE(B48,"_","") -> prvpcpid | J48: =SUBSTITUTE(E48,"_","") -> prvpcpid
B49: prv_pcp_first_name | C49: varchar | D49: 100 | E49: prv_pcp_first_name | F49: 65 | G49: =IF(I49=J49,"Pass","Fail") -> Pass | H49: =IF(AND(ISBLANK(D49),F49>=0),"Pass",IF(F49<=D49,"Pass","Fail")) -> Pass | I49: =SUBSTITUTE(B49,"_","") -> prvpcpfirstname | J49: =SUBSTITUTE(E49,"_","") -> prvpcpfirstname
B50: prv_pcp_middle_name | C50: varchar | D50: 30 | E50: prv_pcp_middle_name | F50: 16 | G50: =IF(I50=J50,"Pass","Fail") -> Pass | H50: =IF(AND(ISBLANK(D50),F50>=0),"Pass",IF(F50<=D50,"Pass","Fail")) -> Pass | I50: =SUBSTITUTE(B50,"_","") -> prvpcpmiddlename | J50: =SUBSTITUTE(E50,"_","") -> prvpcpmiddlename
B51: prv_pcp_last_name | C51: varchar | D51: 30 | E51: prv_pcp_last_name | F51: 20 | G51: =IF(I51=J51,"Pass","Fail") -> Pass | H51: =IF(AND(ISBLANK(D51),F51>=0),"Pass",IF(F51<=D51,"Pass","Fail")) -> Pass | I51: =SUBSTITUTE(B51,"_","") -> prvpcplastname | J51: =SUBSTITUTE(E51,"_","") -> prvpcplastname
B52: prv_pcp_site_id | C52: varchar | D52: 15 | E52: prv_pcp_site_id | F52: 0 | G52: =IF(I52=J52,"Pass","Fail") -> Pass | H52: =IF(AND(ISBLANK(D52),F52>=0),"Pass",IF(F52<=D52,"Pass","Fail")) -> Pass | I52: =SUBSTITUTE(B52,"_","") -> prvpcpsiteid | J52: =SUBSTITUTE(E52,"_","") -> prvpcpsiteid
...

Sheet Generic_Quality_Metrics
B1: Client layout | C1: Data Type | D1: Client Length | E1: Extract Layout | F1: Extract Length | G1: Layout Result | H1: Length Result
B2: dw_record_id | C2: text | D2: 20 | E2: dw_record_id | F2: 6 | G2: =IF(I2=J2,"Pass","Fail") -> Pass | H2: =IF(AND(ISBLANK(D2),F2>=0),"Pass",IF(F2<=D2,"Pass","Fail")) -> Pass | I2: =SUBSTITUTE(B2,"_","") -> dwrecordid | J2: =SUBSTITUTE(E2,"_","") -> dwrecordid | L2: Current Extract Count | M2: Previous Extract Count | N2: Difference
B3: dw_member_id | C3: text | D3: 50 | E3: dw_member_id | F3: 32 | G3: =IF(I3=J3,"Pass","Fail") -> Pass | H3: =IF(AND(ISBLANK(D3),F3>=0),"Pass",IF(F3<=D3,"Pass","Fail")) -> Pass | I3: =SUBSTITUTE(B3,"_","") -> dwmemberid | J3: =SUBSTITUTE(E3,"_","") -> dwmemberid | L3: 230786 | N3: =L3-M3 -> 230786
B4: mbr_id | C4: number | D4: 50 | E4: mbr_id | F4: 32 | G4: =IF(I4=J4,"Pass","Fail") -> Pass | H4: =IF(AND(ISBLANK(D4),F4>=0),"Pass",IF(F4<=D4,"Pass","Fail")) -> Pass | I4: =SUBSTITUTE(B4,"_","") -> mbrid | J4: =SUBSTITUTE(E4,"_","") -> mbrid
B5: memberFirstName | C5: varchar | D5: 30 | E5: memberFirstName | F5: 15 | G5: =IF(I5=J5,"Pass","Fail") -> Pass | H5: =IF(AND(ISBLANK(D5),F5>=0),"Pass",IF(F5<=D5,"Pass","Fail")) -> Pass | I5: =SUBSTITUTE(B5,"_","") -> memberFirstName | J5: =SUBSTITUTE(E5,"_","") -> memberFirstName | L5: Overall | M5: Result
B6: memberLastName | C6: varchar | D6: 30 | E6: memberLastName | F6: 26 | G6: =IF(I6=J6,"Pass","Fail") -> Pass | H6: =IF(AND(ISBLANK(D6),F6>=0),"Pass",IF(F6<=D6,"Pass","Fail")) -> Pass | I6: =SUBSTITUTE(B6,"_","") -> memberLastName | J6: =SUBSTITUTE(E6,"_","") -> memberLastName | L6: Layout Result | M6: =IF(ISERROR(VLOOKUP($O$1,$G$2:$G$15,1,)),"Pass","Fail") -> Pass
B7: memberMiddleName | C7: varchar | D7: 30 | E7: memberMiddleName | F7: 1 | G7: =IF(I7=J7,"Pass","Fail") -> Pass | H7: =IF(AND(ISBLANK(D7),F7>=0),"Pass",IF(F7<=D7,"Pass","Fail")) -> Pass | I7: =SUBSTITUTE(B7,"_","") -> memberMiddleName | J7: =SUBSTITUTE(E7,"_","") -> memberMiddleName | L7: Field Length Result | M7: =IF(ISERROR(VLOOKUP($O$1,$H$2:$H$15,1,)),"Pass","Fail") -> Pass
B8: memberGender | C8: varchar | D8: 7 | E8: memberGender | F8: 7 | G8: =IF(I8=J8,"Pass","Fail") -> Pass | H8: =IF(AND(ISBLANK(D8),F8>=0),"Pass",IF(F8<=D8,"Pass","Fail")) -> Pass | I8: =SUBSTITUTE(B8,"_","") -> memberGender | J8: =SUBSTITUTE(E8,"_","") -> memberGender | L8: % change in count with respect to previous count | M8: =IF(M3=0,0%,N3/M3) -> 0
B9: mbr_age | C9: varchar | D9: 5 | E9: mbr_age | F9: 3 | G9: =IF(I9=J9,"Pass","Fail") -> Pass | H9: =IF(AND(ISBLANK(D9),F9>=0),"Pass",IF(F9<=D9,"Pass","Fail")) -> Pass | I9: =SUBSTITUTE(B9,"_","") -> mbrage | J9: =SUBSTITUTE(E9,"_","") -> mbrage | L9: % change in file size with respect to previous file | M9: =File_Size_Comparision!F6 -> #VALUE!
B10: memberDOB | C10: date | E10: memberDOB | F10: 10 | G10: =IF(I10=J10,"Pass","Fail") -> Pass | H10: =IF(AND(ISBLANK(D10),F10>=0),"Pass",IF(F10<=D10,"Pass","Fail")) -> Pass | I10: =SUBSTITUTE(B10,"_","") -> memberDOB | J10: =SUBSTITUTE(E10,"_","") -> memberDOB
B11: mbr_status | C11: varchar | D11: 30 | E11: mbr_status | F11: 6 | G11: =IF(I11=J11,"Pass","Fail") -> Pass | H11: =IF(AND(ISBLANK(D11),F11>=0),"Pass",IF(F11<=D11,"Pass","Fail")) -> Pass | I11: =SUBSTITUTE(B11,"_","") -> mbrstatus | J11: =SUBSTITUTE(E11,"_","") -> mbrstatus
B12: mbr_relationship | C12: varchar | D12: 42 | E12: mbr_relationship | F12: 42 | G12: =IF(I12=J12,"Pass","Fail") -> Pass | H12: =IF(AND(ISBLANK(D12),F12>=0),"Pass",IF(F12<=D12,"Pass","Fail")) -> Pass | I12: =SUBSTITUTE(B12,"_","") -> mbrrelationship | J12: =SUBSTITUTE(E12,"_","") -> mbrrelationship
B13: pcp_full_name | C13: varchar | D13: 200 | E13: pcp_full_name | F13: 70 | G13: =IF(I13=J13,"Pass","Fail") -> Pass | H13: =IF(AND(ISBLANK(D13),F13>=0),"Pass",IF(F13<=D13,"Pass","Fail")) -> Pass | I13: =SUBSTITUTE(B13,"_","") -> pcpfullname | J13: =SUBSTITUTE(E13,"_","") -> pcpfullname
B14: measureId | C14: varchar | D14: 50 | E14: measureId | F14: 4 | G14: =IF(I14=J14,"Pass","Fail") -> Pass | H14: =IF(AND(ISBLANK(D14),F14>=0),"Pass",IF(F14<=D14,"Pass","Fail")) -> Pass | I14: =SUBSTITUTE(B14,"_","") -> measureId | J14: =SUBSTITUTE(E14,"_","") -> measureId
B15: measureDesc | C15: varchar | D15: 200 | E15: measureDesc | F15: 108 | G15: =IF(I15=J15,"Pass","Fail") -> Pass | H15: =IF(AND(ISBLANK(D15),F15>=0),"Pass",IF(F15<=D15,"Pass","Fail")) -> Pass | I15: =SUBSTITUTE(B15,"_","") -> measureDesc | J15: =SUBSTITUTE(E15,"_","") -> measureDesc
B16: Positive/Negative | C16: varchar | D16: 1 | E16: Positive/Negative | F16: 1 | G16: =IF(I16=J16,"Pass","Fail") -> Pass | H16: =IF(AND(ISBLANK(D16),F16>=0),"Pass",IF(F16<=D16,"Pass","Fail")) -> Pass | I16: =SUBSTITUTE(B16,"_","") -> Positive/Negative | J16: =SUBSTITUTE(E16,"_","") -> Positive/Negative
B17: measureName | C17: varchar | D17: 100 | E17: measureName | F17: 55 | G17: =IF(I17=J17,"Pass","Fail") -> Pass | H17: =IF(AND(ISBLANK(D17),F17>=0),"Pass",IF(F17<=D17,"Pass","Fail")) -> Pass | I17: =SUBSTITUTE(B17,"_","") -> measureName | J17: =SUBSTITUTE(E17,"_","") -> measureName
B18: startDate | C18: date | E18: startDate | F18: 10 | G18: =IF(I18=J18,"Pass","Fail") -> Pass | H18: =IF(AND(ISBLANK(D18),F18>=0),"Pass",IF(F18<=D18,"Pass","Fail")) -> Pass | I18: =SUBSTITUTE(B18,"_","") -> startDate | J18: =SUBSTITUTE(E18,"_","") -> startDate
B19: EndDate | C19: date | E19: EndDate | F19: 10 | G19: =IF(I19=J19,"Pass","Fail") -> Pass | H19: =IF(AND(ISBLANK(D19),F19>=0),"Pass",IF(F19<=D19,"Pass","Fail")) -> Pass | I19: =SUBSTITUTE(B19,"_","") -> EndDate | J19: =SUBSTITUTE(E19,"_","") -> EndDate
B20: numerator | C20: varchar | D20: 1 | E20: numerator | F20: 1 | G20: =IF(I20=J20,"Pass","Fail") -> Pass | H20: =IF(AND(ISBLANK(D20),F20>=0),"Pass",IF(F20<=D20,"Pass","Fail")) -> Pass | I20: =SUBSTITUTE(B20,"_","") -> numerator | J20: =SUBSTITUTE(E20,"_","") -> numerator
B21: denominator | C21: varchar | D21: 1 | E21: denominator | F21: 1 | G21: =IF(I21=J21,"Pass","Fail") -> Pass | H21: =IF(AND(ISBLANK(D21),F21>=0),"Pass",IF(F21<=D21,"Pass","Fail")) -> Pass | I21: =SUBSTITUTE(B21,"_","") -> denominator | J21: =SUBSTITUTE(E21,"_","") -> denominator
B22: care_alert_id | C22: varchar | D22: 30 | E22: care_alert_id | F22: 21 | G22: =IF(I22=J22,"Pass","Fail") -> Pass | H22: =IF(AND(ISBLANK(D22),F22>=0),"Pass",IF(F22<=D22,"Pass","Fail")) -> Pass | I22: =SUBSTITUTE(B22,"_","") -> carealertid | J22: =SUBSTITUTE(E22,"_","") -> carealertid
B23: care_alert_desc | C23: varchar | D23: 70 | E23: care_alert_desc | F23: 70 | G23: =IF(I23=J23,"Pass","Fail") -> Pass | H23: =IF(AND(ISBLANK(D23),F23>=0),"Pass",IF(F23<=D23,"Pass","Fail")) -> Pass | I23: =SUBSTITUTE(B23,"_","") -> carealertdesc | J23: =SUBSTITUTE(E23,"_","") -> carealertdesc
B24: mbr_months | C24: number | E24: mbr_months | F24: 2 | G24: =IF(I24=J24,"Pass","Fail") -> Pass | H24: =IF(AND(ISBLANK(D24),F24>=0),"Pass",IF(F24<=D24,"Pass","Fail")) -> Pass | I24: =SUBSTITUTE(B24,"_","") -> mbrmonths | J24: =SUBSTITUTE(E24,"_","") -> mbrmonths
B25: negativeOutcome | C25: varchar | D25: 1 | E25: negativeOutcome | F25: 1 | G25: =IF(I25=J25,"Pass","Fail") -> Pass | H25: =IF(AND(ISBLANK(D25),F25>=0),"Pass",IF(F25<=D25,"Pass","Fail")) -> Pass | I25: =SUBSTITUTE(B25,"_","") -> negativeOutcome | J25: =SUBSTITUTE(E25,"_","") -> negativeOutcome
B26: activeAlert | C26: varchar | D26: 1 | E26: activeAlert | F26: 1 | G26: =IF(I26=J26,"Pass","Fail") -> Pass | H26: =IF(AND(ISBLANK(D26),F26>=0),"Pass",IF(F26<=D26,"Pass","Fail")) -> Pass | I26: =SUBSTITUTE(B26,"_","") -> activeAlert | J26: =SUBSTITUTE(E26,"_","") -> activeAlert

Sheet High_Cost
B1: Client layout | C1: Data Type | D1: Client Length | E1: Extract Layout | F1: Extract Length | G1: Layout Result | H1: Length Result | L1: Current Extract Count | M1: Previous Extract Count | N1: Difference | O1: Fail
B2: dw_record_id | C2: varchar | E2: dw_record_id | F2: 5 | G2: =IF(I2=J2,"Pass","Fail") -> Pass | H2: =IF(AND(ISBLANK(D2),F2>=0),"Pass",IF(F2<=D2,"Pass","Fail")) -> Pass | I2: =SUBSTITUTE(B2,"_","") -> dwrecordid | J2: =SUBSTITUTE(E2,"_","") -> dwrecordid | L2: 13235 | M2: 12801 | N2: =L2-M2 -> 434
B3: dw_account_id | C3: varchar | D3: 50 | E3: dw_account_id | F3: 8 | G3: =IF(I3=J3,"Pass","Fail") -> Pass | H3: =IF(AND(ISBLANK(D3),F3>=0),"Pass",IF(F3<=D3,"Pass","Fail")) -> Pass | I3: =SUBSTITUTE(B3,"_","") -> dwaccountid | J3: =SUBSTITUTE(E3,"_","") -> dwaccountid
B4: dw_client_id | C4: varchar | D4: 50 | E4: dw_client_id | F4: 8 | G4: =IF(I4=J4,"Pass","Fail") -> Pass | H4: =IF(AND(ISBLANK(D4),F4>=0),"Pass",IF(F4<=D4,"Pass","Fail")) -> Pass | I4: =SUBSTITUTE(B4,"_","") -> dwclientid | J4: =SUBSTITUTE(E4,"_","") -> dwclientid | L4: Overall | M4: Result
B5: dw_member_id | C5: varchar | D5: 50 | E5: dw_member_id | F5: 32 | G5: =IF(I5=J5,"Pass","Fail") -> Pass | H5: =IF(AND(ISBLANK(D5),F5>=0),"Pass",IF(F5<=D5,"Pass","Fail")) -> Pass | I5: =SUBSTITUTE(B5,"_","") -> dwmemberid | J5: =SUBSTITUTE(E5,"_","") -> dwmemberid | L5: Layout Result | M5: =IF(ISERROR(VLOOKUP($O$1,$G$2:$G$10,1,)),"Pass","Fail") -> Pass
B6: mbr_id | C6: varchar | D6: 32 | E6: mbr_id | F6: 32 | G6: =IF(I6=J6,"Pass","Fail") -> Pass | H6: =IF(AND(ISBLANK(D6),F6>=0),"Pass",IF(F6<=D6,"Pass","Fail")) -> Pass | I6: =SUBSTITUTE(B6,"_","") -> mbrid | J6: =SUBSTITUTE(E6,"_","") -> mbrid | L6: Field Length Result | M6: =IF(ISERROR(VLOOKUP($O$1,$H$2:$H$10,1,)),"Pass","Fail") -> Pass
B7: Diagnosis_code | C7: varchar | D7: 10 | E7: diagnosis_code | F7: 8 | G7: =IF(I7=J7,"Pass","Fail") -> Pass | H7: =IF(AND(ISBLANK(D7),F7>=0),"Pass",IF(F7<=D7,"Pass","Fail")) -> Pass | I7: =SUBSTITUTE(B7,"_","") -> Diagnosiscode | J7: =SUBSTITUTE(E7,"_","") -> diagnosiscode | L7: % change in count with respect to previous count | M7: =IF(M2=0,0%,N2/M2) -> 0.033903601
B8: Paid_Amount | C8: varchar | D8: 50 | E8: paid_amount | F8: 23 | G8: =IF(I8=J8,"Pass","Fail") -> Pass | H8: =IF(AND(ISBLANK(D8),F8>=0),"Pass",IF(F8<=D8,"Pass","Fail")) -> Pass | I8: =SUBSTITUTE(B8,"_","") -> PaidAmount | J8: =SUBSTITUTE(E8,"_","") -> paidamount | L8: % change in file size with respect to previous file | M8: =File_Size_Comparision!F7 -> 0.019230769
B9: SuperGrouperDescription | C9: varchar | D9: 50 | E9: superGrouperDescription | F9: 29 | G9: =IF(I9=J9,"Pass","Fail") -> Pass | H9: =IF(AND(ISBLANK(D9),F9>=0),"Pass",IF(F9<=D9,"Pass","Fail")) -> Pass | I9: =SUBSTITUTE(B9,"_","") -> SuperGrouperDescription | J9: =SUBSTITUTE(E9,"_","") -> superGrouperDescription
B10: GrouperDescription | C10: date | D10: 50 | E10: grouperDescription | F10: 40 | G10: =IF(I10=J10,"Pass","Fail") -> Pass | H10: =IF(AND(ISBLANK(D10),F10>=0),"Pass",IF(F10<=D10,"Pass","Fail")) -> Pass | I10: =SUBSTITUTE(B10,"_","") -> GrouperDescription | J10: =SUBSTITUTE(E10,"_","") -> grouperDescription

Sheet Historical_Scores
B1: Client layout | C1: Data Type | D1: Client Length | E1: Extract Layout | F1: Extract Length | G1: Layout Result | H1: Length Result
B2: dw_record_id | C2: int | E2: dw_record_id | F2: 6 | G2: =IF(I2=J2,"Pass","Fail") -> Pass | H2: =IF(AND(ISBLANK(D2),F2>=0),"Pass",IF(F2<=D2,"Pass","Fail")) -> Pass | I2: =SUBSTITUTE(B2,"_","") -> dwrecordid | J2: =SUBSTITUTE(E2,"_","") -> dwrecordid | L2: Current Extract Count | M2: Previous Extract Count | N2: Difference
B3: dw_account_id | C3: varchar | D3: 50 | E3: dw_account_id | F3: 0 | G3: =IF(I3=J3,"Pass","Fail") -> Pass | H3: =IF(AND(ISBLANK(D3),F3>=0),"Pass",IF(F3<=D3,"Pass","Fail")) -> Pass | I3: =SUBSTITUTE(B3,"_","") -> dwaccountid | J3: =SUBSTITUTE(E3,"_","") -> dwaccountid | L3: 139066 | M3: 135440 | N3: =L3-M3 -> 3626
B4: dw_client_id | C4: varchar | D4: 50 | E4: dw_client_id | F4: 8 | G4: =IF(I4=J4,"Pass","Fail") -> Pass | H4: =IF(AND(ISBLANK(D4),F4>=0),"Pass",IF(F4<=D4,"Pass","Fail")) -> Pass | I4: =SUBSTITUTE(B4,"_","") -> dwclientid | J4: =SUBSTITUTE(E4,"_","") -> dwclientid
B5: dw_member_id | C5: varchar | D5: 50 | E5: dw_member_id | F5: 32 | G5: =IF(I5=J5,"Pass","Fail") -> Pass | H5: =IF(AND(ISBLANK(D5),F5>=0),"Pass",IF(F5<=D5,"Pass","Fail")) -> Pass | I5: =SUBSTITUTE(B5,"_","") -> dwmemberid | J5: =SUBSTITUTE(E5,"_","") -> dwmemberid | L5: Overall | M5: Result
B6: mbr_id | C6: varchar | D6: 25 | E6: mbr_id | F6: 25 | G6: =IF(I6=J6,"Pass","Fail") -> Pass | H6: =IF(AND(ISBLANK(D6),F6>=0),"Pass",IF(F6<=D6,"Pass","Fail")) -> Pass | I6: =SUBSTITUTE(B6,"_","") -> mbrid | J6: =SUBSTITUTE(E6,"_","") -> mbrid | L6: Layout Result | M6: =IF(ISERROR(VLOOKUP($O$1,$G$2:$G$26,1,)),"Pass","Fail") -> Pass
B7: score_type | C7: varchar | D7: 50 | E7: score_type | F7: 0 | G7: =IF(I7=J7,"Pass","Fail") -> Pass | H7: =IF(AND(ISBLANK(D7),F7>=0),"Pass",IF(F7<=D7,"Pass","Fail")) -> Pass | I7: =SUBSTITUTE(B7,"_","") -> scoretype | J7: =SUBSTITUTE(E7,"_","") -> scoretype | L7: Field Length Result | M7: =IF(ISERROR(VLOOKUP($O$1,$H$2:$H$26,1,)),"Pass","Fail") -> Pass
B8: score_start_date | C8: date | E8: score_start_date | F8: 10 | G8: =IF(I8=J8,"Pass","Fail") -> Pass | H8: =IF(AND(ISBLANK(D8),F8>=0),"Pass",IF(F8<=D8,"Pass","Fail")) -> Pass | I8: =SUBSTITUTE(B8,"_","") -> scorestartdate | J8: =SUBSTITUTE(E8,"_","") -> scorestartdate | L8: % change in count with respect to previous count | M8: =IF(M3=0,0%,N3/M3) -> 0.026772002
B9: score_end_date | C9: date | E9: score_end_date | F9: 10 | G9: =IF(I9=J9,"Pass","Fail") -> Pass | H9: =IF(AND(ISBLANK(D9),F9>=0),"Pass",IF(F9<=D9,"Pass","Fail")) -> Pass | I9: =SUBSTITUTE(B9,"_","") -> scoreenddate | J9: =SUBSTITUTE(E9,"_","") -> scoreenddate | L9: % change in file size with respect to previous file | M9: =File_Size_Comparision!F8 -> 0.026586621
B10: ip_score | C10: varchar | D10: 50 | E10: ip_score | F10: 5 | G10: =IF(I10=J10,"Pass","Fail") -> Pass | H10: =IF(AND(ISBLANK(D10),F10>=0),"Pass",IF(F10<=D10,"Pass","Fail")) -> Pass | I10: =SUBSTITUTE(B10,"_","") -> ipscore | J10: =SUBSTITUTE(E10,"_","") -> ipscore
B11: op_score | C11: varchar | D11: 50 | E11: op_score | F11: 5 | G11: =IF(I11=J11,"Pass","Fail") -> Pass | H11: =IF(AND(ISBLANK(D11),F11>=0),"Pass",IF(F11<=D11,"Pass","Fail")) -> Pass | I11: =SUBSTITUTE(B11,"_","") -> opscore | J11: =SUBSTITUTE(E11,"_","") -> opscore
B12: phy_score | C12: varchar | D12: 50 | E12: phy_score | F12: 4 | G12: =IF(I12=J12,"Pass","Fail") -> Pass | H12: =IF(AND(ISBLANK(D12),F12>=0),"Pass",IF(F12<=D12,"Pass","Fail")) -> Pass | I12: =SUBSTITUTE(B12,"_","") -> physcore | J12: =SUBSTITUTE(E12,"_","") -> physcore
B13: rx_score | C13: varchar | D13: 50 | E13: rx_score | F13: 5 | G13: =IF(I13=J13,"Pass","Fail") -> Pass | H13: =IF(AND(ISBLANK(D13),F13>=0),"Pass",IF(F13<=D13,"Pass","Fail")) -> Pass | I13: =SUBSTITUTE(B13,"_","") -> rxscore | J13: =SUBSTITUTE(E13,"_","") -> rxscore
B14: med_score | C14: varchar | D14: 50 | E14: med_score | F14: 5 | G14: =IF(I14=J14,"Pass","Fail") -> Pass | H14: =IF(AND(ISBLANK(D14),F14>=0),"Pass",IF(F14<=D14,"Pass","Fail")) -> Pass | I14: =SUBSTITUTE(B14,"_","") -> medscore | J14: =SUBSTITUTE(E14,"_","") -> medscore
B15: total_score | C15: varchar | D15: 50 | E15: total_score | F15: 5 | G15: =IF(I15=J15,"Pass","Fail") -> Pass | H15: =IF(AND(ISBLANK(D15),F15>=0),"Pass",IF(F15<=D15,"Pass","Fail")) -> Pass | I15: =SUBSTITUTE(B15,"_","") -> totalscore | J15: =SUBSTITUTE(E15,"_","") -> totalscore
B16: concurrent_total | C16: varchar | D16: 50 | E16: concurrent_total | F16: 5 | G16: =IF(I16=J16,"Pass","Fail") -> Pass | H16: =IF(AND(ISBLANK(D16),F16>=0),"Pass",IF(F16<=D16,"Pass","Fail")) -> Pass | I16: =SUBSTITUTE(B16,"_","") -> concurrenttotal | J16: =SUBSTITUTE(E16,"_","") -> concurrenttotal
B17: erScore | C17: varchar | D17: 50 | E17: erScore | F17: 4 | G17: =IF(I17=J17,"Pass","Fail") -> Pass | H17: =IF(AND(ISBLANK(D17),F17>=0),"Pass",IF(F17<=D17,"Pass","Fail")) -> Pass | I17: =SUBSTITUTE(B17,"_","") -> erScore | J17: =SUBSTITUTE(E17,"_","") -> erScore
B18: otherScore | C18: varchar | D18: 50 | E18: otherScore | F18: 4 | G18: =IF(I18=J18,"Pass","Fail") -> Pass | H18: =IF(AND(ISBLANK(D18),F18>=0),"Pass",IF(F18<=D18,"Pass","Fail")) -> Pass | I18: =SUBSTITUTE(B18,"_","") -> otherScore | J18: =SUBSTITUTE(E18,"_","") -> otherScore
B19: concurrentInpatient | C19: varchar | D19: 50 | E19: concurrentInpatient | F19: 5 | G19: =IF(I19=J19,"Pass","Fail") -> Pass | H19: =IF(AND(ISBLANK(D19),F19>=0),"Pass",IF(F19<=D19,"Pass","Fail")) -> Pass | I19: =SUBSTITUTE(B19,"_","") -> concurrentInpatient | J19: =SUBSTITUTE(E19,"_","") -> concurrentInpatient
B20: concurrentMedical | C20: varchar | D20: 50 | E20: concurrentMedical | F20: 5 | G20: =IF(I20=J20,"Pass","Fail") -> Pass | H20: =IF(AND(ISBLANK(D20),F20>=0),"Pass",IF(F20<=D20,"Pass","Fail")) -> Pass | I20: =SUBSTITUTE(B20,"_","") -> concurrentMedical | J20: =SUBSTITUTE(E20,"_","") -> concurrentMedical
B21: concurrentOutpatient | C21: varchar | D21: 50 | E21: concurrentOutpatient | F21: 5 | G21: =IF(I21=J21,"Pass","Fail") -> Pass | H21: =IF(AND(ISBLANK(D21),F21>=0),"Pass",IF(F21<=D21,"Pass","Fail")) -> Pass | I21: =SUBSTITUTE(B21,"_","") -> concurrentOutpatient | J21: =SUBSTITUTE(E21,"_","") -> concurrentOutpatient
... B26: concurrentPhyNormalizedToGroup | C26: varchar | D26: 50 | E26: concurrentPhyNormalizedToGroup | F26: 5 | G26: =IF(I26=J26,"Pass","Fail") -> Pass | H26: =IF(AND(ISBLANK(D26),F26>=0),"Pass",IF(F26<=D26,"Pass","Fail")) -> Pass | I26: =SUBSTITUTE(B26,"_","") -> concurrentPhyNormalizedToGroup | J26: =SUBSTITUTE(E26,"_","") -> concurrentPhyNormalizedToGroup

Sheet Lab
B1: Client layout | C1: Data Type | D1: Client Length | E1: Extract Layout | F1: Extract Length | G1: Layout Result | H1: Length Result | L1: Extract Total Count | M1: Application Total Count | N1: Difference | O1: Fail
B2: dw_record_id | C2: text | D2: 20 | E2: dw_record_id | F2: 5 | G2: =IF(I2=J2,"Pass","Fail") -> Pass | H2: =IF(AND(ISBLANK(D2),F2>=0),"Pass",IF(F2<=D2,"Pass","Fail")) -> Pass | I2: =SUBSTITUTE(B2,"_","") -> dwrecordid | J2: =SUBSTITUTE(E2,"_","") -> dwrecordid | L2: 45720 | M2: 45720 | N2: =L2-M2 -> 0
B3: transaction_id | C3: text | D3: 20 | E3: transaction_id | F3: 0 | G3: =IF(I3=J3,"Pass","Fail") -> Pass | H3: =IF(AND(ISBLANK(D3),F3>=0),"Pass",IF(F3<=D3,"Pass","Fail")) -> Pass | I3: =SUBSTITUTE(B3,"_","") -> transactionid | J3: =SUBSTITUTE(E3,"_","") -> transactionid | L3: Prior Count | N3: =L2-M3 -> 45720
B4: dw_member_id | C4: number | D4: 50 | E4: dw_member_id | F4: 32 | G4: =IF(I4=J4,"Pass","Fail") -> Pass | H4: =IF(AND(ISBLANK(D4),F4>=0),"Pass",IF(F4<=D4,"Pass","Fail")) -> Pass | I4: =SUBSTITUTE(B4,"_","") -> dwmemberid | J4: =SUBSTITUTE(E4,"_","") -> dwmemberid
B5: mbr_id | C5: text | D5: 20 | E5: mbr_id | F5: 20 | G5: =IF(I5=J5,"Pass","Fail") -> Pass | H5: =IF(AND(ISBLANK(D5),F5>=0),"Pass",IF(F5<=D5,"Pass","Fail")) -> Pass | I5: =SUBSTITUTE(B5,"_","") -> mbrid | J5: =SUBSTITUTE(E5,"_","") -> mbrid | L5: Overall | M5: Result
B6: mbr_ssn | C6: text | D6: 20 | E6: mbr_ssn | F6: 11 | G6: =IF(I6=J6,"Pass","Fail") -> Pass | H6: =IF(AND(ISBLANK(D6),F6>=0),"Pass",IF(F6<=D6,"Pass","Fail")) -> Pass | I6: =SUBSTITUTE(B6,"_","") -> mbrssn | J6: =SUBSTITUTE(E6,"_","") -> mbrssn | L6: Layout Result | M6: =IF(ISERROR(VLOOKUP($O$1,$G$2:$G$120,1,)),"Pass","Fail") -> Pass
B7: mbr_first_name | C7: text | D7: 100 | E7: mbr_first_name | F7: 13 | G7: =IF(I7=J7,"Pass","Fail") -> Pass | H7: =IF(AND(ISBLANK(D7),F7>=0),"Pass",IF(F7<=D7,"Pass","Fail")) -> Pass | I7: =SUBSTITUTE(B7,"_","") -> mbrfirstname | J7: =SUBSTITUTE(E7,"_","") -> mbrfirstname | L7: Field Length Result | M7: =IF(ISERROR(VLOOKUP($O$1,$H$2:$H$120,1,)),"Pass","Fail") -> Pass
B8: mbr_middle_name | C8: text | D8: 100 | E8: mbr_middle_name | F8: 0 | G8: =IF(I8=J8,"Pass","Fail") -> Pass | H8: =IF(AND(ISBLANK(D8),F8>=0),"Pass",IF(F8<=D8,"Pass","Fail")) -> Pass | I8: =SUBSTITUTE(B8,"_","") -> mbrmiddlename | J8: =SUBSTITUTE(E8,"_","") -> mbrmiddlename | L8: Count Result | M8: =IF(N2=0,"Pass","Fail") -> Pass
B9: mbr_last_name | C9: text | D9: 100 | E9: mbr_last_name | F9: 18 | G9: =IF(I9=J9,"Pass","Fail") -> Pass | H9: =IF(AND(ISBLANK(D9),F9>=0),"Pass",IF(F9<=D9,"Pass","Fail")) -> Pass | I9: =SUBSTITUTE(B9,"_","") -> mbrlastname | J9: =SUBSTITUTE(E9,"_","") -> mbrlastname | L9: % change in count with respect to previous count | M9: =IF(M3=0,0%,N3/M3) -> 0
B10: mbr_gender | C10: text | D10: 2 | E10: mbr_gender | F10: 1 | G10: =IF(I10=J10,"Pass","Fail") -> Pass | H10: =IF(AND(ISBLANK(D10),F10>=0),"Pass",IF(F10<=D10,"Pass","Fail")) -> Pass | I10: =SUBSTITUTE(B10,"_","") -> mbrgender | J10: =SUBSTITUTE(E10,"_","") -> mbrgender | L10: % change in file size with respect to previous file | M10: =File_Size_Comparision!F9 -> #VALUE!
B11: mbr_dob | C11: date | E11: mbr_dob | F11: 10 | G11: =IF(I11=J11,"Pass","Fail") -> Pass | H11: =IF(AND(ISBLANK(D11),F11>=0),"Pass",IF(F11<=D11,"Pass","Fail")) -> Pass | I11: =SUBSTITUTE(B11,"_","") -> mbrdob | J11: =SUBSTITUTE(E11,"_","") -> mbrdob
B12: mbr_street_1 | C12: text | D12: 50 | E12: mbr_street_1 | F12: 30 | G12: =IF(I12=J12,"Pass","Fail") -> Pass | H12: =IF(AND(ISBLANK(D12),F12>=0),"Pass",IF(F12<=D12,"Pass","Fail")) -> Pass | I12: =SUBSTITUTE(B12,"_","") -> mbrstreet1 | J12: =SUBSTITUTE(E12,"_","") -> mbrstreet1
B13: mbr_street_2 | C13: text | D13: 50 | E13: mbr_street_2 | F13: 21 | G13: =IF(I13=J13,"Pass","Fail") -> Pass | H13: =IF(AND(ISBLANK(D13),F13>=0),"Pass",IF(F13<=D13,"Pass","Fail")) -> Pass | I13: =SUBSTITUTE(B13,"_","") -> mbrstreet2 | J13: =SUBSTITUTE(E13,"_","") -> mbrstreet2
B14: mbr_city | C14: text | D14: 20 | E14: mbr_city | F14: 18 | G14: =IF(I14=J14,"Pass","Fail") -> Pass | H14: =IF(AND(ISBLANK(D14),F14>=0),"Pass",IF(F14<=D14,"Pass","Fail")) -> Pass | I14: =SUBSTITUTE(B14,"_","") -> mbrcity | J14: =SUBSTITUTE(E14,"_","") -> mbrcity
B15: mbr_county | C15: text | D15: 20 | E15: mbr_county | F15: 5 | G15: =IF(I15=J15,"Pass","Fail") -> Pass | H15: =IF(AND(ISBLANK(D15),F15>=0),"Pass",IF(F15<=D15,"Pass","Fail")) -> Pass | I15: =SUBSTITUTE(B15,"_","") -> mbrcounty | J15: =SUBSTITUTE(E15,"_","") -> mbrcounty
B16: mbr_state | C16: text | D16: 2 | E16: mbr_state | F16: 2 | G16: =IF(I16=J16,"Pass","Fail") -> Pass | H16: =IF(AND(ISBLANK(D16),F16>=0),"Pass",IF(F16<=D16,"Pass","Fail")) -> Pass | I16: =SUBSTITUTE(B16,"_","") -> mbrstate | J16: =SUBSTITUTE(E16,"_","") -> mbrstate
B17: mbr_zip | C17: text | D17: 10 | E17: mbr_zip | F17: 5 | G17: =IF(I17=J17,"Pass","Fail") -> Pass | H17: =IF(AND(ISBLANK(D17),F17>=0),"Pass",IF(F17<=D17,"Pass","Fail")) -> Pass | I17: =SUBSTITUTE(B17,"_","") -> mbrzip | J17: =SUBSTITUTE(E17,"_","") -> mbrzip
B18: mbr_phone | C18: text | D18: 15 | E18: mbr_phone | F18: 10 | G18: =IF(I18=J18,"Pass","Fail") -> Pass | H18: =IF(AND(ISBLANK(D18),F18>=0),"Pass",IF(F18<=D18,"Pass","Fail")) -> Pass | I18: =SUBSTITUTE(B18,"_","") -> mbrphone | J18: =SUBSTITUTE(E18,"_","") -> mbrphone
B19: mbr_email_address | C19: text | D19: 50 | E19: mbr_email_address | F19: 0 | G19: =IF(I19=J19,"Pass","Fail") -> Pass | H19: =IF(AND(ISBLANK(D19),F19>=0),"Pass",IF(F19<=D19,"Pass","Fail")) -> Pass | I19: =SUBSTITUTE(B19,"_","") -> mbremailaddress | J19: =SUBSTITUTE(E19,"_","") -> mbremailaddress
B20: mbr_marital_status | C20: text | D20: 20 | E20: mbr_marital_status | F20: 0 | G20: =IF(I20=J20,"Pass","Fail") -> Pass | H20: =IF(AND(ISBLANK(D20),F20>=0),"Pass",IF(F20<=D20,"Pass","Fail")) -> Pass | I20: =SUBSTITUTE(B20,"_","") -> mbrmaritalstatus | J20: =SUBSTITUTE(E20,"_","") -> mbrmaritalstatus
B21: mbr_race | C21: text | D21: 50 | E21: mbr_race | F21: 0 | G21: =IF(I21=J21,"Pass","Fail") -> Pass | H21: =IF(AND(ISBLANK(D21),F21>=0),"Pass",IF(F21<=D21,"Pass","Fail")) -> Pass | I21: =SUBSTITUTE(B21,"_","") -> mbrrace | J21: =SUBSTITUTE(E21,"_","") -> mbrrace
B22: mbr_ethnic_group | C22: text | D22: 50 | E22: mbr_ethnic_group | F22: 0 | G22: =IF(I22=J22,"Pass","Fail") -> Pass | H22: =IF(AND(ISBLANK(D22),F22>=0),"Pass",IF(F22<=D22,"Pass","Fail")) -> Pass | I22: =SUBSTITUTE(B22,"_","") -> mbrethnicgroup | J22: =SUBSTITUTE(E22,"_","") -> mbrethnicgroup
B23: mbr_edu_lvl | C23: text | D23: 50 | E23: mbr_edu_lvl | F23: 0 | G23: =IF(I23=J23,"Pass","Fail") -> Pass | H23: =IF(AND(ISBLANK(D23),F23>=0),"Pass",IF(F23<=D23,"Pass","Fail")) -> Pass | I23: =SUBSTITUTE(B23,"_","") -> mbredulvl | J23: =SUBSTITUTE(E23,"_","") -> mbredulvl
... B32: ins_carrier_name | C32: text | D32: 100 | E32: ins_carrier_name | F32: 12 | G32: =IF(I32=J32,"Pass","Fail") -> Pass | H32: =IF(AND(ISBLANK(D32),F32>=0),"Pass",IF(F32<=D32,"Pass","Fail")) -> Pass | I32: =SUBSTITUTE(B32,"_","") -> inscarriername | J32: =SUBSTITUTE(E32,"_","") -> inscarriername
B33: ins_division_id | C33: text | D33: 47 | E33: ins_division_id | F33: 47 | G33: =IF(I33=J33,"Pass","Fail") -> Pass | H33: =IF(AND(ISBLANK(D33),F33>=0),"Pass",IF(F33<=D33,"Pass","Fail")) -> Pass | I33: =SUBSTITUTE(B33,"_","") -> insdivisionid | J33: =SUBSTITUTE(E33,"_","") -> insdivisionid | K33: ins_division_id field length changed from 20 to 47
B34: ins_division_name | C34: text | D34: 100 | E34: ins_division_name | F34: 56 | G34: =IF(I34=J34,"Pass","Fail") -> Pass | H34: =IF(AND(ISBLANK(D34),F34>=0),"Pass",IF(F34<=D34,"Pass","Fail")) -> Pass | I34: =SUBSTITUTE(B34,"_","") -> insdivisionname | J34: =SUBSTITUTE(E34,"_","") -> insdivisionname
B35: ins_plan_id | C35: text | D35: 66 | E35: ins_plan_id | F35: 66 | G35: =IF(I35=J35,"Pass","Fail") -> Pass | H35: =IF(AND(ISBLANK(D35),F35>=0),"Pass",IF(F35<=D35,"Pass","Fail")) -> Pass | I35: =SUBSTITUTE(B35,"_","") -> insplanid | J35: =SUBSTITUTE(E35,"_","") -> insplanid
B36: ins_plan_desc | C36: text | D36: 100 | E36: ins_plan_desc | F36: 86 | G36: =IF(I36=J36,"Pass","Fail") -> Pass | H36: =IF(AND(ISBLANK(D36),F36>=0),"Pass",IF(F36<=D36,"Pass","Fail")) -> Pass | I36: =SUBSTITUTE(B36,"_","") -> insplandesc | J36: =SUBSTITUTE(E36,"_","") -> insplandesc
B37: prv_provider_id | C37: text | D37: 20 | E37: prv_provider_id | F37: 0 | G37: =IF(I37=J37,"Pass","Fail") -> Pass | H37: =IF(AND(ISBLANK(D37),F37>=0),"Pass",IF(F37<=D37,"Pass","Fail")) -> Pass | I37: =SUBSTITUTE(B37,"_","") -> prvproviderid | J37: =SUBSTITUTE(E37,"_","") -> prvproviderid
B38: prv_first_name | C38: text | D38: 100 | E38: prv_first_name | F38: 0 | G38: =IF(I38=J38,"Pass","Fail") -> Pass | H38: =IF(AND(ISBLANK(D38),F38>=0),"Pass",IF(F38<=D38,"Pass","Fail")) -> Pass | I38: =SUBSTITUTE(B38,"_","") -> prvfirstname | J38: =SUBSTITUTE(E38,"_","") -> prvfirstname
B39: prv_middle_name | C39: text | D39: 100 | E39: prv_middle_name | F39: 0 | G39: =IF(I39=J39,"Pass","Fail") -> Pass | H39: =IF(AND(ISBLANK(D39),F39>=0),"Pass",IF(F39<=D39,"Pass","Fail")) -> Pass | I39: =SUBSTITUTE(B39,"_","") -> prvmiddlename | J39: =SUBSTITUTE(E39,"_","") -> prvmiddlename
B40: prv_last_name | C40: text | D40: 100 | E40: prv_last_name | F40: 0 | G40: =IF(I40=J40,"Pass","Fail") -> Pass | H40: =IF(AND(ISBLANK(D40),F40>=0),"Pass",IF(F40<=D40,"Pass","Fail")) -> Pass | I40: =SUBSTITUTE(B40,"_","") -> prvlastname | J40: =SUBSTITUTE(E40,"_","") -> prvlastname
