Workbook

Sheet Test_Summary
B1: Test Case Revision History
B2: Date | C2: Version | D2: Description | E2: Author | F2: Reviewer/s | G2: Remarks
B3: 42418 | C3: 1.0 | E3: RaghuP
B4: 42425 | C4: 1.1 | D4: Overall Result Auto Display function added. | E4: RaghuP
B5: 42578 | C5: 1.2 | D5: Previous Extract and Current Count section added in each tab | E5: RaghuP
B6: 42587 | C6: 1.3 | D6: Count Verification between extract and application added in each tab | E6: RaghuP
B8: Test Case Execution History
B9: Start Date | C9: End Date | D9: Test Environment | E9: Tester | F9: Overall Result | G9: Remarks
B10: 42825 | C10: 42825 | D10: UAT | E10: SubinV | F10: Partially Pass
B12: Test Case Summary Results
B13: Test Case ID | C13: Summary | G13: Test Result
B14: EX01 | C14: Verify file size | G14: =File_Size_Comparision!L2 -> Fail
B15: EX02 | C15: Verify Demographics layout | G15: =Demographics!M5 -> Pass
B16: EX03 | C16: Verify Demographics field length | G16: =Demographics!M6 -> Pass
B17: EX04 | C17: Verify Eligibility layout | G17: =Eligibility!M6 -> Pass
B18: EX05 | C18: Verify Eligibility field length | G18: =Eligibility!M7 -> Pass
B19: EX06 | C19: Verify Eligibility count between application and extract | G19: =Eligibility!M8 -> Pass
B20: EX07 | C20: Verify High_Cost layout | G20: =High_Cost!M5 -> Pass
B21: EX08 | C21: Verify High_Cost field length | G21: =High_Cost!M6 -> Pass
B22: EX09 | C22: Verify Medcial Claims layout | G22: =Medical_Claims!M6 -> Pass
B23: EX10 | C23: Verify Medcial Claims field length | G23: =Medical_Claims!M7 -> Pass
B24: EX11 | C24: Verify Medcial Claims count between application and extract | G24: =Medical_Claims!M8 -> Pass
B25: EX12 | C25: Verify Participation layout | G25: =Participation!M7 -> Fail
B26: EX13 | C26: Verify Participation field length | G26: =Participation!M8 -> Pass
B27: EX14 | C27: Verify Participation count between application and extract | G27: =Participation!M9 -> Pass
B28: EX15 | C28: Verify Member PCP layout | G28: =Member_PCP!M6 -> Pass
B29: EX16 | C29: Verify Member PCP field length | G29: =Member_PCP!M7 -> Pass
B30: EX17 | C30: Verify Pharmacy layout | G30: =Pharmacy!M6 -> Pass
B31: EX18 | C31: Verify Pharmacy field length | G31: =Pharmacy!M7 -> Pass
B32: EX19 | C32: Verify Pharmacy count between application and extract | G32: =Pharmacy!M8 -> Pass
B33: EX20 | C33: Verify Quality Metrics layout | G33: =Quality_Metrics!M6 -> Pass
B34: EX21 | C34: Verify Quality Metrics field length | G34: =Quality_Metrics!M7 -> Pass
B35: EX22 | C35: Verify Scores layout | G35: =Scores!M6 -> Pass
B36: EX23 | C36: Verify Scores field length | G36: =Scores!M7 -> Pass
B37: EX24 | C37: Verify Visit layout | G37: =Visit!M6 -> Pass
B38: EX25 | C38: Verify Visit field length | G38: =Visit!M7 -> Pass

Sheet File_Size_Comparision
B1: Previous Extract | D1: Current Extract | F1: % Change | G1: Test Result | M1: Fail
B2: File Name | C2: Size | D2: File Name | E2: Size | K2: Overall File Size Result | L2: =IF(ISERROR(VLOOKUP($M$1,$G$2:$G$11,1,)),"Pass","Fail") -> Fail
B3: CareAlerts.csv | C3: 3.96 MB | D3: CareAlerts.csv | E3: 7.70 MB | F3: =IF(I3=0,0%,(I3-H3)/I3) -> 0.48571429 | G3: =IF(AND(F3<=10%,F3>=-10%),"Pass","Fail") -> Fail | H3: =LEFT(C3, SEARCH(" ", C3, 1)) -> 3.96 | I3: =LEFT(E3, SEARCH(" ", E3, 1)) -> 7.70
B4: Demographics.csv | C4: 1.58 MB | D4: Demographics.csv | E4: 3.24 MB | F4: =IF(I4=0,0%,(I4-H4)/I4) -> 0.51234568 | G4: =IF(AND(F4<=10%,F4>=-10%),"Pass","Fail") -> Fail | H4: =LEFT(C4, SEARCH(" ", C4, 1)) -> 1.58 | I4: =LEFT(E4, SEARCH(" ", E4, 1)) -> 3.24
B5: Eligibility.csv | C5: 89.56 MB | D5: Eligibility.csv | E5: 115.13 MB | F5: =IF(I5=0,0%,(I5-H5)/I5) -> 0.22209676 | G5: =IF(AND(F5<=10%,F5>=-10%),"Pass","Fail") -> Fail | H5: =LEFT(C5, SEARCH(" ", C5, 1)) -> 89.56 | I5: =LEFT(E5, SEARCH(" ", E5, 1)) -> 115.13
B6: HighCost.csv | C6: 719.15 KB | D6: HighCost.csv | E6: 1566.72 KB | F6: =IF(I6=0,0%,(I6-H6)/I6) -> 0.54098371 | G6: =IF(AND(F6<=10%,F6>=-10%),"Pass","Fail") -> Fail | H6: =LEFT(C6, SEARCH(" ", C6, 1)) -> 719.15 | I6: =LEFT(E6, SEARCH(" ", E6, 1)) -> 1566.72
B7: HistoricalScores.csv | C7: 6.76 MB | D7: HistoricalScores.csv | E7: 8.99 MB | F7: =IF(I7=0,0%,(I7-H7)/I7) -> 0.24805339 | G7: =IF(AND(F7<=10%,F7>=-10%),"Pass","Fail") -> Fail | H7: =LEFT(C7, SEARCH(" ", C7, 1)) -> 6.76 | I7: =LEFT(E7, SEARCH(" ", E7, 1)) -> 8.99
B8: Medical.csv | C8: 500.43 MB | D8: Medical.csv | E8: 1177.6 GB | F8: =IF(I8=0,0%,(I8-H8)/I8) -> 0.57504246 | G8: =IF(AND(F8<=10%,F8>=-10%),"Pass","Fail") -> Fail | H8: =LEFT(C8, SEARCH(" ", C8, 1)) -> 500.43 | I8: =LEFT(E8, SEARCH(" ", E8, 1)) -> 1177.6
B9: Participation.csv | C9: 151 Byte | D9: Participation.csv | F9: =IF(I9=0,0%,(I9-H9)/I9) -> #VALUE! | G9: =IF(AND(F9<=10%,F9>=-10%),"Pass","Fail") -> #VALUE! | H9: =LEFT(C9, SEARCH(" ", C9, 1)) -> 151 | I9: =LEFT(E9, SEARCH(" ", E9, 1)) -> #VALUE!
B10: Pcp.csv | C10: 635.58 KB | D10: Pcp.csv | E10: 945 KB | F10: =IF(I10=0,0%,(I10-H10)/I10) -> 0.32742857 | G10: =IF(AND(F10<=10%,F10>=-10%),"Pass","Fail") -> Fail | H10: =LEFT(C10, SEARCH(" ", C10, 1)) -> 635.58 | I10: =LEFT(E10, SEARCH(" ", E10, 1)) -> 945
B11: Pharmacy.csv | C11: 52.38 MB | D11: Pharmacy.csv | E11: 122.73 MB | F11: =IF(I11=0,0%,(I11-H11)/I11) -> 0.57320948 | G11: =IF(AND(F11<=10%,F11>=-10%),"Pass","Fail") -> Fail | H11: =LEFT(C11, SEARCH(" ", C11, 1)) -> 52.38 | I11: =LEFT(E11, SEARCH(" ", E11, 1)) -> 122.73
B12: QualityMetrics.csv | C12: 19.32 MB | D12: QualityMetrics.csv | E12: 38.85 MB | F12: =IF(I12=0,0%,(I12-H12)/I12) -> 0.5027027 | G12: =IF(AND(F12<=10%,F12>=-10%),"Pass","Fail") -> Fail | H12: =LEFT(C12, SEARCH(" ", C12, 1)) -> 19.32 | I12: =LEFT(E12, SEARCH(" ", E12, 1)) -> 38.85
B13: Scores.csv | C13: 574.77 KB | D13: Scores.csv | E13: 1443.84 KB | F13: =IF(I13=0,0%,(I13-H13)/I13) -> 0.60191572 | G13: =IF(AND(F13<=10%,F13>=-10%),"Pass","Fail") -> Fail | H13: =LEFT(C13, SEARCH(" ", C13, 1)) -> 574.77 | I13: =LEFT(E13, SEARCH(" ", E13, 1)) -> 1443.84
B14: Visits.csv | C14: 6.25 MB | D14: Visits.csv | E14: 13.64 MB | F14: =IF(I14=0,0%,(I14-H14)/I14) -> 0.54178886 | G14: =IF(AND(F14<=10%,F14>=-10%),"Pass","Fail") -> Fail | H14: =LEFT(C14, SEARCH(" ", C14, 1)) -> 6.25 | I14: =LEFT(E14, SEARCH(" ", E14, 1)) -> 13.64

Sheet Care_Alerts
B1: Client layout | C1: Data Type | D1: Client Length | E1: Extract Layout | F1: Extract Length | G1: Layout Result | H1: Length Result | L1: Current Extract Count | M1: Previous Extract Count | N1: Difference
B2: dw_record_id | C2: int | E2: dw_record_id | F2: 5 | G2: =IF(I2=J2,"Pass","Fail") -> Pass | H2: =IF(AND(ISBLANK(D2),F2>=0),"Pass",IF(F2<=D2,"Pass","Fail")) -> Pass | I2: =SUBSTITUTE(B2,"_","") -> dwrecordid | J2: =SUBSTITUTE(E2,"_","") -> dwrecordid | L2: 36646 | M2: 18577 | N2: =L2-M2 -> 18069
B3: dw_member_id | C3: varchar | D3: 50 | E3: dw_member_id | F3: 32 | G3: =IF(I3=J3,"Pass","Fail") -> Pass | H3: =IF(AND(ISBLANK(D3),F3>=0),"Pass",IF(F3<=D3,"Pass","Fail")) -> Pass | I3: =SUBSTITUTE(B3,"_","") -> dwmemberid | J3: =SUBSTITUTE(E3,"_","") -> dwmemberid
B4: mbr_id | C4: varchar | D4: 50 | E4: mbr_id | F4: 32 | G4: =IF(I4=J4,"Pass","Fail") -> Pass | H4: =IF(AND(ISBLANK(D4),F4>=0),"Pass",IF(F4<=D4,"Pass","Fail")) -> Pass | I4: =SUBSTITUTE(B4,"_","") -> mbrid | J4: =SUBSTITUTE(E4,"_","") -> mbrid | L4: Overall | M4: Result
B5: first_name | C5: varchar | D5: 50 | E5: first_name | F5: 15 | G5: =IF(I5=J5,"Pass","Fail") -> Pass | H5: =IF(AND(ISBLANK(D5),F5>=0),"Pass",IF(F5<=D5,"Pass","Fail")) -> Pass | I5: =SUBSTITUTE(B5,"_","") -> firstname | J5: =SUBSTITUTE(E5,"_","") -> firstname | L5: Layout Result | M5: =IF(ISERROR(VLOOKUP($O$1,$G$2:$G$19,1,)),"Pass","Fail") -> Pass
B6: last_name | C6: varchar | D6: 20 | E6: last_name | F6: 17 | G6: =IF(I6=J6,"Pass","Fail") -> Pass | H6: =IF(AND(ISBLANK(D6),F6>=0),"Pass",IF(F6<=D6,"Pass","Fail")) -> Pass | I6: =SUBSTITUTE(B6,"_","") -> lastname | J6: =SUBSTITUTE(E6,"_","") -> lastname | L6: Field Length Result | M6: =IF(ISERROR(VLOOKUP($O$1,$H$2:$H$19,1,)),"Pass","Fail") -> Pass
B7: middle_name | C7: varchar | D7: 10 | E7: middle_name | F7: 0 | G7: =IF(I7=J7,"Pass","Fail") -> Pass | H7: =IF(AND(ISBLANK(D7),F7>=0),"Pass",IF(F7<=D7,"Pass","Fail")) -> Pass | I7: =SUBSTITUTE(B7,"_","") -> middlename | J7: =SUBSTITUTE(E7,"_","") -> middlename | L7: % change in count with respect to previous count | M7: =IF(M2=0,0%,N2/M2) -> 0.97265436
B8: mbr_dob | C8: date | E8: mbr_dob | F8: 10 | G8: =IF(I8=J8,"Pass","Fail") -> Pass | H8: =IF(AND(ISBLANK(D8),F8>=0),"Pass",IF(F8<=D8,"Pass","Fail")) -> Pass | I8: =SUBSTITUTE(B8,"_","") -> mbrdob | J8: =SUBSTITUTE(E8,"_","") -> mbrdob | L8: % change in file size with respect to previous file | M8: =File_Size_Comparision!F3 -> 0.48571429
B9: mbr_gender | C9: varchar | D9: 10 | E9: mbr_gender | F9: 7 | G9: =IF(I9=J9,"Pass","Fail") -> Pass | H9: =IF(AND(ISBLANK(D9),F9>=0),"Pass",IF(F9<=D9,"Pass","Fail")) -> Pass | I9: =SUBSTITUTE(B9,"_","") -> mbrgender | J9: =SUBSTITUTE(E9,"_","") -> mbrgender
B10: mbr_status | C10: varchar | D10: 10 | E10: mbr_status | F10: 6 | G10: =IF(I10=J10,"Pass","Fail") -> Pass | H10: =IF(AND(ISBLANK(D10),F10>=0),"Pass",IF(F10<=D10,"Pass","Fail")) -> Pass | I10: =SUBSTITUTE(B10,"_","") -> mbrstatus | J10: =SUBSTITUTE(E10,"_","") -> mbrstatus
B11: mbr_relationship | C11: varchar | D11: 50 | E11: mbr_relationship | F11: 42 | G11: =IF(I11=J11,"Pass","Fail") -> Pass | H11: =IF(AND(ISBLANK(D11),F11>=0),"Pass",IF(F11<=D11,"Pass","Fail")) -> Pass | I11: =SUBSTITUTE(B11,"_","") -> mbrrelationship | J11: =SUBSTITUTE(E11,"_","") -> mbrrelationship
B12: pcp_full_name | C12: varchar | D12: 65 | E12: pcp_full_name | F12: 65 | G12: =IF(I12=J12,"Pass","Fail") -> Pass | H12: =IF(AND(ISBLANK(D12),F12>=0),"Pass",IF(F12<=D12,"Pass","Fail")) -> Pass | I12: =SUBSTITUTE(B12,"_","") -> pcpfullname | J12: =SUBSTITUTE(E12,"_","") -> pcpfullname
B13: mbr_age | C13: varchar | D13: 3 | E13: mbr_age | F13: 3 | G13: =IF(I13=J13,"Pass","Fail") -> Pass | H13: =IF(AND(ISBLANK(D13),F13>=0),"Pass",IF(F13<=D13,"Pass","Fail")) -> Pass | I13: =SUBSTITUTE(B13,"_","") -> mbrage | J13: =SUBSTITUTE(E13,"_","") -> mbrage
B14: mbr_months | C14: varchar | D14: 3 | E14: mbr_months | F14: 2 | G14: =IF(I14=J14,"Pass","Fail") -> Pass | H14: =IF(AND(ISBLANK(D14),F14>=0),"Pass",IF(F14<=D14,"Pass","Fail")) -> Pass | I14: =SUBSTITUTE(B14,"_","") -> mbrmonths | J14: =SUBSTITUTE(E14,"_","") -> mbrmonths
B15: care_alert_startDate | C15: date | E15: care_alert_startDate | F15: 10 | G15: =IF(I15=J15,"Pass","Fail") -> Pass | H15: =IF(AND(ISBLANK(D15),F15>=0),"Pass",IF(F15<=D15,"Pass","Fail")) -> Pass | I15: =SUBSTITUTE(B15,"_","") -> carealertstartDate | J15: =SUBSTITUTE(E15,"_","") -> carealertstartDate
B16: care_alert_id | C16: varchar | D16: 50 | E16: care_alert_id | F16: 21 | G16: =IF(I16=J16,"Pass","Fail") -> Pass | H16: =IF(AND(ISBLANK(D16),F16>=0),"Pass",IF(F16<=D16,"Pass","Fail")) -> Pass | I16: =SUBSTITUTE(B16,"_","") -> carealertid | J16: =SUBSTITUTE(E16,"_","") -> carealertid
B17: care_alert_desc | C17: varchar | D17: 94 | E17: care_alert_desc | F17: 94 | G17: =IF(I17=J17,"Pass","Fail") -> Pass | H17: =IF(AND(ISBLANK(D17),F17>=0),"Pass",IF(F17<=D17,"Pass","Fail")) -> Pass | I17: =SUBSTITUTE(B17,"_","") -> carealertdesc | J17: =SUBSTITUTE(E17,"_","") -> carealertdesc
B18: metric_Type | C18: varchar | D18: 50 | E18: metric_Type | F18: 15 | G18: =IF(I18=J18,"Pass","Fail") -> Pass | H18: =IF(AND(ISBLANK(D18),F18>=0),"Pass",IF(F18<=D18,"Pass","Fail")) -> Pass | I18: =SUBSTITUTE(B18,"_","") -> metricType | J18: =SUBSTITUTE(E18,"_","") -> metricType
B19: metric_name | C19: varchar | D19: 50 | E19: metric_name | F19: 15 | G19: =IF(I19=J19,"Pass","Fail") -> Pass | H19: =IF(AND(ISBLANK(D19),F19>=0),"Pass",IF(F19<=D19,"Pass","Fail")) -> Pass | I19: =SUBSTITUTE(B19,"_","") -> metricname | J19: =SUBSTITUTE(E19,"_","") -> metricname

Sheet Demographics
B1: Client layout | C1: Data Type | D1: Client Length | E1: Extract Layout | F1: Extract Length | G1: Layout Result | H1: Length Result | L1: Current Extract Count | M1: Previous Extract Count | N1: Difference | O1: Fail
B2: dw_record_id | C2: varchar | E2: dw_record_id | F2: 5 | G2: =IF(I2=J2,"Pass","Fail") -> Pass | H2: =IF(AND(ISBLANK(D2),F2>=0),"Pass",IF(F2<=D2,"Pass","Fail")) -> Pass | I2: =SUBSTITUTE(B2,"_","") -> dwrecordid | J2: =SUBSTITUTE(E2,"_","") -> dwrecordid | L2: 12801 | M2: 6169 | N2: =L2-M2 -> 6632
B3: dw_account_id | C3: varchar | D3: 10 | E3: dw_account_id | F3: 0 | G3: =IF(I3=J3,"Pass","Fail") -> Pass | H3: =IF(AND(ISBLANK(D3),F3>=0),"Pass",IF(F3<=D3,"Pass","Fail")) -> Pass | I3: =SUBSTITUTE(B3,"_","") -> dwaccountid | J3: =SUBSTITUTE(E3,"_","") -> dwaccountid
B4: dw_client_id | C4: varchar | D4: 10 | E4: dw_client_id | F4: 8 | G4: =IF(I4=J4,"Pass","Fail") -> Pass | H4: =IF(AND(ISBLANK(D4),F4>=0),"Pass",IF(F4<=D4,"Pass","Fail")) -> Pass | I4: =SUBSTITUTE(B4,"_","") -> dwclientid | J4: =SUBSTITUTE(E4,"_","") -> dwclientid | L4: Overall | M4: Result
B5: dw_member_id | C5: varchar | D5: 50 | E5: dw_member_id | F5: 32 | G5: =IF(I5=J5,"Pass","Fail") -> Pass | H5: =IF(AND(ISBLANK(D5),F5>=0),"Pass",IF(F5<=D5,"Pass","Fail")) -> Pass | I5: =SUBSTITUTE(B5,"_","") -> dwmemberid | J5: =SUBSTITUTE(E5,"_","") -> dwmemberid | L5: Layout Result | M5: =IF(ISERROR(VLOOKUP($O$1,$G$2:$G$27,1,)),"Pass","Fail") -> Pass
B6: mbr_id | C6: varchar | D6: 32 | E6: mbr_id | F6: 32 | G6: =IF(I6=J6,"Pass","Fail") -> Pass | H6: =IF(AND(ISBLANK(D6),F6>=0),"Pass",IF(F6<=D6,"Pass","Fail")) -> Pass | I6: =SUBSTITUTE(B6,"_","") -> mbrid | J6: =SUBSTITUTE(E6,"_","") -> mbrid | L6: Field Length Result | M6: =IF(ISERROR(VLOOKUP($O$1,$H$2:$H$27,1,)),"Pass","Fail") -> Pass
B7: mbr_ssn | C7: varchar | D7: 22 | E7: mbr_ssn | F7: 22 | G7: =IF(I7=J7,"Pass","Fail") -> Pass | H7: =IF(AND(ISBLANK(D7),F7>=0),"Pass",IF(F7<=D7,"Pass","Fail")) -> Pass | I7: =SUBSTITUTE(B7,"_","") -> mbrssn | J7: =SUBSTITUTE(E7,"_","") -> mbrssn | L7: % change in count with respect to previous count | M7: =IF(M2=0,0%,N2/M2) -> 1.0750527
B8: mbr_first_name | C8: varchar | D8: 100 | E8: mbr_first_name | F8: 15 | G8: =IF(I8=J8,"Pass","Fail") -> Pass | H8: =IF(AND(ISBLANK(D8),F8>=0),"Pass",IF(F8<=D8,"Pass","Fail")) -> Pass | I8: =SUBSTITUTE(B8,"_","") -> mbrfirstname | J8: =SUBSTITUTE(E8,"_","") -> mbrfirstname | L8: % change in file size with respect to previous file | M8: =File_Size_Comparision!F4 -> 0.51234568
B9: mbr_middle_name | C9: varchar | D9: 100 | E9: mbr_middle_name | F9: 1 | G9: =IF(I9=J9,"Pass","Fail") -> Pass | H9: =IF(AND(ISBLANK(D9),F9>=0),"Pass",IF(F9<=D9,"Pass","Fail")) -> Pass | I9: =SUBSTITUTE(B9,"_","") -> mbrmiddlename | J9: =SUBSTITUTE(E9,"_","") -> mbrmiddlename
B10: mbr_last_name | C10: date | D10: 100 | E10: mbr_last_name | F10: 26 | G10: =IF(I10=J10,"Pass","Fail") -> Pass | H10: =IF(AND(ISBLANK(D10),F10>=0),"Pass",IF(F10<=D10,"Pass","Fail")) -> Pass | I10: =SUBSTITUTE(B10,"_","") -> mbrlastname | J10: =SUBSTITUTE(E10,"_","") -> mbrlastname
B11: mbr_current_status | C11: varchar | D11: 10 | E11: mbr_current_status | F11: 6 | G11: =IF(I11=J11,"Pass","Fail") -> Pass | H11: =IF(AND(ISBLANK(D11),F11>=0),"Pass",IF(F11<=D11,"Pass","Fail")) -> Pass | I11: =SUBSTITUTE(B11,"_","") -> mbrcurrentstatus | J11: =SUBSTITUTE(E11,"_","") -> mbrcurrentstatus
B12: mbr_gender | C12: varchar | D12: 10 | E12: mbr_gender | F12: 1 | G12: =IF(I12=J12,"Pass","Fail") -> Pass | H12: =IF(AND(ISBLANK(D12),F12>=0),"Pass",IF(F12<=D12,"Pass","Fail")) -> Pass | I12: =SUBSTITUTE(B12,"_","") -> mbrgender | J12: =SUBSTITUTE(E12,"_","") -> mbrgender
B13: mbr_dob | C13: varchar | E13: mbr_dob | F13: 10 | G13: =IF(I13=J13,"Pass","Fail") -> Pass | H13: =IF(AND(ISBLANK(D13),F13>=0),"Pass",IF(F13<=D13,"Pass","Fail")) -> Pass | I13: =SUBSTITUTE(B13,"_","") -> mbrdob | J13: =SUBSTITUTE(E13,"_","") -> mbrdob
B14: mbr_street_1 | C14: varchar | D14: 100 | E14: mbr_street_1 | F14: 30 | G14: =IF(I14=J14,"Pass","Fail") -> Pass | H14: =IF(AND(ISBLANK(D14),F14>=0),"Pass",IF(F14<=D14,"Pass","Fail")) -> Pass | I14: =SUBSTITUTE(B14,"_","") -> mbrstreet1 | J14: =SUBSTITUTE(E14,"_","") -> mbrstreet1
B15: mbr_street_2 | C15: varchar | D15: 100 | E15: mbr_street_2 | F15: 22 | G15: =IF(I15=J15,"Pass","Fail") -> Pass | H15: =IF(AND(ISBLANK(D15),F15>=0),"Pass",IF(F15<=D15,"Pass","Fail")) -> Pass | I15: =SUBSTITUTE(B15,"_","") -> mbrstreet2 | J15: =SUBSTITUTE(E15,"_","") -> mbrstreet2
B16: mbr_city | C16: varchar | D16: 100 | E16: mbr_city | F16: 20 | G16: =IF(I16=J16,"Pass","Fail") -> Pass | H16: =IF(AND(ISBLANK(D16),F16>=0),"Pass",IF(F16<=D16,"Pass","Fail")) -> Pass | I16: =SUBSTITUTE(B16,"_","") -> mbrcity | J16: =SUBSTITUTE(E16,"_","") -> mbrcity
B17: mbr_county | C17: varchar | D17: 100 | E17: mbr_county | F17: 5 | G17: =IF(I17=J17,"Pass","Fail") -> Pass | H17: =IF(AND(ISBLANK(D17),F17>=0),"Pass",IF(F17<=D17,"Pass","Fail")) -> Pass | I17: =SUBSTITUTE(B17,"_","") -> mbrcounty | J17: =SUBSTITUTE(E17,"_","") -> mbrcounty
B18: mbr_state | C18: varchar | D18: 100 | E18: mbr_state | F18: 2 | G18: =IF(I18=J18,"Pass","Fail") -> Pass | H18: =IF(AND(ISBLANK(D18),F18>=0),"Pass",IF(F18<=D18,"Pass","Fail")) -> Pass | I18: =SUBSTITUTE(B18,"_","") -> mbrstate | J18: =SUBSTITUTE(E18,"_","") -> mbrstate
B19: mbr_zip | C19: varchar | D19: 100 | E19: mbr_zip | F19: 5 | G19: =IF(I19=J19,"Pass","Fail") -> Pass | H19: =IF(AND(ISBLANK(D19),F19>=0),"Pass",IF(F19<=D19,"Pass","Fail")) -> Pass | I19: =SUBSTITUTE(B19,"_","") -> mbrzip | J19: =SUBSTITUTE(E19,"_","") -> mbrzip
B20: mbr_phone | C20: varchar | D20: 100 | E20: mbr_phone | F20: 12 | G20: =IF(I20=J20,"Pass","Fail") -> Pass | H20: =IF(AND(ISBLANK(D20),F20>=0),"Pass",IF(F20<=D20,"Pass","Fail")) -> Pass | I20: =SUBSTITUTE(B20,"_","") -> mbrphone | J20: =SUBSTITUTE(E20,"_","") -> mbrphone
B21: mbr_region_code | C21: varchar | D21: 100 | E21: mbr_region_code | F21: 0 | G21: =IF(I21=J21,"Pass","Fail") -> Pass | H21: =IF(AND(ISBLANK(D21),F21>=0),"Pass",IF(F21<=D21,"Pass","Fail")) -> Pass | I21: =SUBSTITUTE(B21,"_","") -> mbrregioncode | J21: =SUBSTITUTE(E21,"_","") -> mbrregioncode
B22: mbr_region_name | C22: varchar | D22: 100 | E22: mbr_region_name | F22: 0 | G22: =IF(I22=J22,"Pass","Fail") -> Pass | H22: =IF(AND(ISBLANK(D22),F22>=0),"Pass",IF(F22<=D22,"Pass","Fail")) -> Pass | I22: =SUBSTITUTE(B22,"_","") -> mbrregionname | J22: =SUBSTITUTE(E22,"_","") -> mbrregionname
B23: mbr_relationship_code | C23: varchar | D23: 10 | E23: mbr_relationship_code | F23: 3 | G23: =IF(I23=J23,"Pass","Fail") -> Pass | H23: =IF(AND(ISBLANK(D23),F23>=0),"Pass",IF(F23<=D23,"Pass","Fail")) -> Pass | I23: =SUBSTITUTE(B23,"_","") -> mbrrelationshipcode | J23: =SUBSTITUTE(E23,"_","") -> mbrrelationshipcode
B24: mbr_relationship_desc | C24: varchar | D24: 50 | E24: mbr_relationship_desc | F24: 42 | G24: =IF(I24=J24,"Pass","Fail") -> Pass | H24: =IF(AND(ISBLANK(D24),F24>=0),"Pass",IF(F24<=D24,"Pass","Fail")) -> Pass | I24: =SUBSTITUTE(B24,"_","") -> mbrrelationshipdesc | J24: =SUBSTITUTE(E24,"_","") -> mbrrelationshipdesc
B25: dw_rawfilename | C25: varchar | D25: 100 | E25: dw_rawfilename | F25: 85 | G25: =IF(I25=J25,"Pass","Fail") -> Pass | H25: =IF(AND(ISBLANK(D25),F25>=0),"Pass",IF(F25<=D25,"Pass","Fail")) -> Pass | I25: =SUBSTITUTE(B25,"_","") -> dwrawfilename | J25: =SUBSTITUTE(E25,"_","") -> dwrawfilename
... B27: dw_vendor_name | C27: varchar | D27: 100 | E27: dw_vendor_name | F27: 8 | G27: =IF(I27=J27,"Pass","Fail") -> Pass | H27: =IF(AND(ISBLANK(D27),F27>=0),"Pass",IF(F27<=D27,"Pass","Fail")) -> Pass | I27: =SUBSTITUTE(B27,"_","") -> dwvendorname | J27: =SUBSTITUTE(E27,"_","") -> dwvendorname

Sheet Eligibility
B1: Client layout | C1: Data Type | D1: Client Length | E1: Extract Layout | F1: Extract Length | G1: Layout Result | H1: Length Result | L1: Extract Total Count | M1: Application Total Count | N1: Difference | O1: Fail
B2: mbr_id | C2: varchar | D2: 32 | E2: mbr_id | F2: 32 | G2: =IF(I2=J2,"Pass","Fail") -> Pass | H2: =IF(AND(ISBLANK(D2),F2>=0),"Pass",IF(F2<=D2,"Pass","Fail")) -> Pass | I2: =SUBSTITUTE(B2,"_","") -> mbrid | J2: =SUBSTITUTE(E2,"_","") -> mbrid | L2: 207601 | M2: 207601 | N2: =L2-M2 -> 0
B3: ins_policy_id | C3: varchar | D3: 20 | E3: ins_policy_id | F3: 0 | G3: =IF(I3=J3,"Pass","Fail") -> Pass | H3: =IF(AND(ISBLANK(D3),F3>=0),"Pass",IF(F3<=D3,"Pass","Fail")) -> Pass | I3: =SUBSTITUTE(B3,"_","") -> inspolicyid | J3: =SUBSTITUTE(E3,"_","") -> inspolicyid | L3: Prior Count | M3: 163833 | N3: =L2-M3 -> 43768
B4: mbr_ssn | C4: varchar | D4: 22 | E4: mbr_ssn | F4: 22 | G4: =IF(I4=J4,"Pass","Fail") -> Pass | H4: =IF(AND(ISBLANK(D4),F4>=0),"Pass",IF(F4<=D4,"Pass","Fail")) -> Pass | I4: =SUBSTITUTE(B4,"_","") -> mbrssn | J4: =SUBSTITUTE(E4,"_","") -> mbrssn
B5: mbr_first_name | C5: varchar | D5: 30 | E5: mbr_first_name | F5: 15 | G5: =IF(I5=J5,"Pass","Fail") -> Pass | H5: =IF(AND(ISBLANK(D5),F5>=0),"Pass",IF(F5<=D5,"Pass","Fail")) -> Pass | I5: =SUBSTITUTE(B5,"_","") -> mbrfirstname | J5: =SUBSTITUTE(E5,"_","") -> mbrfirstname | L5: Overall | M5: Result
B6: mbr_middle_name | C6: varchar | D6: 30 | E6: mbr_middle_name | F6: 1 | G6: =IF(I6=J6,"Pass","Fail") -> Pass | H6: =IF(AND(ISBLANK(D6),F6>=0),"Pass",IF(F6<=D6,"Pass","Fail")) -> Pass | I6: =SUBSTITUTE(B6,"_","") -> mbrmiddlename | J6: =SUBSTITUTE(E6,"_","") -> mbrmiddlename | L6: Layout Result | M6: =IF(ISERROR(VLOOKUP($O$1,$G$2:$G$94,1,)),"Pass","Fail") -> Pass
B7: mbr_last_name | C7: varchar | D7: 30 | E7: mbr_last_name | F7: 26 | G7: =IF(I7=J7,"Pass","Fail") -> Pass | H7: =IF(AND(ISBLANK(D7),F7>=0),"Pass",IF(F7<=D7,"Pass","Fail")) -> Pass | I7: =SUBSTITUTE(B7,"_","") -> mbrlastname | J7: =SUBSTITUTE(E7,"_","") -> mbrlastname | L7: Field Length Result | M7: =IF(ISERROR(VLOOKUP($O$1,$H$2:$H$94,1,)),"Pass","Fail") -> Pass
B8: mbr_current_status | C8: varchar | D8: 20 | E8: mbr_current_status | F8: 6 | G8: =IF(I8=J8,"Pass","Fail") -> Pass | H8: =IF(AND(ISBLANK(D8),F8>=0),"Pass",IF(F8<=D8,"Pass","Fail")) -> Pass | I8: =SUBSTITUTE(B8,"_","") -> mbrcurrentstatus | J8: =SUBSTITUTE(E8,"_","") -> mbrcurrentstatus | L8: Count Result | M8: =IF(N2=0,"Pass","Fail") -> Pass
B9: mbr_gender | C9: varchar | D9: 2 | E9: mbr_gender | F9: 1 | G9: =IF(I9=J9,"Pass","Fail") -> Pass | H9: =IF(AND(ISBLANK(D9),F9>=0),"Pass",IF(F9<=D9,"Pass","Fail")) -> Pass | I9: =SUBSTITUTE(B9,"_","") -> mbrgender | J9: =SUBSTITUTE(E9,"_","") -> mbrgender | L9: % change in count with respect to previous count | M9: =IF(M3=0,0%,N3/M3) -> 0.26715009
B10: mbr_dob | C10: date | E10: mbr_dob | F10: 10 | G10: =IF(I10=J10,"Pass","Fail") -> Pass | H10: =IF(AND(ISBLANK(D10),F10>=0),"Pass",IF(F10<=D10,"Pass","Fail")) -> Pass | I10: =SUBSTITUTE(B10,"_","") -> mbrdob | J10: =SUBSTITUTE(E10,"_","") -> mbrdob | L10: % change in file size with respect to previous file | M10: =File_Size_Comparision!F5 -> 0.22209676
B11: mbr_street_1 | C11: varchar | D11: 50 | E11: mbr_street_1 | F11: 30 | G11: =IF(I11=J11,"Pass","Fail") -> Pass | H11: =IF(AND(ISBLANK(D11),F11>=0),"Pass",IF(F11<=D11,"Pass","Fail")) -> Pass | I11: =SUBSTITUTE(B11,"_","") -> mbrstreet1 | J11: =SUBSTITUTE(E11,"_","") -> mbrstreet1
B12: mbr_street_2 | C12: varchar | D12: 50 | E12: mbr_street_2 | F12: 22 | G12: =IF(I12=J12,"Pass","Fail") -> Pass | H12: =IF(AND(ISBLANK(D12),F12>=0),"Pass",IF(F12<=D12,"Pass","Fail")) -> Pass | I12: =SUBSTITUTE(B12,"_","") -> mbrstreet2 | J12: =SUBSTITUTE(E12,"_","") -> mbrstreet2
B13: mbr_city | C13: varchar | D13: 100 | E13: mbr_city | F13: 20 | G13: =IF(I13=J13,"Pass","Fail") -> Pass | H13: =IF(AND(ISBLANK(D13),F13>=0),"Pass",IF(F13<=D13,"Pass","Fail")) -> Pass | I13: =SUBSTITUTE(B13,"_","") -> mbrcity | J13: =SUBSTITUTE(E13,"_","") -> mbrcity
B14: mbr_county | C14: varchar | D14: 20 | E14: mbr_county | F14: 5 | G14: =IF(I14=J14,"Pass","Fail") -> Pass | H14: =IF(AND(ISBLANK(D14),F14>=0),"Pass",IF(F14<=D14,"Pass","Fail")) -> Pass | I14: =SUBSTITUTE(B14,"_","") -> mbrcounty | J14: =SUBSTITUTE(E14,"_","") -> mbrcounty
B15: mbr_state | C15: varchar | D15: 2 | E15: mbr_state | F15: 2 | G15: =IF(I15=J15,"Pass","Fail") -> Pass | H15: =IF(AND(ISBLANK(D15),F15>=0),"Pass",IF(F15<=D15,"Pass","Fail")) -> Pass | I15: =SUBSTITUTE(B15,"_","") -> mbrstate | J15: =SUBSTITUTE(E15,"_","") -> mbrstate
B16: mbr_zip | C16: varchar | D16: 12 | E16: mbr_zip | F16: 5 | G16: =IF(I16=J16,"Pass","Fail") -> Pass | H16: =IF(AND(ISBLANK(D16),F16>=0),"Pass",IF(F16<=D16,"Pass","Fail")) -> Pass | I16: =SUBSTITUTE(B16,"_","") -> mbrzip | J16: =SUBSTITUTE(E16,"_","") -> mbrzip
B17: mbr_phone | C17: varchar | D17: 15 | E17: mbr_phone | F17: 12 | G17: =IF(I17=J17,"Pass","Fail") -> Pass | H17: =IF(AND(ISBLANK(D17),F17>=0),"Pass",IF(F17<=D17,"Pass","Fail")) -> Pass | I17: =SUBSTITUTE(B17,"_","") -> mbrphone | J17: =SUBSTITUTE(E17,"_","") -> mbrphone
B18: mbr_region_code | C18: varchar | D18: 32 | E18: mbr_region_code | F18: 0 | G18: =IF(I18=J18,"Pass","Fail") -> Pass | H18: =IF(AND(ISBLANK(D18),F18>=0),"Pass",IF(F18<=D18,"Pass","Fail")) -> Pass | I18: =SUBSTITUTE(B18,"_","") -> mbrregioncode | J18: =SUBSTITUTE(E18,"_","") -> mbrregioncode
B19: mbr_region_name | C19: varchar | D19: 50 | E19: mbr_region_name | F19: 0 | G19: =IF(I19=J19,"Pass","Fail") -> Pass | H19: =IF(AND(ISBLANK(D19),F19>=0),"Pass",IF(F19<=D19,"Pass","Fail")) -> Pass | I19: =SUBSTITUTE(B19,"_","") -> mbrregionname | J19: =SUBSTITUTE(E19,"_","") -> mbrregionname
B20: mbr_relationship_code | C20: varchar | D20: 5 | E20: mbr_relationship_code | F20: 3 | G20: =IF(I20=J20,"Pass","Fail") -> Pass | H20: =IF(AND(ISBLANK(D20),F20>=0),"Pass",IF(F20<=D20,"Pass","Fail")) -> Pass | I20: =SUBSTITUTE(B20,"_","") -> mbrrelationshipcode | J20: =SUBSTITUTE(E20,"_","") -> mbrrelationshipcode
B21: mbr_relationship_desc | C21: varchar | D21: 42 | E21: mbr_relationship_desc | F21: 42 | G21: =IF(I21=J21,"Pass","Fail") -> Pass | H21: =IF(AND(ISBLANK(D21),F21>=0),"Pass",IF(F21<=D21,"Pass","Fail")) -> Pass | I21: =SUBSTITUTE(B21,"_","") -> mbrrelationshipdesc | J21: =SUBSTITUTE(E21,"_","") -> mbrrelationshipdesc
B22: ins_plan_type_code | C22: varchar | D22: 20 | E22: ins_plan_type_code | F22: 20 | G22: =IF(I22=J22,"Pass","Fail") -> Pass | H22: =IF(AND(ISBLANK(D22),F22>=0),"Pass",IF(F22<=D22,"Pass","Fail")) -> Pass | I22: =SUBSTITUTE(B22,"_","") -> insplantypecode | J22: =SUBSTITUTE(E22,"_","") -> insplantypecode
... B35: ins_cobra_desc | C35: varchar | D35: 30 | E35: ins_cobra_desc | F35: 0 | G35: =IF(I35=J35,"Pass","Fail") -> Pass | H35: =IF(AND(ISBLANK(D35),F35>=0),"Pass",IF(F35<=D35,"Pass","Fail")) -> Pass | I35: =SUBSTITUTE(B35,"_","") -> inscobradesc | J35: =SUBSTITUTE(E35,"_","") -> inscobradesc
B36: ins_med_eff_date | C36: date | E36: ins_med_eff_date | F36: 10 | G36: =IF(I36=J36,"Pass","Fail") -> Pass | H36: =IF(AND(ISBLANK(D36),F36>=0),"Pass",IF(F36<=D36,"Pass","Fail")) -> Pass | I36: =SUBSTITUTE(B36,"_","") -> insmedeffdate | J36: =SUBSTITUTE(E36,"_","") -> insmedeffdate
B37: ins_med_term_date | C37: date | E37: ins_med_term_date | F37: 10 | G37: =IF(I37=J37,"Pass","Fail") -> Pass | H37: =IF(AND(ISBLANK(D37),F37>=0),"Pass",IF(F37<=D37,"Pass","Fail")) -> Pass | I37: =SUBSTITUTE(B37,"_","") -> insmedtermdate | J37: =SUBSTITUTE(E37,"_","") -> insmedtermdate
B38: ins_rx_eff_date | C38: date | E38: ins_rx_eff_date | F38: 0 | G38: =IF(I38=J38,"Pass","Fail") -> Pass | H38: =IF(AND(ISBLANK(D38),F38>=0),"Pass",IF(F38<=D38,"Pass","Fail")) -> Pass | I38: =SUBSTITUTE(B38,"_","") -> insrxeffdate | J38: =SUBSTITUTE(E38,"_","") -> insrxeffdate
B39: ins_rx_term_date | C39: date | E39: ins_rx_term_date | F39: 0 | G39: =IF(I39=J39,"Pass","Fail") -> Pass | H39: =IF(AND(ISBLANK(D39),F39>=0),"Pass",IF(F39<=D39,"Pass","Fail")) -> Pass | I39: =SUBSTITUTE(B39,"_","") -> insrxtermdate | J39: =SUBSTITUTE(E39,"_","") -> insrxtermdate
B40: ins_den_eff_date | C40: date | E40: ins_den_eff_date | F40: 0 | G40: =IF(I40=J40,"Pass","Fail") -> Pass | H40: =IF(AND(ISBLANK(D40),F40>=0),"Pass",IF(F40<=D40,"Pass","Fail")) -> Pass | I40: =SUBSTITUTE(B40,"_","") -> insdeneffdate | J40: =SUBSTITUTE(E40,"_","") -> insdeneffdate
B41: ins_den_term_date | C41: date | E41: ins_den_term_date | F41: 0 | G41: =IF(I41=J41,"Pass","Fail") -> Pass | H41: =IF(AND(ISBLANK(D41),F41>=0),"Pass",IF(F41<=D41,"Pass","Fail")) -> Pass | I41: =SUBSTITUTE(B41,"_","") -> insdentermdate | J41: =SUBSTITUTE(E41,"_","") -> insdentermdate
B42: ins_vis_eff_date | C42: date | E42: ins_vis_eff_date | F42: 0 | G42: =IF(I42=J42,"Pass","Fail") -> Pass | H42: =IF(AND(ISBLANK(D42),F42>=0),"Pass",IF(F42<=D42,"Pass","Fail")) -> Pass | I42: =SUBSTITUTE(B42,"_","") -> insviseffdate | J42: =SUBSTITUTE(E42,"_","") -> insviseffdate
B43: ins_vis_term_date | C43: date | E43: ins_vis_term_date | F43: 0 | G43: =IF(I43=J43,"Pass","Fail") -> Pass | H43: =IF(AND(ISBLANK(D43),F43>=0),"Pass",IF(F43<=D43,"Pass","Fail")) -> Pass | I43: =SUBSTITUTE(B43,"_","") -> insvistermdate | J43: =SUBSTITUTE(E43,"_","") -> insvistermdate
B44: ins_ltd_eff_date | C44: date | E44: ins_ltd_eff_date | F44: 0 | G44: =IF(I44=J44,"Pass","Fail") -> Pass | H44: =IF(AND(ISBLANK(D44),F44>=0),"Pass",IF(F44<=D44,"Pass","Fail")) -> Pass | I44: =SUBSTITUTE(B44,"_","") -> insltdeffdate | J44: =SUBSTITUTE(E44,"_","") -> insltdeffdate
B45: ins_ltd_term_date | C45: date | E45: ins_ltd_term_date | F45: 0 | G45: =IF(I45=J45,"Pass","Fail") -> Pass | H45: =IF(AND(ISBLANK(D45),F45>=0),"Pass",IF(F45<=D45,"Pass","Fail")) -> Pass | I45: =SUBSTITUTE(B45,"_","") -> insltdtermdate | J45: =SUBSTITUTE(E45,"_","") -> insltdtermdate
B46: ins_std_eff_date | C46: date | E46: ins_std_eff_date | F46: 0 | G46: =IF(I46=J46,"Pass","Fail") -> Pass | H46: =IF(AND(ISBLANK(D46),F46>=0),"Pass",IF(F46<=D46,"Pass","Fail")) -> Pass | I46: =SUBSTITUTE(B46,"_","") -> insstdeffdate | J46: =SUBSTITUTE(E46,"_","") -> insstdeffdate
B47: ins_std_term_date | C47: date | E47: ins_std_term_date | F47: 0 | G47: =IF(I47=J47,"Pass","Fail") -> Pass | H47: =IF(AND(ISBLANK(D47),F47>=0),"Pass",IF(F47<=D47,"Pass","Fail")) -> Pass | I47: =SUBSTITUTE(B47,"_","") -> insstdtermdate | J47: =SUBSTITUTE(E47,"_","") -> insstdtermdate
B48: prv_pcp_id | C48: varchar | D48: 50 | E48: prv_pcp_id | F48: 10 | G48: =IF(I48=J48,"Pass","Fail") -> Pass | H48: =IF(AND(ISBLANK(D48),F48>=0),"Pass",IF(F48<=D48,"Pass","Fail")) -> Pass | I48: =SUBSTITUTE(B48,"_","") -> prvpcpid | J48: =SUBSTITUTE(E48,"_","") -> prvpcpid
B49: prv_pcp_first_name | C49: varchar | D49: 100 | E49: prv_pcp_first_name | F49: 65 | G49: =IF(I49=J49,"Pass","Fail") -> Pass | H49: =IF(AND(ISBLANK(D49),F49>=0),"Pass",IF(F49<=D49,"Pass","Fail")) -> Pass | I49: =SUBSTITUTE(B49,"_","") -> prvpcpfirstname | J49: =SUBSTITUTE(E49,"_","") -> prvpcpfirstname
B50: prv_pcp_middle_name | C50: varchar | D50: 30 | E50: prv_pcp_middle_name | F50: 16 | G50: =IF(I50=J50,"Pass","Fail") -> Pass | H50: =IF(AND(ISBLANK(D50),F50>=0),"Pass",IF(F50<=D50,"Pass","Fail")) -> Pass | I50: =SUBSTITUTE(B50,"_","") -> prvpcpmiddlename | J50: =SUBSTITUTE(E50,"_","") -> prvpcpmiddlename
B51: prv_pcp_last_name | C51: varchar | D51: 30 | E51: prv_pcp_last_name | F51: 20 | G51: =IF(I51=J51,"Pass","Fail") -> Pass | H51: =IF(AND(ISBLANK(D51),F51>=0),"Pass",IF(F51<=D51,"Pass","Fail")) -> Pass | I51: =SUBSTITUTE(B51,"_","") -> prvpcplastname | J51: =SUBSTITUTE(E51,"_","") -> prvpcplastname
B52: prv_pcp_site_id | C52: varchar | D52: 15 | E52: prv_pcp_site_id | F52: 0 | G52: =IF(I52=J52,"Pass","Fail") -> Pass | H52: =IF(AND(ISBLANK(D52),F52>=0),"Pass",IF(F52<=D52,"Pass","Fail")) -> Pass | I52: =SUBSTITUTE(B52,"_","") -> prvpcpsiteid | J52: =SUBSTITUTE(E52,"_","") -> prvpcpsiteid
...

Sheet High_Cost
B1: Client layout | C1: Data Type | D1: Client Length | E1: Extract Layout | F1: Extract Length | G1: Layout Result | H1: Length Result | L1: Current Extract Count | M1: Previous Extract Count | N1: Difference | O1: Fail
B2: dw_record_id | C2: varchar | E2: dw_record_id | F2: 5 | G2: =IF(I2=J2,"Pass","Fail") -> Pass | H2: =IF(AND(ISBLANK(D2),F2>=0),"Pass",IF(F2<=D2,"Pass","Fail")) -> Pass | I2: =SUBSTITUTE(B2,"_","") -> dwrecordid | J2: =SUBSTITUTE(E2,"_","") -> dwrecordid | L2: 12801 | M2: 6169 | N2: =L2-M2 -> 6632
B3: dw_account_id | C3: varchar | D3: 50 | E3: dw_account_id | F3: 8 | G3: =IF(I3=J3,"Pass","Fail") -> Pass | H3: =IF(AND(ISBLANK(D3),F3>=0),"Pass",IF(F3<=D3,"Pass","Fail")) -> Pass | I3: =SUBSTITUTE(B3,"_","") -> dwaccountid | J3: =SUBSTITUTE(E3,"_","") -> dwaccountid
B4: dw_client_id | C4: varchar | D4: 50 | E4: dw_client_id | F4: 8 | G4: =IF(I4=J4,"Pass","Fail") -> Pass | H4: =IF(AND(ISBLANK(D4),F4>=0),"Pass",IF(F4<=D4,"Pass","Fail")) -> Pass | I4: =SUBSTITUTE(B4,"_","") -> dwclientid | J4: =SUBSTITUTE(E4,"_","") -> dwclientid | L4: Overall | M4: Result
B5: dw_member_id | C5: varchar | D5: 50 | E5: dw_member_id | F5: 32 | G5: =IF(I5=J5,"Pass","Fail") -> Pass | H5: =IF(AND(ISBLANK(D5),F5>=0),"Pass",IF(F5<=D5,"Pass","Fail")) -> Pass | I5: =SUBSTITUTE(B5,"_","") -> dwmemberid | J5: =SUBSTITUTE(E5,"_","") -> dwmemberid | L5: Layout Result | M5: =IF(ISERROR(VLOOKUP($O$1,$G$2:$G$10,1,)),"Pass","Fail") -> Pass
B6: mbr_id | C6: varchar | D6: 32 | E6: mbr_id | F6: 32 | G6: =IF(I6=J6,"Pass","Fail") -> Pass | H6: =IF(AND(ISBLANK(D6),F6>=0),"Pass",IF(F6<=D6,"Pass","Fail")) -> Pass | I6: =SUBSTITUTE(B6,"_","") -> mbrid | J6: =SUBSTITUTE(E6,"_","") -> mbrid | L6: Field Length Result | M6: =IF(ISERROR(VLOOKUP($O$1,$H$2:$H$10,1,)),"Pass","Fail") -> Pass
B7: Diagnosis_code | C7: varchar | D7: 10 | E7: diagnosis_code | F7: 8 | G7: =IF(I7=J7,"Pass","Fail") -> Pass | H7: =IF(AND(ISBLANK(D7),F7>=0),"Pass",IF(F7<=D7,"Pass","Fail")) -> Pass | I7: =SUBSTITUTE(B7,"_","") -> Diagnosiscode | J7: =SUBSTITUTE(E7,"_","") -> diagnosiscode | L7: % change in count with respect to previous count | M7: =IF(M2=0,0%,N2/M2) -> 1.0750527
B8: Paid_Amount | C8: varchar | D8: 50 | E8: paid_amount | F8: 19 | G8: =IF(I8=J8,"Pass","Fail") -> Pass | H8: =IF(AND(ISBLANK(D8),F8>=0),"Pass",IF(F8<=D8,"Pass","Fail")) -> Pass | I8: =SUBSTITUTE(B8,"_","") -> PaidAmount | J8: =SUBSTITUTE(E8,"_","") -> paidamount | L8: % change in file size with respect to previous file | M8: =File_Size_Comparision!F6 -> 0.54098371
B9: SuperGrouperDescription | C9: varchar | D9: 50 | E9: superGrouperDescription | F9: 29 | G9: =IF(I9=J9,"Pass","Fail") -> Pass | H9: =IF(AND(ISBLANK(D9),F9>=0),"Pass",IF(F9<=D9,"Pass","Fail")) -> Pass | I9: =SUBSTITUTE(B9,"_","") -> SuperGrouperDescription | J9: =SUBSTITUTE(E9,"_","") -> superGrouperDescription
B10: GrouperDescription | C10: date | D10: 50 | E10: grouperDescription | F10: 40 | G10: =IF(I10=J10,"Pass","Fail") -> Pass | H10: =IF(AND(ISBLANK(D10),F10>=0),"Pass",IF(F10<=D10,"Pass","Fail")) -> Pass | I10: =SUBSTITUTE(B10,"_","") -> GrouperDescription | J10: =SUBSTITUTE(E10,"_","") -> grouperDescription

Sheet Historical_Scores
B1: Client layout | C1: Data Type | D1: Client Length | E1: Extract Layout | F1: Extract Length | G1: Layout Result | H1: Length Result
B2: dw_record_id | C2: int | E2: dw_record_id | F2: 5 | G2: =IF(I2=J2,"Pass","Fail") -> Pass | H2: =IF(AND(ISBLANK(D2),F2>=0),"Pass",IF(F2<=D2,"Pass","Fail")) -> Pass | I2: =SUBSTITUTE(B2,"_","") -> dwrecordid | J2: =SUBSTITUTE(E2,"_","") -> dwrecordid | L2: Current Extract Count | M2: Previous Extract Count | N2: Difference
B3: dw_account_id | C3: varchar | D3: 50 | E3: dw_account_id | F3: 0 | G3: =IF(I3=J3,"Pass","Fail") -> Pass | H3: =IF(AND(ISBLANK(D3),F3>=0),"Pass",IF(F3<=D3,"Pass","Fail")) -> Pass | I3: =SUBSTITUTE(B3,"_","") -> dwaccountid | J3: =SUBSTITUTE(E3,"_","") -> dwaccountid | L3: 54330 | M3: 40992 | N3: =L3-M3 -> 13338
B4: dw_client_id | C4: varchar | D4: 50 | E4: dw_client_id | F4: 8 | G4: =IF(I4=J4,"Pass","Fail") -> Pass | H4: =IF(AND(ISBLANK(D4),F4>=0),"Pass",IF(F4<=D4,"Pass","Fail")) -> Pass | I4: =SUBSTITUTE(B4,"_","") -> dwclientid | J4: =SUBSTITUTE(E4,"_","") -> dwclientid
B5: dw_member_id | C5: varchar | D5: 50 | E5: dw_member_id | F5: 32 | G5: =IF(I5=J5,"Pass","Fail") -> Pass | H5: =IF(AND(ISBLANK(D5),F5>=0),"Pass",IF(F5<=D5,"Pass","Fail")) -> Pass | I5: =SUBSTITUTE(B5,"_","") -> dwmemberid | J5: =SUBSTITUTE(E5,"_","") -> dwmemberid | L5: Overall | M5: Result
B6: mbr_id | C6: varchar | D6: 25 | E6: mbr_id | F6: 25 | G6: =IF(I6=J6,"Pass","Fail") -> Pass | H6: =IF(AND(ISBLANK(D6),F6>=0),"Pass",IF(F6<=D6,"Pass","Fail")) -> Pass | I6: =SUBSTITUTE(B6,"_","") -> mbrid | J6: =SUBSTITUTE(E6,"_","") -> mbrid | L6: Layout Result | M6: =IF(ISERROR(VLOOKUP($O$1,$G$2:$G$26,1,)),"Pass","Fail") -> Pass
B7: score_type | C7: varchar | D7: 50 | E7: score_type | F7: 0 | G7: =IF(I7=J7,"Pass","Fail") -> Pass | H7: =IF(AND(ISBLANK(D7),F7>=0),"Pass",IF(F7<=D7,"Pass","Fail")) -> Pass | I7: =SUBSTITUTE(B7,"_","") -> scoretype | J7: =SUBSTITUTE(E7,"_","") -> scoretype | L7: Field Length Result | M7: =IF(ISERROR(VLOOKUP($O$1,$H$2:$H$26,1,)),"Pass","Fail") -> Pass
B8: score_start_date | C8: date | E8: score_start_date | F8: 10 | G8: =IF(I8=J8,"Pass","Fail") -> Pass | H8: =IF(AND(ISBLANK(D8),F8>=0),"Pass",IF(F8<=D8,"Pass","Fail")) -> Pass | I8: =SUBSTITUTE(B8,"_","") -> scorestartdate | J8: =SUBSTITUTE(E8,"_","") -> scorestartdate | L8: % change in count with respect to previous count | M8: =IF(M3=0,0%,N3/M3) -> 0.32538056
B9: score_end_date | C9: date | E9: score_end_date | F9: 10 | G9: =IF(I9=J9,"Pass","Fail") -> Pass | H9: =IF(AND(ISBLANK(D9),F9>=0),"Pass",IF(F9<=D9,"Pass","Fail")) -> Pass | I9: =SUBSTITUTE(B9,"_","") -> scoreenddate | J9: =SUBSTITUTE(E9,"_","") -> scoreenddate | L9: % change in file size with respect to previous file | M9: =File_Size_Comparision!F7 -> 0.24805339
B10: ip_score | C10: varchar | D10: 50 | E10: ip_score | F10: 5 | G10: =IF(I10=J10,"Pass","Fail") -> Pass | H10: =IF(AND(ISBLANK(D10),F10>=0),"Pass",IF(F10<=D10,"Pass","Fail")) -> Pass | I10: =SUBSTITUTE(B10,"_","") -> ipscore | J10: =SUBSTITUTE(E10,"_","") -> ipscore
B11: op_score | C11: varchar | D11: 50 | E11: op_score | F11: 5 | G11: =IF(I11=J11,"Pass","Fail") -> Pass | H11: =IF(AND(ISBLANK(D11),F11>=0),"Pass",IF(F11<=D11,"Pass","Fail")) -> Pass | I11: =SUBSTITUTE(B11,"_","") -> opscore | J11: =SUBSTITUTE(E11,"_","") -> opscore
B12: phy_score | C12: varchar | D12: 50 | E12: phy_score | F12: 4 | G12: =IF(I12=J12,"Pass","Fail") -> Pass | H12: =IF(AND(ISBLANK(D12),F12>=0),"Pass",IF(F12<=D12,"Pass","Fail")) -> Pass | I12: =SUBSTITUTE(B12,"_","") -> physcore | J12: =SUBSTITUTE(E12,"_","") -> physcore
B13: rx_score | C13: varchar | D13: 50 | E13: rx_score | F13: 5 | G13: =IF(I13=J13,"Pass","Fail") -> Pass | H13: =IF(AND(ISBLANK(D13),F13>=0),"Pass",IF(F13<=D13,"Pass","Fail")) -> Pass | I13: =SUBSTITUTE(B13,"_","") -> rxscore | J13: =SUBSTITUTE(E13,"_","") -> rxscore
B14: med_score | C14: varchar | D14: 50 | E14: med_score | F14: 5 | G14: =IF(I14=J14,"Pass","Fail") -> Pass | H14: =IF(AND(ISBLANK(D14),F14>=0),"Pass",IF(F14<=D14,"Pass","Fail")) -> Pass | I14: =SUBSTITUTE(B14,"_","") -> medscore | J14: =SUBSTITUTE(E14,"_","") -> medscore
B15: total_score | C15: varchar | D15: 50 | E15: total_score | F15: 5 | G15: =IF(I15=J15,"Pass","Fail") -> Pass | H15: =IF(AND(ISBLANK(D15),F15>=0),"Pass",IF(F15<=D15,"Pass","Fail")) -> Pass | I15: =SUBSTITUTE(B15,"_","") -> totalscore | J15: =SUBSTITUTE(E15,"_","") -> totalscore
B16: concurrent_total | C16: varchar | D16: 50 | E16: concurrent_total | F16: 5 | G16: =IF(I16=J16,"Pass","Fail") -> Pass | H16: =IF(AND(ISBLANK(D16),F16>=0),"Pass",IF(F16<=D16,"Pass","Fail")) -> Pass | I16: =SUBSTITUTE(B16,"_","") -> concurrenttotal | J16: =SUBSTITUTE(E16,"_","") -> concurrenttotal
B17: erScore | C17: varchar | D17: 50 | E17: erScore | F17: 4 | G17: =IF(I17=J17,"Pass","Fail") -> Pass | H17: =IF(AND(ISBLANK(D17),F17>=0),"Pass",IF(F17<=D17,"Pass","Fail")) -> Pass | I17: =SUBSTITUTE(B17,"_","") -> erScore | J17: =SUBSTITUTE(E17,"_","") -> erScore
B18: otherScore | C18: varchar | D18: 50 | E18: otherScore | F18: 4 | G18: =IF(I18=J18,"Pass","Fail") -> Pass | H18: =IF(AND(ISBLANK(D18),F18>=0),"Pass",IF(F18<=D18,"Pass","Fail")) -> Pass | I18: =SUBSTITUTE(B18,"_","") -> otherScore | J18: =SUBSTITUTE(E18,"_","") -> otherScore
B19: concurrentInpatient | C19: varchar | D19: 50 | E19: concurrentInpatient | F19: 5 | G19: =IF(I19=J19,"Pass","Fail") -> Pass | H19: =IF(AND(ISBLANK(D19),F19>=0),"Pass",IF(F19<=D19,"Pass","Fail")) -> Pass | I19: =SUBSTITUTE(B19,"_","") -> concurrentInpatient | J19: =SUBSTITUTE(E19,"_","") -> concurrentInpatient
B20: concurrentMedical | C20: varchar | D20: 50 | E20: concurrentMedical | F20: 5 | G20: =IF(I20=J20,"Pass","Fail") -> Pass | H20: =IF(AND(ISBLANK(D20),F20>=0),"Pass",IF(F20<=D20,"Pass","Fail")) -> Pass | I20: =SUBSTITUTE(B20,"_","") -> concurrentMedical | J20: =SUBSTITUTE(E20,"_","") -> concurrentMedical
B21: concurrentOutpatient | C21: varchar | D21: 50 | E21: concurrentOutpatient | F21: 5 | G21: =IF(I21=J21,"Pass","Fail") -> Pass | H21: =IF(AND(ISBLANK(D21),F21>=0),"Pass",IF(F21<=D21,"Pass","Fail")) -> Pass | I21: =SUBSTITUTE(B21,"_","") -> concurrentOutpatient | J21: =SUBSTITUTE(E21,"_","") -> concurrentOutpatient
... B26: concurrentPhyNormalizedToGroup | C26: varchar | D26: 50 | E26: concurrentPhyNormalizedToGroup | F26: 5 | G26: =IF(I26=J26,"Pass","Fail") -> Pass | H26: =IF(AND(ISBLANK(D26),F26>=0),"Pass",IF(F26<=D26,"Pass","Fail")) -> Pass | I26: =SUBSTITUTE(B26,"_","") -> concurrentPhyNormalizedToGroup | J26: =SUBSTITUTE(E26,"_","") -> concurrentPhyNormalizedToGroup

Sheet Medical_Claims
B1: Client layout | C1: Data Type | D1: Client Length | E1: Extract Layout | F1: Extract Length | G1: Layout Result | H1: Length Result | L1: Extract Total Count | M1: Application Total Count | N1: Difference | O1: Fail
B2: rev_claim_id | C2: varchar | D2: 42 | E2: rev_claim_id | F2: 42 | G2: =IF(I2=J2,"Pass","Fail") -> Pass | H2: =IF(AND(ISBLANK(D2),F2>=0),"Pass",IF(F2<=D2,"Pass","Fail")) -> Pass | I2: =SUBSTITUTE(B2,"_","") -> revclaimid | J2: =SUBSTITUTE(E2,"_","") -> revclaimid | L2: 610060 | M2: 610060 | N2: =L2-M2 -> 0
B3: rev_claim_line_id | C3: varchar | D3: 25 | E3: rev_claim_line_id | F3: 8 | G3: =IF(I3=J3,"Pass","Fail") -> Pass | H3: =IF(AND(ISBLANK(D3),F3>=0),"Pass",IF(F3<=D3,"Pass","Fail")) -> Pass | I3: =SUBSTITUTE(B3,"_","") -> revclaimlineid | J3: =SUBSTITUTE(E3,"_","") -> revclaimlineid | L3: Prior Count | M3: 299908 | N3: =L2-M3 -> 310152
B4: rev_claim_type | C4: varchar | D4: 15 | E4: rev_claim_type | F4: 4 | G4: =IF(I4=J4,"Pass","Fail") -> Pass | H4: =IF(AND(ISBLANK(D4),F4>=0),"Pass",IF(F4<=D4,"Pass","Fail")) -> Pass | I4: =SUBSTITUTE(B4,"_","") -> revclaimtype | J4: =SUBSTITUTE(E4,"_","") -> revclaimtype
B5: rev_claim_type_flag | C5: char | D5: 1 | E5: rev_claim_type_flag | F5: 0 | G5: =IF(I5=J5,"Pass","Fail") -> Pass | H5: =IF(AND(ISBLANK(D5),F5>=0),"Pass",IF(F5<=D5,"Pass","Fail")) -> Pass | I5: =SUBSTITUTE(B5,"_","") -> revclaimtypeflag | J5: =SUBSTITUTE(E5,"_","") -> revclaimtypeflag | L5: Overall | M5: Result
B6: ins_plan_type_code | C6: varchar | D6: 20 | E6: ins_plan_type_code | F6: 2 | G6: =IF(I6=J6,"Pass","Fail") -> Pass | H6: =IF(AND(ISBLANK(D6),F6>=0),"Pass",IF(F6<=D6,"Pass","Fail")) -> Pass | I6: =SUBSTITUTE(B6,"_","") -> insplantypecode | J6: =SUBSTITUTE(E6,"_","") -> insplantypecode | L6: Layout Result | M6: =IF(ISERROR(VLOOKUP($O$1,$G$2:$G$276,1,)),"Pass","Fail") -> Pass
B7: ins_plan_type_desc | C7: varchar | D7: 255 | E7: ins_plan_type_desc | F7: 5 | G7: =IF(I7=J7,"Pass","Fail") -> Pass | H7: =IF(AND(ISBLANK(D7),F7>=0),"Pass",IF(F7<=D7,"Pass","Fail")) -> Pass | I7: =SUBSTITUTE(B7,"_","") -> insplantypedesc | J7: =SUBSTITUTE(E7,"_","") -> insplantypedesc | L7: Field Length Result | M7: =IF(ISERROR(VLOOKUP($O$1,$H$2:$H$276,1,)),"Pass","Fail") -> Pass
B8: ins_carrier_id | C8: varchar | D8: 20 | E8: ins_carrier_id | F8: 13 | G8: =IF(I8=J8,"Pass","Fail") -> Pass | H8: =IF(AND(ISBLANK(D8),F8>=0),"Pass",IF(F8<=D8,"Pass","Fail")) -> Pass | I8: =SUBSTITUTE(B8,"_","") -> inscarrierid | J8: =SUBSTITUTE(E8,"_","") -> inscarrierid | L8: Count Result | M8: =IF(N2=0,"Pass","Fail") -> Pass
B9: ins_carrier_name | C9: varchar | D9: 50 | E9: ins_carrier_name | F9: 43 | G9: =IF(I9=J9,"Pass","Fail") -> Pass | H9: =IF(AND(ISBLANK(D9),F9>=0),"Pass",IF(F9<=D9,"Pass","Fail")) -> Pass | I9: =SUBSTITUTE(B9,"_","") -> inscarriername | J9: =SUBSTITUTE(E9,"_","") -> inscarriername | L9: % change in count with respect to previous count | M9: =IF(M3=0,0%,N3/M3) -> 1.0341571
B10: ins_coverage_type_code | C10: varchar | D10: 10 | E10: ins_coverage_type_code | F10: 2 | G10: =IF(I10=J10,"Pass","Fail") -> Pass | H10: =IF(AND(ISBLANK(D10),F10>=0),"Pass",IF(F10<=D10,"Pass","Fail")) -> Pass | I10: =SUBSTITUTE(B10,"_","") -> inscoveragetypecode | J10: =SUBSTITUTE(E10,"_","") -> inscoveragetypecode | L10: % change in file size with respect to previous file | M10: =File_Size_Comparision!F8 -> 0.57504246
B11: ins_coverage_type_desc | C11: varchar | D11: 50 | E11: ins_coverage_type_desc | F11: 5 | G11: =IF(I11=J11,"Pass","Fail") -> Pass | H11: =IF(AND(ISBLANK(D11),F11>=0),"Pass",IF(F11<=D11,"Pass","Fail")) -> Pass | I11: =SUBSTITUTE(B11,"_","") -> inscoveragetypedesc | J11: =SUBSTITUTE(E11,"_","") -> inscoveragetypedesc
B12: ins_plan_id | C12: varchar | D12: 66 | E12: ins_plan_id | F12: 66 | G12: =IF(I12=J12,"Pass","Fail") -> Pass | H12: =IF(AND(ISBLANK(D12),F12>=0),"Pass",IF(F12<=D12,"Pass","Fail")) -> Pass | I12: =SUBSTITUTE(B12,"_","") -> insplanid | J12: =SUBSTITUTE(E12,"_","") -> insplanid
B13: ins_emp_group_id | C13: varchar | D13: 20 | E13: ins_emp_group_id | F13: 15 | G13: =IF(I13=J13,"Pass","Fail") -> Pass | H13: =IF(AND(ISBLANK(D13),F13>=0),"Pass",IF(F13<=D13,"Pass","Fail")) -> Pass | I13: =SUBSTITUTE(B13,"_","") -> insempgroupid | J13: =SUBSTITUTE(E13,"_","") -> insempgroupid
B14: ins_emp_group_name | C14: varchar | D14: 50 | E14: ins_emp_group_name | F14: 15 | G14: =IF(I14=J14,"Pass","Fail") -> Pass | H14: =IF(AND(ISBLANK(D14),F14>=0),"Pass",IF(F14<=D14,"Pass","Fail")) -> Pass | I14: =SUBSTITUTE(B14,"_","") -> insempgroupname | J14: =SUBSTITUTE(E14,"_","") -> insempgroupname
B15: ins_division_id | C15: varchar | D15: 53 | E15: ins_division_id | F15: 53 | G15: =IF(I15=J15,"Pass","Fail") -> Pass | H15: =IF(AND(ISBLANK(D15),F15>=0),"Pass",IF(F15<=D15,"Pass","Fail")) -> Pass | I15: =SUBSTITUTE(B15,"_","") -> insdivisionid | J15: =SUBSTITUTE(E15,"_","") -> insdivisionid
B16: ins_division_name | C16: varchar | D16: 100 | E16: ins_division_name | F16: 68 | G16: =IF(I16=J16,"Pass","Fail") -> Pass | H16: =IF(AND(ISBLANK(D16),F16>=0),"Pass",IF(F16<=D16,"Pass","Fail")) -> Pass | I16: =SUBSTITUTE(B16,"_","") -> insdivisionname | J16: =SUBSTITUTE(E16,"_","") -> insdivisionname
B17: ins_cobra_code | C17: varchar | D17: 2 | E17: ins_cobra_code | F17: 0 | G17: =IF(I17=J17,"Pass","Fail") -> Pass | H17: =IF(AND(ISBLANK(D17),F17>=0),"Pass",IF(F17<=D17,"Pass","Fail")) -> Pass | I17: =SUBSTITUTE(B17,"_","") -> inscobracode | J17: =SUBSTITUTE(E17,"_","") -> inscobracode
B18: ins_cobra_desc | C18: varchar | D18: 30 | E18: ins_cobra_desc | F18: 0 | G18: =IF(I18=J18,"Pass","Fail") -> Pass | H18: =IF(AND(ISBLANK(D18),F18>=0),"Pass",IF(F18<=D18,"Pass","Fail")) -> Pass | I18: =SUBSTITUTE(B18,"_","") -> inscobradesc | J18: =SUBSTITUTE(E18,"_","") -> inscobradesc
B19: mbr_id | C19: varchar | D19: 25 | E19: mbr_id | F19: 25 | G19: =IF(I19=J19,"Pass","Fail") -> Pass | H19: =IF(AND(ISBLANK(D19),F19>=0),"Pass",IF(F19<=D19,"Pass","Fail")) -> Pass | I19: =SUBSTITUTE(B19,"_","") -> mbrid | J19: =SUBSTITUTE(E19,"_","") -> mbrid
B20: mbr_ssn | C20: varchar | D20: 22 | E20: mbr_ssn | F20: 22 | G20: =IF(I20=J20,"Pass","Fail") -> Pass | H20: =IF(AND(ISBLANK(D20),F20>=0),"Pass",IF(F20<=D20,"Pass","Fail")) -> Pass | I20: =SUBSTITUTE(B20,"_","") -> mbrssn | J20: =SUBSTITUTE(E20,"_","") -> mbrssn
B21: mbr_first_name | C21: varchar | D21: 30 | E21: mbr_first_name | F21: 15 | G21: =IF(I21=J21,"Pass","Fail") -> Pass | H21: =IF(AND(ISBLANK(D21),F21>=0),"Pass",IF(F21<=D21,"Pass","Fail")) -> Pass | I21: =SUBSTITUTE(B21,"_","") -> mbrfirstname | J21: =SUBSTITUTE(E21,"_","") -> mbrfirstname
B22: mbr_middle_name | C22: varchar | D22: 30 | E22: mbr_middle_name | F22: 1 | G22: =IF(I22=J22,"Pass","Fail") -> Pass | H22: =IF(AND(ISBLANK(D22),F22>=0),"Pass",IF(F22<=D22,"Pass","Fail")) -> Pass | I22: =SUBSTITUTE(B22,"_","") -> mbrmiddlename | J22: =SUBSTITUTE(E22,"_","") -> mbrmiddlename
... B24: mbr_gender | C24: varchar | D24: 2 | E24: mbr_gender | F24: 1 | G24: =IF(I24=J24,"Pass","Fail") -> Pass | H24: =IF(AND(ISBLANK(D24),F24>=0),"Pass",IF(F24<=D24,"Pass","Fail")) -> Pass | I24: =SUBSTITUTE(B24,"_","") -> mbrgender | J24: =SUBSTITUTE(E24,"_","") -> mbrgender
B25: mbr_dob | C25: date | E25: mbr_dob | F25: 10 | G25: =IF(I25=J25,"Pass","Fail") -> Pass | H25: =IF(AND(ISBLANK(D25),F25>=0),"Pass",IF(F25<=D25,"Pass","Fail")) -> Pass | I25: =SUBSTITUTE(B25,"_","") -> mbrdob | J25: =SUBSTITUTE(E25,"_","") -> mbrdob
B26: mbr_street_1 | C26: varchar | D26: 50 | E26: mbr_street_1 | F26: 30 | G26: =IF(I26=J26,"Pass","Fail") -> Pass | H26: =IF(AND(ISBLANK(D26),F26>=0),"Pass",IF(F26<=D26,"Pass","Fail")) -> Pass | I26: =SUBSTITUTE(B26,"_","") -> mbrstreet1 | J26: =SUBSTITUTE(E26,"_","") -> mbrstreet1
B27: mbr_street_2 | C27: varchar | D27: 50 | E27: mbr_street_2 | F27: 22 | G27: =IF(I27=J27,"Pass","Fail") -> Pass | H27: =IF(AND(ISBLANK(D27),F27>=0),"Pass",IF(F27<=D27,"Pass","Fail")) -> Pass | I27: =SUBSTITUTE(B27,"_","") -> mbrstreet2 | J27: =SUBSTITUTE(E27,"_","") -> mbrstreet2
B28: mbr_city | C28: varchar | D28: 50 | E28: mbr_city | F28: 20 | G28: =IF(I28=J28,"Pass","Fail") -> Pass | H28: =IF(AND(ISBLANK(D28),F28>=0),"Pass",IF(F28<=D28,"Pass","Fail")) -> Pass | I28: =SUBSTITUTE(B28,"_","") -> mbrcity | J28: =SUBSTITUTE(E28,"_","") -> mbrcity
B29: mbr_county | C29: varchar | D29: 20 | E29: mbr_county | F29: 5 | G29: =IF(I29=J29,"Pass","Fail") -> Pass | H29: =IF(AND(ISBLANK(D29),F29>=0),"Pass",IF(F29<=D29,"Pass","Fail")) -> Pass | I29: =SUBSTITUTE(B29,"_","") -> mbrcounty | J29: =SUBSTITUTE(E29,"_","") -> mbrcounty
B30: mbr_state | C30: varchar | D30: 2 | E30: mbr_state | F30: 2 | G30: =IF(I30=J30,"Pass","Fail") -> Pass | H30: =IF(AND(ISBLANK(D30),F30>=0),"Pass",IF(F30<=D30,"Pass","Fail")) -> Pass | I30: =SUBSTITUTE(B30,"_","") -> mbrstate | J30: =SUBSTITUTE(E30,"_","") -> mbrstate
B31: mbr_zip | C31: varchar | D31: 10 | E31: mbr_zip | F31: 5 | G31: =IF(I31=J31,"Pass","Fail") -> Pass | H31: =IF(AND(ISBLANK(D31),F31>=0),"Pass",IF(F31<=D31,"Pass","Fail")) -> Pass | I31: =SUBSTITUTE(B31,"_","") -> mbrzip | J31: =SUBSTITUTE(E31,"_","") -> mbrzip
B32: mbr_phone | C32: varchar | D32: 15 | E32: mbr_phone | F32: 12 | G32: =IF(I32=J32,"Pass","Fail") -> Pass | H32: =IF(AND(ISBLANK(D32),F32>=0),"Pass",IF(F32<=D32,"Pass","Fail")) -> Pass | I32: =SUBSTITUTE(B32,"_","") -> mbrphone | J32: =SUBSTITUTE(E32,"_","") -> mbrphone
B33: mbr_region_code | C33: varchar | D33: 32 | E33: mbr_region_code | F33: 0 | G33: =IF(I33=J33,"Pass","Fail") -> Pass | H33: =IF(AND(ISBLANK(D33),F33>=0),"Pass",IF(F33<=D33,"Pass","Fail")) -> Pass | I33: =SUBSTITUTE(B33,"_","") -> mbrregioncode | J33: =SUBSTITUTE(E33,"_","") -> mbrregioncode
B34: mbr_region_name | C34: varchar | D34: 50 | E34: mbr_region_name | F34: 0 | G34: =IF(I34=J34,"Pass","Fail") -> Pass | H34: =IF(AND(ISBLANK(D34),F34>=0),"Pass",IF(F34<=D34,"Pass","Fail")) -> Pass | I34: =SUBSTITUTE(B34,"_","") -> mbrregionname | J34: =SUBSTITUTE(E34,"_","") -> mbrregionname
B35: mbr_relationship_code | C35: varchar | D35: 10 | E35: mbr_relationship_code | F35: 3 | G35: =IF(I35=J35,"Pass","Fail") -> Pass | H35: =IF(AND(ISBLANK(D35),F35>=0),"Pass",IF(F35<=D35,"Pass","Fail")) -> Pass | I35: =SUBSTITUTE(B35,"_","") -> mbrrelationshipcode | J35: =SUBSTITUTE(E35,"_","") -> mbrrelationshipcode
B36: mbr_relationship_desc | C36: varchar | D36: 42 | E36: mbr_relationship_desc | F36: 42 | G36: =IF(I36=J36,"Pass","Fail") -> Pass | H36: =IF(AND(ISBLANK(D36),F36>=0),"Pass",IF(F36<=D36,"Pass","Fail")) -> Pass | I36: =SUBSTITUTE(B36,"_","") -> mbrrelationshipdesc | J36: =SUBSTITUTE(E36,"_","") -> mbrrelationshipdesc
B37: prv_service_provider_id | C37: varchar | D37: 37 | E37: prv_service_provider_id | F37: 37 | G37: =IF(I37=J37,"Pass","Fail") -> Pass | H37: =IF(AND(ISBLANK(D37),F37>=0),"Pass",IF(F37<=D37,"Pass","Fail")) -> Pass | I37: =SUBSTITUTE(B37,"_","") -> prvserviceproviderid | J37: =SUBSTITUTE(E37,"_","") -> prvserviceproviderid
... B112: svc_discharge_desc | C112: varchar | D112: 119 | E112: svc_discharge_desc | F112: 119 | G112: =IF(I112=J112,"Pass","Fail") -> Pass | H112: =IF(AND(ISBLANK(D112),F112>=0),"Pass",IF(F112<=D112,"Pass","Fail")) -> Pass | I112: =SUBSTITUTE(B112,"_","") -> svcdischargedesc | J112: =SUBSTITUTE(E112,"_","") -> svcdischargedesc
B113: svc_service_qty | C113: int | E113: svc_service_qty | F113: 4 | G113: =IF(I113=J113,"Pass","Fail") -> Pass | H113: =IF(AND(ISBLANK(D113),F113>=0),"Pass",IF(F113<=D113,"Pass","Fail")) -> Pass | I113: =SUBSTITUTE(B113,"_","") -> svcserviceqty | J113: =SUBSTITUTE(E113,"_","") -> svcserviceqty
B114: svc_ip_days | C114: int | E114: svc_ip_days | F114: 3 | G114: =IF(I114=J114,"Pass","Fail") -> Pass | H114: =IF(AND(ISBLANK(D114),F114>=0),"Pass",IF(F114<=D114,"Pass","Fail")) -> Pass | I114: =SUBSTITUTE(B114,"_","") -> svcipdays | J114: =SUBSTITUTE(E114,"_","") -> svcipdays
B115: svc_covered_days | C115: int | E115: svc_covered_days | F115: 1 | G115: =IF(I115=J115,"Pass","Fail") -> Pass | H115: =IF(AND(ISBLANK(D115),F115>=0),"Pass",IF(F115<=D115,"Pass","Fail")) -> Pass | I115: =SUBSTITUTE(B115,"_","") -> svccovereddays | J115: =SUBSTITUTE(E115,"_","") -> svccovereddays
...

Sheet Participation
B1: Client layout | C1: Data Type | D1: Client Length | E1: Extract Layout | F1: Extract Length | G1: Layout Result | H1: Length Result | O1: Fail
B2: dw_record_id | C2: int | G2: =IF(I2=J2,"Pass","Fail") -> Fail | H2: =IF(AND(ISBLANK(D2),F2>=0),"Pass",IF(F2<=D2,"Pass","Fail")) -> Pass | I2: =SUBSTITUTE(B2,"_","") -> dwrecordid | J2: =SUBSTITUTE(E2,"_","") | L2: Extract Total Count | M2: Application Total Count | N2: Difference
B3: dw_account_id | C3: varchar | D3: 50 | G3: =IF(I3=J3,"Pass","Fail") -> Fail | H3: =IF(AND(ISBLANK(D3),F3>=0),"Pass",IF(F3<=D3,"Pass","Fail")) -> Pass | I3: =SUBSTITUTE(B3,"_","") -> dwaccountid | J3: =SUBSTITUTE(E3,"_","") | N3: =L3-M3 -> 0
B4: dw_client_id | C4: varchar | D4: 50 | G4: =IF(I4=J4,"Pass","Fail") -> Fail | H4: =IF(AND(ISBLANK(D4),F4>=0),"Pass",IF(F4<=D4,"Pass","Fail")) -> Pass | I4: =SUBSTITUTE(B4,"_","") -> dwclientid | J4: =SUBSTITUTE(E4,"_","") | L4: Prior Count | N4: =L3-M4 -> 0
B5: dw_member_id | C5: varchar | D5: 50 | G5: =IF(I5=J5,"Pass","Fail") -> Fail | H5: =IF(AND(ISBLANK(D5),F5>=0),"Pass",IF(F5<=D5,"Pass","Fail")) -> Pass | I5: =SUBSTITUTE(B5,"_","") -> dwmemberid | J5: =SUBSTITUTE(E5,"_","")
B6: mbr_id | C6: varchar | D6: 20 | G6: =IF(I6=J6,"Pass","Fail") -> Fail | H6: =IF(AND(ISBLANK(D6),F6>=0),"Pass",IF(F6<=D6,"Pass","Fail")) -> Pass | I6: =SUBSTITUTE(B6,"_","") -> mbrid | J6: =SUBSTITUTE(E6,"_","") | L6: Overall | M6: Result
B7: program_type | C7: varchar | D7: 50 | G7: =IF(I7=J7,"Pass","Fail") -> Fail | H7: =IF(AND(ISBLANK(D7),F7>=0),"Pass",IF(F7<=D7,"Pass","Fail")) -> Pass | I7: =SUBSTITUTE(B7,"_","") -> programtype | J7: =SUBSTITUTE(E7,"_","") | L7: Layout Result | M7: =IF(ISERROR(VLOOKUP($O$1,$G$2:$G$12,1,)),"Pass","Fail") -> Fail
B8: program_code | C8: varchar | D8: 20 | G8: =IF(I8=J8,"Pass","Fail") -> Fail | H8: =IF(AND(ISBLANK(D8),F8>=0),"Pass",IF(F8<=D8,"Pass","Fail")) -> Pass | I8: =SUBSTITUTE(B8,"_","") -> programcode | J8: =SUBSTITUTE(E8,"_","") | L8: Field Length Result | M8: =IF(ISERROR(VLOOKUP($O$1,$H$2:$H$12,1,)),"Pass","Fail") -> Pass
B9: program_name | C9: date | D9: 50 | G9: =IF(I9=J9,"Pass","Fail") -> Fail | H9: =IF(AND(ISBLANK(D9),F9>=0),"Pass",IF(F9<=D9,"Pass","Fail")) -> Pass | I9: =SUBSTITUTE(B9,"_","") -> programname | J9: =SUBSTITUTE(E9,"_","") | L9: Count Result | M9: =IF(N3=0,"Pass","Fail") -> Pass
B10: program_status | C10: date | D10: 20 | G10: =IF(I10=J10,"Pass","Fail") -> Fail | H10: =IF(AND(ISBLANK(D10),F10>=0),"Pass",IF(F10<=D10,"Pass","Fail")) -> Pass | I10: =SUBSTITUTE(B10,"_","") -> programstatus | J10: =SUBSTITUTE(E10,"_","") | L10: % change in count with respect to previous count | M10: =IF(M4=0,0%,N4/M4) -> 0
B11: program_start_date | G11: =IF(I11=J11,"Pass","Fail") -> Fail | H11: =IF(AND(ISBLANK(D11),F11>=0),"Pass",IF(F11<=D11,"Pass","Fail")) -> Pass | I11: =SUBSTITUTE(B11,"_","") -> programstartdate | J11: =SUBSTITUTE(E11,"_","") | L11: % change in file size with respect to previous file | M11: =File_Size_Comparision!F9 -> #VALUE!
B12: program_end_date | G12: =IF(I12=J12,"Pass","Fail") -> Fail | H12: =IF(AND(ISBLANK(D12),F12>=0),"Pass",IF(F12<=D12,"Pass","Fail")) -> Pass | I12: =SUBSTITUTE(B12,"_","") -> programenddate | J12: =SUBSTITUTE(E12,"_","")

Sheet Member_PCP
B1: Client layout | C1: Data Type | D1: Client Length | E1: Extract Layout | F1: Extract Length | G1: Layout Result | H1: Length Result | O1: Fail
B2: dw_record_id | C2: int | E2: dw_record_id | F2: 4 | G2: =IF(I2=J2,"Pass","Fail") -> Pass | H2: =IF(AND(ISBLANK(D2),F2>=0),"Pass",IF(F2<=D2,"Pass","Fail")) -> Pass | I2: =SUBSTITUTE(B2,"_","") -> dwrecordid | J2: =SUBSTITUTE(E2,"_","") -> dwrecordid | L2: Current Extract Count | M2: Previous Extract Count | N2: Difference
B3: dw_account_id | C3: varchar | D3: 10 | E3: dw_account_id | F3: 0 | G3: =IF(I3=J3,"Pass","Fail") -> Pass | H3: =IF(AND(ISBLANK(D3),F3>=0),"Pass",IF(F3<=D3,"Pass","Fail")) -> Pass | I3: =SUBSTITUTE(B3,"_","") -> dwaccountid | J3: =SUBSTITUTE(E3,"_","") -> dwaccountid | L3: 8505 | M3: 5666 | N3: =L3-M3 -> 2839
B4: dw_client_id | C4: varchar | D4: 10 | E4: dw_client_id | F4: 8 | G4: =IF(I4=J4,"Pass","Fail") -> Pass | H4: =IF(AND(ISBLANK(D4),F4>=0),"Pass",IF(F4<=D4,"Pass","Fail")) -> Pass | I4: =SUBSTITUTE(B4,"_","") -> dwclientid | J4: =SUBSTITUTE(E4,"_","") -> dwclientid
B5: dw_member_id | C5: varchar | D5: 50 | E5: dw_member_id | F5: 32 | G5: =IF(I5=J5,"Pass","Fail") -> Pass | H5: =IF(AND(ISBLANK(D5),F5>=0),"Pass",IF(F5<=D5,"Pass","Fail")) -> Pass | I5: =SUBSTITUTE(B5,"_","") -> dwmemberid | J5: =SUBSTITUTE(E5,"_","") -> dwmemberid | L5: Overall | M5: Result
B6: mbr_id | C6: varchar | D6: 25 | E6: mbr_id | F6: 25 | G6: =IF(I6=J6,"Pass","Fail") -> Pass | H6: =IF(AND(ISBLANK(D6),F6>=0),"Pass",IF(F6<=D6,"Pass","Fail")) -> Pass | I6: =SUBSTITUTE(B6,"_","") -> mbrid | J6: =SUBSTITUTE(E6,"_","") -> mbrid | L6: Layout Result | M6: =IF(ISERROR(VLOOKUP($O$1,$G$2:$G$10,1,)),"Pass","Fail") -> Pass
B7: pcp_name | C7: varchar | D7: 100 | E7: pcp_name | F7: 70 | G7: =IF(I7=J7,"Pass","Fail") -> Pass | H7: =IF(AND(ISBLANK(D7),F7>=0),"Pass",IF(F7<=D7,"Pass","Fail")) -> Pass | I7: =SUBSTITUTE(B7,"_","") -> pcpname | J7: =SUBSTITUTE(E7,"_","") -> pcpname | L7: Field Length Result | M7: =IF(ISERROR(VLOOKUP($O$1,$H$2:$H$10,1,)),"Pass","Fail") -> Pass
B8: pcp_npi | C8: varchar | D8: 100 | E8: pcp_npi | F8: 10 | G8: =IF(I8=J8,"Pass","Fail") -> Pass | H8: =IF(AND(ISBLANK(D8),F8>=0),"Pass",IF(F8<=D8,"Pass","Fail")) -> Pass | I8: =SUBSTITUTE(B8,"_","") -> pcpnpi | J8: =SUBSTITUTE(E8,"_","") -> pcpnpi | L8: % change in count with respect to previous count | M8: =IF(M3=0,0%,N3/M3) -> 0.50105895
B9: start_date | C9: date | E9: start_date | F9: 10 | G9: =IF(I9=J9,"Pass","Fail") -> Pass | H9: =IF(AND(ISBLANK(D9),F9>=0),"Pass",IF(F9<=D9,"Pass","Fail")) -> Pass | I9: =SUBSTITUTE(B9,"_","") -> startdate | J9: =SUBSTITUTE(E9,"_","") -> startdate | L9: % change in file size with respect to previous file | M9: =File_Size_Comparision!F10 -> 0.32742857
B10: end_date | C10: date | E10: end_date | F10: 10 | G10: =IF(I10=J10,"Pass","Fail") -> Pass | H10: =IF(AND(ISBLANK(D10),F10>=0),"Pass",IF(F10<=D10,"Pass","Fail")) -> Pass | I10: =SUBSTITUTE(B10,"_","") -> enddate | J10: =SUBSTITUTE(E10,"_","") -> enddate

Sheet Pharmacy
B1: Client layout | C1: Data Type | D1: Client Length | E1: Extract Layout | F1: Extract Length | G1: Layout Result | H1: Length Result | L1: Extract Total Count | M1: Application Total Count | N1: Difference | O1: Fail
